[2022-07-30 18:18:52,505] {taskinstance.py:1159} INFO - Dependencies all met for <TaskInstance: dag_with_postgres_operator.create_postgres_table scheduled__2022-01-15T00:00:00+00:00 [queued]>
[2022-07-30 18:18:52,522] {taskinstance.py:1159} INFO - Dependencies all met for <TaskInstance: dag_with_postgres_operator.create_postgres_table scheduled__2022-01-15T00:00:00+00:00 [queued]>
[2022-07-30 18:18:52,523] {taskinstance.py:1356} INFO - 
--------------------------------------------------------------------------------
[2022-07-30 18:18:52,523] {taskinstance.py:1357} INFO - Starting attempt 4 of 6
[2022-07-30 18:18:52,523] {taskinstance.py:1358} INFO - 
--------------------------------------------------------------------------------
[2022-07-30 18:18:52,543] {taskinstance.py:1377} INFO - Executing <Task(PostgresOperator): create_postgres_table> on 2022-01-15 00:00:00+00:00
[2022-07-30 18:18:52,549] {standard_task_runner.py:52} INFO - Started process 2537 to run task
[2022-07-30 18:18:52,553] {standard_task_runner.py:79} INFO - Running: ['***', 'tasks', 'run', 'dag_with_postgres_operator', 'create_postgres_table', 'scheduled__2022-01-15T00:00:00+00:00', '--job-id', '158', '--raw', '--subdir', 'DAGS_FOLDER/DAGWithPostgresOperator.py', '--cfg-path', '/tmp/tmpvcqrwbho', '--error-file', '/tmp/tmpyo63974p']
[2022-07-30 18:18:52,553] {standard_task_runner.py:80} INFO - Job 158: Subtask create_postgres_table
[2022-07-30 18:18:52,622] {task_command.py:369} INFO - Running <TaskInstance: dag_with_postgres_operator.create_postgres_table scheduled__2022-01-15T00:00:00+00:00 [running]> on host 66bf18ec08cc
[2022-07-30 18:18:52,714] {taskinstance.py:1571} INFO - Exporting the following env vars:
AIRFLOW_CTX_DAG_OWNER=yosr
AIRFLOW_CTX_DAG_ID=dag_with_postgres_operator
AIRFLOW_CTX_TASK_ID=create_postgres_table
AIRFLOW_CTX_EXECUTION_DATE=2022-01-15T00:00:00+00:00
AIRFLOW_CTX_TRY_NUMBER=4
AIRFLOW_CTX_DAG_RUN_ID=scheduled__2022-01-15T00:00:00+00:00
[2022-07-30 18:18:52,727] {base.py:68} INFO - Using connection ID 'postgres_localhost' for task execution.
[2022-07-30 18:18:52,728] {taskinstance.py:1889} ERROR - Task failed with exception
Traceback (most recent call last):
  File "/home/airflow/.local/lib/python3.7/site-packages/airflow/providers/postgres/operators/postgres.py", line 92, in execute
    self.hook.run(self.sql, self.autocommit, parameters=self.parameters)
  File "/home/airflow/.local/lib/python3.7/site-packages/airflow/hooks/dbapi.py", line 181, in run
    with closing(self.get_conn()) as conn:
  File "/home/airflow/.local/lib/python3.7/site-packages/airflow/providers/postgres/hooks/postgres.py", line 113, in get_conn
    self.conn = psycopg2.connect(**conn_args)
  File "/home/airflow/.local/lib/python3.7/site-packages/psycopg2/__init__.py", line 122, in connect
    conn = _connect(dsn, connection_factory=connection_factory, **kwasync)
psycopg2.OperationalError: could not translate host name "host.docker.internal " to address: Name or service not known

[2022-07-30 18:18:52,741] {taskinstance.py:1400} INFO - Marking task as UP_FOR_RETRY. dag_id=dag_with_postgres_operator, task_id=create_postgres_table, execution_date=20220115T000000, start_date=20220730T181852, end_date=20220730T181852
[2022-07-30 18:18:52,758] {standard_task_runner.py:97} ERROR - Failed to execute job 158 for task create_postgres_table (could not translate host name "host.docker.internal " to address: Name or service not known
; 2537)
[2022-07-30 18:18:52,770] {local_task_job.py:156} INFO - Task exited with return code 1
[2022-07-30 18:18:52,885] {local_task_job.py:273} INFO - 0 downstream tasks scheduled from follow-on schedule check
[2022-07-31 00:25:06,073] {taskinstance.py:1159} INFO - Dependencies all met for <TaskInstance: dag_with_postgres_operator.create_postgres_table scheduled__2022-01-15T00:00:00+00:00 [queued]>
[2022-07-31 00:25:06,092] {taskinstance.py:1159} INFO - Dependencies all met for <TaskInstance: dag_with_postgres_operator.create_postgres_table scheduled__2022-01-15T00:00:00+00:00 [queued]>
[2022-07-31 00:25:06,093] {taskinstance.py:1356} INFO - 
--------------------------------------------------------------------------------
[2022-07-31 00:25:06,093] {taskinstance.py:1357} INFO - Starting attempt 4 of 6
[2022-07-31 00:25:06,093] {taskinstance.py:1358} INFO - 
--------------------------------------------------------------------------------
[2022-07-31 00:25:06,112] {taskinstance.py:1377} INFO - Executing <Task(PostgresOperator): create_postgres_table> on 2022-01-15 00:00:00+00:00
[2022-07-31 00:25:06,116] {standard_task_runner.py:52} INFO - Started process 6464 to run task
[2022-07-31 00:25:06,119] {standard_task_runner.py:79} INFO - Running: ['***', 'tasks', 'run', 'dag_with_postgres_operator', 'create_postgres_table', 'scheduled__2022-01-15T00:00:00+00:00', '--job-id', '1166', '--raw', '--subdir', 'DAGS_FOLDER/DAGWithPostgresOperator.py', '--cfg-path', '/tmp/tmpss1cv0u5', '--error-file', '/tmp/tmp56z1s6gs']
[2022-07-31 00:25:06,120] {standard_task_runner.py:80} INFO - Job 1166: Subtask create_postgres_table
[2022-07-31 00:25:06,179] {task_command.py:369} INFO - Running <TaskInstance: dag_with_postgres_operator.create_postgres_table scheduled__2022-01-15T00:00:00+00:00 [running]> on host 66bf18ec08cc
[2022-07-31 00:25:06,258] {taskinstance.py:1571} INFO - Exporting the following env vars:
AIRFLOW_CTX_DAG_OWNER=yosr
AIRFLOW_CTX_DAG_ID=dag_with_postgres_operator
AIRFLOW_CTX_TASK_ID=create_postgres_table
AIRFLOW_CTX_EXECUTION_DATE=2022-01-15T00:00:00+00:00
AIRFLOW_CTX_TRY_NUMBER=4
AIRFLOW_CTX_DAG_RUN_ID=scheduled__2022-01-15T00:00:00+00:00
[2022-07-31 00:25:06,269] {base.py:68} INFO - Using connection ID 'postgres_localhost' for task execution.
[2022-07-31 00:25:06,269] {taskinstance.py:1889} ERROR - Task failed with exception
Traceback (most recent call last):
  File "/home/airflow/.local/lib/python3.7/site-packages/airflow/providers/postgres/operators/postgres.py", line 92, in execute
    self.hook.run(self.sql, self.autocommit, parameters=self.parameters)
  File "/home/airflow/.local/lib/python3.7/site-packages/airflow/hooks/dbapi.py", line 181, in run
    with closing(self.get_conn()) as conn:
  File "/home/airflow/.local/lib/python3.7/site-packages/airflow/providers/postgres/hooks/postgres.py", line 113, in get_conn
    self.conn = psycopg2.connect(**conn_args)
  File "/home/airflow/.local/lib/python3.7/site-packages/psycopg2/__init__.py", line 122, in connect
    conn = _connect(dsn, connection_factory=connection_factory, **kwasync)
psycopg2.OperationalError: could not translate host name "host.docker.local " to address: Name or service not known

[2022-07-31 00:25:06,279] {taskinstance.py:1400} INFO - Marking task as UP_FOR_RETRY. dag_id=dag_with_postgres_operator, task_id=create_postgres_table, execution_date=20220115T000000, start_date=20220731T002506, end_date=20220731T002506
[2022-07-31 00:25:06,292] {standard_task_runner.py:97} ERROR - Failed to execute job 1166 for task create_postgres_table (could not translate host name "host.docker.local " to address: Name or service not known
; 6464)
[2022-07-31 00:25:06,299] {local_task_job.py:156} INFO - Task exited with return code 1
[2022-07-31 00:25:06,340] {local_task_job.py:273} INFO - 0 downstream tasks scheduled from follow-on schedule check
[2022-07-31 11:18:49,209] {taskinstance.py:1159} INFO - Dependencies all met for <TaskInstance: dag_with_postgres_operator.create_postgres_table scheduled__2022-01-15T00:00:00+00:00 [queued]>
[2022-07-31 11:18:49,233] {taskinstance.py:1159} INFO - Dependencies all met for <TaskInstance: dag_with_postgres_operator.create_postgres_table scheduled__2022-01-15T00:00:00+00:00 [queued]>
[2022-07-31 11:18:49,234] {taskinstance.py:1356} INFO - 
--------------------------------------------------------------------------------
[2022-07-31 11:18:49,234] {taskinstance.py:1357} INFO - Starting attempt 4 of 6
[2022-07-31 11:18:49,234] {taskinstance.py:1358} INFO - 
--------------------------------------------------------------------------------
[2022-07-31 11:18:49,254] {taskinstance.py:1377} INFO - Executing <Task(PostgresOperator): create_postgres_table> on 2022-01-15 00:00:00+00:00
[2022-07-31 11:18:49,261] {standard_task_runner.py:52} INFO - Started process 5335 to run task
[2022-07-31 11:18:49,267] {standard_task_runner.py:79} INFO - Running: ['***', 'tasks', 'run', 'dag_with_postgres_operator', 'create_postgres_table', 'scheduled__2022-01-15T00:00:00+00:00', '--job-id', '1613', '--raw', '--subdir', 'DAGS_FOLDER/DAGWithPostgresOperator.py', '--cfg-path', '/tmp/tmpdd80b7ar', '--error-file', '/tmp/tmpr125_lf5']
[2022-07-31 11:18:49,268] {standard_task_runner.py:80} INFO - Job 1613: Subtask create_postgres_table
[2022-07-31 11:18:49,405] {task_command.py:369} INFO - Running <TaskInstance: dag_with_postgres_operator.create_postgres_table scheduled__2022-01-15T00:00:00+00:00 [running]> on host 66bf18ec08cc
[2022-07-31 11:18:49,508] {taskinstance.py:1571} INFO - Exporting the following env vars:
AIRFLOW_CTX_DAG_OWNER=yosr
AIRFLOW_CTX_DAG_ID=dag_with_postgres_operator
AIRFLOW_CTX_TASK_ID=create_postgres_table
AIRFLOW_CTX_EXECUTION_DATE=2022-01-15T00:00:00+00:00
AIRFLOW_CTX_TRY_NUMBER=4
AIRFLOW_CTX_DAG_RUN_ID=scheduled__2022-01-15T00:00:00+00:00
[2022-07-31 11:18:49,521] {base.py:68} INFO - Using connection ID 'postgres_localhost' for task execution.
[2022-07-31 11:19:19,545] {taskinstance.py:1889} ERROR - Task failed with exception
Traceback (most recent call last):
  File "/home/airflow/.local/lib/python3.7/site-packages/airflow/providers/postgres/operators/postgres.py", line 92, in execute
    self.hook.run(self.sql, self.autocommit, parameters=self.parameters)
  File "/home/airflow/.local/lib/python3.7/site-packages/airflow/hooks/dbapi.py", line 181, in run
    with closing(self.get_conn()) as conn:
  File "/home/airflow/.local/lib/python3.7/site-packages/airflow/providers/postgres/hooks/postgres.py", line 113, in get_conn
    self.conn = psycopg2.connect(**conn_args)
  File "/home/airflow/.local/lib/python3.7/site-packages/psycopg2/__init__.py", line 122, in connect
    conn = _connect(dsn, connection_factory=connection_factory, **kwasync)
psycopg2.OperationalError: could not translate host name "host.docker.internal" to address: Temporary failure in name resolution

[2022-07-31 11:19:19,559] {taskinstance.py:1400} INFO - Marking task as UP_FOR_RETRY. dag_id=dag_with_postgres_operator, task_id=create_postgres_table, execution_date=20220115T000000, start_date=20220731T111849, end_date=20220731T111919
[2022-07-31 11:19:19,578] {standard_task_runner.py:97} ERROR - Failed to execute job 1613 for task create_postgres_table (could not translate host name "host.docker.internal" to address: Temporary failure in name resolution
; 5335)
[2022-07-31 11:19:19,615] {local_task_job.py:156} INFO - Task exited with return code 1
[2022-07-31 11:19:19,651] {local_task_job.py:273} INFO - 0 downstream tasks scheduled from follow-on schedule check
[2022-07-31 13:50:12,399] {taskinstance.py:1159} INFO - Dependencies all met for <TaskInstance: dag_with_postgres_operator.create_postgres_table scheduled__2022-01-15T00:00:00+00:00 [queued]>
[2022-07-31 13:50:12,415] {taskinstance.py:1159} INFO - Dependencies all met for <TaskInstance: dag_with_postgres_operator.create_postgres_table scheduled__2022-01-15T00:00:00+00:00 [queued]>
[2022-07-31 13:50:12,416] {taskinstance.py:1356} INFO - 
--------------------------------------------------------------------------------
[2022-07-31 13:50:12,416] {taskinstance.py:1357} INFO - Starting attempt 4 of 6
[2022-07-31 13:50:12,416] {taskinstance.py:1358} INFO - 
--------------------------------------------------------------------------------
[2022-07-31 13:50:12,436] {taskinstance.py:1377} INFO - Executing <Task(PostgresOperator): create_postgres_table> on 2022-01-15 00:00:00+00:00
[2022-07-31 13:50:12,440] {standard_task_runner.py:52} INFO - Started process 2938 to run task
[2022-07-31 13:50:12,444] {standard_task_runner.py:79} INFO - Running: ['***', 'tasks', 'run', 'dag_with_postgres_operator', 'create_postgres_table', 'scheduled__2022-01-15T00:00:00+00:00', '--job-id', '158', '--raw', '--subdir', 'DAGS_FOLDER/DAGWithPostgresOperator.py', '--cfg-path', '/tmp/tmpekfw3b9l', '--error-file', '/tmp/tmp8yht8esh']
[2022-07-31 13:50:12,444] {standard_task_runner.py:80} INFO - Job 158: Subtask create_postgres_table
[2022-07-31 13:50:12,513] {task_command.py:369} INFO - Running <TaskInstance: dag_with_postgres_operator.create_postgres_table scheduled__2022-01-15T00:00:00+00:00 [running]> on host 4688dd3b7141
[2022-07-31 13:50:12,595] {taskinstance.py:1571} INFO - Exporting the following env vars:
AIRFLOW_CTX_DAG_OWNER=yosr
AIRFLOW_CTX_DAG_ID=dag_with_postgres_operator
AIRFLOW_CTX_TASK_ID=create_postgres_table
AIRFLOW_CTX_EXECUTION_DATE=2022-01-15T00:00:00+00:00
AIRFLOW_CTX_TRY_NUMBER=4
AIRFLOW_CTX_DAG_RUN_ID=scheduled__2022-01-15T00:00:00+00:00
[2022-07-31 13:50:12,676] {taskinstance.py:1889} ERROR - Task failed with exception
Traceback (most recent call last):
  File "/home/airflow/.local/lib/python3.7/site-packages/airflow/providers/postgres/operators/postgres.py", line 92, in execute
    self.hook.run(self.sql, self.autocommit, parameters=self.parameters)
  File "/home/airflow/.local/lib/python3.7/site-packages/airflow/hooks/dbapi.py", line 181, in run
    with closing(self.get_conn()) as conn:
  File "/home/airflow/.local/lib/python3.7/site-packages/airflow/providers/postgres/hooks/postgres.py", line 86, in get_conn
    conn = deepcopy(self.connection or self.get_connection(conn_id))
  File "/home/airflow/.local/lib/python3.7/site-packages/airflow/hooks/base.py", line 67, in get_connection
    conn = Connection.get_connection_from_secrets(conn_id)
  File "/home/airflow/.local/lib/python3.7/site-packages/airflow/models/connection.py", line 430, in get_connection_from_secrets
    raise AirflowNotFoundException(f"The conn_id `{conn_id}` isn't defined")
airflow.exceptions.AirflowNotFoundException: The conn_id `postgres_localhost` isn't defined
[2022-07-31 13:50:12,680] {taskinstance.py:1400} INFO - Marking task as UP_FOR_RETRY. dag_id=dag_with_postgres_operator, task_id=create_postgres_table, execution_date=20220115T000000, start_date=20220731T135012, end_date=20220731T135012
[2022-07-31 13:50:12,696] {standard_task_runner.py:97} ERROR - Failed to execute job 158 for task create_postgres_table (The conn_id `postgres_localhost` isn't defined; 2938)
[2022-07-31 13:50:12,702] {local_task_job.py:156} INFO - Task exited with return code 1
[2022-07-31 13:50:12,743] {local_task_job.py:273} INFO - 0 downstream tasks scheduled from follow-on schedule check
