[2022-07-30 18:08:48,023] {taskinstance.py:1159} INFO - Dependencies all met for <TaskInstance: dag_with_postgres_operator.create_postgres_table scheduled__2022-01-08T00:00:00+00:00 [queued]>
[2022-07-30 18:08:48,049] {taskinstance.py:1159} INFO - Dependencies all met for <TaskInstance: dag_with_postgres_operator.create_postgres_table scheduled__2022-01-08T00:00:00+00:00 [queued]>
[2022-07-30 18:08:48,052] {taskinstance.py:1356} INFO - 
--------------------------------------------------------------------------------
[2022-07-30 18:08:48,052] {taskinstance.py:1357} INFO - Starting attempt 2 of 6
[2022-07-30 18:08:48,053] {taskinstance.py:1358} INFO - 
--------------------------------------------------------------------------------
[2022-07-30 18:08:48,090] {taskinstance.py:1377} INFO - Executing <Task(PostgresOperator): create_postgres_table> on 2022-01-08 00:00:00+00:00
[2022-07-30 18:08:48,096] {standard_task_runner.py:52} INFO - Started process 1998 to run task
[2022-07-30 18:08:48,105] {standard_task_runner.py:79} INFO - Running: ['***', 'tasks', 'run', 'dag_with_postgres_operator', 'create_postgres_table', 'scheduled__2022-01-08T00:00:00+00:00', '--job-id', '118', '--raw', '--subdir', 'DAGS_FOLDER/DAGWithPostgresOperator.py', '--cfg-path', '/tmp/tmpkncj4_mp', '--error-file', '/tmp/tmpt6aan62r']
[2022-07-30 18:08:48,107] {standard_task_runner.py:80} INFO - Job 118: Subtask create_postgres_table
[2022-07-30 18:08:48,264] {task_command.py:369} INFO - Running <TaskInstance: dag_with_postgres_operator.create_postgres_table scheduled__2022-01-08T00:00:00+00:00 [running]> on host 66bf18ec08cc
[2022-07-30 18:08:48,440] {taskinstance.py:1571} INFO - Exporting the following env vars:
AIRFLOW_CTX_DAG_OWNER=yosr
AIRFLOW_CTX_DAG_ID=dag_with_postgres_operator
AIRFLOW_CTX_TASK_ID=create_postgres_table
AIRFLOW_CTX_EXECUTION_DATE=2022-01-08T00:00:00+00:00
AIRFLOW_CTX_TRY_NUMBER=2
AIRFLOW_CTX_DAG_RUN_ID=scheduled__2022-01-08T00:00:00+00:00
[2022-07-30 18:08:48,454] {base.py:68} INFO - Using connection ID 'postgres_localhost' for task execution.
[2022-07-30 18:08:48,455] {taskinstance.py:1889} ERROR - Task failed with exception
Traceback (most recent call last):
  File "/home/airflow/.local/lib/python3.7/site-packages/airflow/providers/postgres/operators/postgres.py", line 92, in execute
    self.hook.run(self.sql, self.autocommit, parameters=self.parameters)
  File "/home/airflow/.local/lib/python3.7/site-packages/airflow/hooks/dbapi.py", line 181, in run
    with closing(self.get_conn()) as conn:
  File "/home/airflow/.local/lib/python3.7/site-packages/airflow/providers/postgres/hooks/postgres.py", line 113, in get_conn
    self.conn = psycopg2.connect(**conn_args)
  File "/home/airflow/.local/lib/python3.7/site-packages/psycopg2/__init__.py", line 122, in connect
    conn = _connect(dsn, connection_factory=connection_factory, **kwasync)
psycopg2.OperationalError: could not translate host name "host.docker.internal " to address: Name or service not known

[2022-07-30 18:08:48,474] {taskinstance.py:1400} INFO - Marking task as UP_FOR_RETRY. dag_id=dag_with_postgres_operator, task_id=create_postgres_table, execution_date=20220108T000000, start_date=20220730T180848, end_date=20220730T180848
[2022-07-30 18:08:48,497] {standard_task_runner.py:97} ERROR - Failed to execute job 118 for task create_postgres_table (could not translate host name "host.docker.internal " to address: Name or service not known
; 1998)
[2022-07-30 18:08:48,536] {local_task_job.py:156} INFO - Task exited with return code 1
[2022-07-30 18:08:48,695] {local_task_job.py:273} INFO - 0 downstream tasks scheduled from follow-on schedule check
[2022-07-31 00:15:01,886] {taskinstance.py:1159} INFO - Dependencies all met for <TaskInstance: dag_with_postgres_operator.create_postgres_table scheduled__2022-01-08T00:00:00+00:00 [queued]>
[2022-07-31 00:15:01,905] {taskinstance.py:1159} INFO - Dependencies all met for <TaskInstance: dag_with_postgres_operator.create_postgres_table scheduled__2022-01-08T00:00:00+00:00 [queued]>
[2022-07-31 00:15:01,905] {taskinstance.py:1356} INFO - 
--------------------------------------------------------------------------------
[2022-07-31 00:15:01,905] {taskinstance.py:1357} INFO - Starting attempt 2 of 6
[2022-07-31 00:15:01,906] {taskinstance.py:1358} INFO - 
--------------------------------------------------------------------------------
[2022-07-31 00:15:01,931] {taskinstance.py:1377} INFO - Executing <Task(PostgresOperator): create_postgres_table> on 2022-01-08 00:00:00+00:00
[2022-07-31 00:15:01,936] {standard_task_runner.py:52} INFO - Started process 5918 to run task
[2022-07-31 00:15:01,939] {standard_task_runner.py:79} INFO - Running: ['***', 'tasks', 'run', 'dag_with_postgres_operator', 'create_postgres_table', 'scheduled__2022-01-08T00:00:00+00:00', '--job-id', '1127', '--raw', '--subdir', 'DAGS_FOLDER/DAGWithPostgresOperator.py', '--cfg-path', '/tmp/tmp06q4l28t', '--error-file', '/tmp/tmpu9py54_n']
[2022-07-31 00:15:01,940] {standard_task_runner.py:80} INFO - Job 1127: Subtask create_postgres_table
[2022-07-31 00:15:02,010] {task_command.py:369} INFO - Running <TaskInstance: dag_with_postgres_operator.create_postgres_table scheduled__2022-01-08T00:00:00+00:00 [running]> on host 66bf18ec08cc
[2022-07-31 00:15:02,103] {taskinstance.py:1571} INFO - Exporting the following env vars:
AIRFLOW_CTX_DAG_OWNER=yosr
AIRFLOW_CTX_DAG_ID=dag_with_postgres_operator
AIRFLOW_CTX_TASK_ID=create_postgres_table
AIRFLOW_CTX_EXECUTION_DATE=2022-01-08T00:00:00+00:00
AIRFLOW_CTX_TRY_NUMBER=2
AIRFLOW_CTX_DAG_RUN_ID=scheduled__2022-01-08T00:00:00+00:00
[2022-07-31 00:15:02,119] {base.py:68} INFO - Using connection ID 'postgres_localhost' for task execution.
[2022-07-31 00:15:02,120] {taskinstance.py:1889} ERROR - Task failed with exception
Traceback (most recent call last):
  File "/home/airflow/.local/lib/python3.7/site-packages/airflow/providers/postgres/operators/postgres.py", line 92, in execute
    self.hook.run(self.sql, self.autocommit, parameters=self.parameters)
  File "/home/airflow/.local/lib/python3.7/site-packages/airflow/hooks/dbapi.py", line 181, in run
    with closing(self.get_conn()) as conn:
  File "/home/airflow/.local/lib/python3.7/site-packages/airflow/providers/postgres/hooks/postgres.py", line 113, in get_conn
    self.conn = psycopg2.connect(**conn_args)
  File "/home/airflow/.local/lib/python3.7/site-packages/psycopg2/__init__.py", line 122, in connect
    conn = _connect(dsn, connection_factory=connection_factory, **kwasync)
psycopg2.OperationalError: could not translate host name "host.docker.local " to address: Name or service not known

[2022-07-31 00:15:02,133] {taskinstance.py:1400} INFO - Marking task as UP_FOR_RETRY. dag_id=dag_with_postgres_operator, task_id=create_postgres_table, execution_date=20220108T000000, start_date=20220731T001501, end_date=20220731T001502
[2022-07-31 00:15:02,148] {standard_task_runner.py:97} ERROR - Failed to execute job 1127 for task create_postgres_table (could not translate host name "host.docker.local " to address: Name or service not known
; 5918)
[2022-07-31 00:15:02,159] {local_task_job.py:156} INFO - Task exited with return code 1
[2022-07-31 00:15:02,247] {local_task_job.py:273} INFO - 0 downstream tasks scheduled from follow-on schedule check
[2022-07-31 11:08:27,835] {taskinstance.py:1159} INFO - Dependencies all met for <TaskInstance: dag_with_postgres_operator.create_postgres_table scheduled__2022-01-08T00:00:00+00:00 [queued]>
[2022-07-31 11:08:27,863] {taskinstance.py:1159} INFO - Dependencies all met for <TaskInstance: dag_with_postgres_operator.create_postgres_table scheduled__2022-01-08T00:00:00+00:00 [queued]>
[2022-07-31 11:08:27,863] {taskinstance.py:1356} INFO - 
--------------------------------------------------------------------------------
[2022-07-31 11:08:27,863] {taskinstance.py:1357} INFO - Starting attempt 2 of 6
[2022-07-31 11:08:27,863] {taskinstance.py:1358} INFO - 
--------------------------------------------------------------------------------
[2022-07-31 11:08:27,886] {taskinstance.py:1377} INFO - Executing <Task(PostgresOperator): create_postgres_table> on 2022-01-08 00:00:00+00:00
[2022-07-31 11:08:27,892] {standard_task_runner.py:52} INFO - Started process 4795 to run task
[2022-07-31 11:08:27,896] {standard_task_runner.py:79} INFO - Running: ['***', 'tasks', 'run', 'dag_with_postgres_operator', 'create_postgres_table', 'scheduled__2022-01-08T00:00:00+00:00', '--job-id', '1579', '--raw', '--subdir', 'DAGS_FOLDER/DAGWithPostgresOperator.py', '--cfg-path', '/tmp/tmp0y5tx2qn', '--error-file', '/tmp/tmpaa8cme9a']
[2022-07-31 11:08:27,896] {standard_task_runner.py:80} INFO - Job 1579: Subtask create_postgres_table
[2022-07-31 11:08:27,971] {task_command.py:369} INFO - Running <TaskInstance: dag_with_postgres_operator.create_postgres_table scheduled__2022-01-08T00:00:00+00:00 [running]> on host 66bf18ec08cc
[2022-07-31 11:08:28,080] {taskinstance.py:1571} INFO - Exporting the following env vars:
AIRFLOW_CTX_DAG_OWNER=yosr
AIRFLOW_CTX_DAG_ID=dag_with_postgres_operator
AIRFLOW_CTX_TASK_ID=create_postgres_table
AIRFLOW_CTX_EXECUTION_DATE=2022-01-08T00:00:00+00:00
AIRFLOW_CTX_TRY_NUMBER=2
AIRFLOW_CTX_DAG_RUN_ID=scheduled__2022-01-08T00:00:00+00:00
[2022-07-31 11:08:28,095] {base.py:68} INFO - Using connection ID 'postgres_localhost' for task execution.
[2022-07-31 11:08:28,096] {taskinstance.py:1889} ERROR - Task failed with exception
Traceback (most recent call last):
  File "/home/airflow/.local/lib/python3.7/site-packages/airflow/providers/postgres/operators/postgres.py", line 92, in execute
    self.hook.run(self.sql, self.autocommit, parameters=self.parameters)
  File "/home/airflow/.local/lib/python3.7/site-packages/airflow/hooks/dbapi.py", line 181, in run
    with closing(self.get_conn()) as conn:
  File "/home/airflow/.local/lib/python3.7/site-packages/airflow/providers/postgres/hooks/postgres.py", line 113, in get_conn
    self.conn = psycopg2.connect(**conn_args)
  File "/home/airflow/.local/lib/python3.7/site-packages/psycopg2/__init__.py", line 122, in connect
    conn = _connect(dsn, connection_factory=connection_factory, **kwasync)
psycopg2.OperationalError: connection to server at "localhost" (127.0.0.1), port 5432 failed: Connection refused
	Is the server running on that host and accepting TCP/IP connections?
connection to server at "localhost" (::1), port 5432 failed: Cannot assign requested address
	Is the server running on that host and accepting TCP/IP connections?

[2022-07-31 11:08:28,114] {taskinstance.py:1400} INFO - Marking task as UP_FOR_RETRY. dag_id=dag_with_postgres_operator, task_id=create_postgres_table, execution_date=20220108T000000, start_date=20220731T110827, end_date=20220731T110828
[2022-07-31 11:08:28,132] {standard_task_runner.py:97} ERROR - Failed to execute job 1579 for task create_postgres_table (connection to server at "localhost" (127.0.0.1), port 5432 failed: Connection refused
	Is the server running on that host and accepting TCP/IP connections?
connection to server at "localhost" (::1), port 5432 failed: Cannot assign requested address
	Is the server running on that host and accepting TCP/IP connections?
; 4795)
[2022-07-31 11:08:28,155] {local_task_job.py:156} INFO - Task exited with return code 1
[2022-07-31 11:08:28,319] {local_task_job.py:273} INFO - 0 downstream tasks scheduled from follow-on schedule check
[2022-07-31 13:40:07,909] {taskinstance.py:1159} INFO - Dependencies all met for <TaskInstance: dag_with_postgres_operator.create_postgres_table scheduled__2022-01-08T00:00:00+00:00 [queued]>
[2022-07-31 13:40:07,946] {taskinstance.py:1159} INFO - Dependencies all met for <TaskInstance: dag_with_postgres_operator.create_postgres_table scheduled__2022-01-08T00:00:00+00:00 [queued]>
[2022-07-31 13:40:07,946] {taskinstance.py:1356} INFO - 
--------------------------------------------------------------------------------
[2022-07-31 13:40:07,946] {taskinstance.py:1357} INFO - Starting attempt 2 of 6
[2022-07-31 13:40:07,947] {taskinstance.py:1358} INFO - 
--------------------------------------------------------------------------------
[2022-07-31 13:40:07,966] {taskinstance.py:1377} INFO - Executing <Task(PostgresOperator): create_postgres_table> on 2022-01-08 00:00:00+00:00
[2022-07-31 13:40:07,973] {standard_task_runner.py:52} INFO - Started process 2387 to run task
[2022-07-31 13:40:07,983] {standard_task_runner.py:79} INFO - Running: ['***', 'tasks', 'run', 'dag_with_postgres_operator', 'create_postgres_table', 'scheduled__2022-01-08T00:00:00+00:00', '--job-id', '115', '--raw', '--subdir', 'DAGS_FOLDER/DAGWithPostgresOperator.py', '--cfg-path', '/tmp/tmp6dgveo9g', '--error-file', '/tmp/tmpsdgyie7u']
[2022-07-31 13:40:07,984] {standard_task_runner.py:80} INFO - Job 115: Subtask create_postgres_table
[2022-07-31 13:40:08,099] {task_command.py:369} INFO - Running <TaskInstance: dag_with_postgres_operator.create_postgres_table scheduled__2022-01-08T00:00:00+00:00 [running]> on host 4688dd3b7141
[2022-07-31 13:40:08,266] {taskinstance.py:1571} INFO - Exporting the following env vars:
AIRFLOW_CTX_DAG_OWNER=yosr
AIRFLOW_CTX_DAG_ID=dag_with_postgres_operator
AIRFLOW_CTX_TASK_ID=create_postgres_table
AIRFLOW_CTX_EXECUTION_DATE=2022-01-08T00:00:00+00:00
AIRFLOW_CTX_TRY_NUMBER=2
AIRFLOW_CTX_DAG_RUN_ID=scheduled__2022-01-08T00:00:00+00:00
[2022-07-31 13:40:08,321] {taskinstance.py:1889} ERROR - Task failed with exception
Traceback (most recent call last):
  File "/home/airflow/.local/lib/python3.7/site-packages/airflow/providers/postgres/operators/postgres.py", line 92, in execute
    self.hook.run(self.sql, self.autocommit, parameters=self.parameters)
  File "/home/airflow/.local/lib/python3.7/site-packages/airflow/hooks/dbapi.py", line 181, in run
    with closing(self.get_conn()) as conn:
  File "/home/airflow/.local/lib/python3.7/site-packages/airflow/providers/postgres/hooks/postgres.py", line 86, in get_conn
    conn = deepcopy(self.connection or self.get_connection(conn_id))
  File "/home/airflow/.local/lib/python3.7/site-packages/airflow/hooks/base.py", line 67, in get_connection
    conn = Connection.get_connection_from_secrets(conn_id)
  File "/home/airflow/.local/lib/python3.7/site-packages/airflow/models/connection.py", line 430, in get_connection_from_secrets
    raise AirflowNotFoundException(f"The conn_id `{conn_id}` isn't defined")
airflow.exceptions.AirflowNotFoundException: The conn_id `postgres_localhost` isn't defined
[2022-07-31 13:40:08,328] {taskinstance.py:1400} INFO - Marking task as UP_FOR_RETRY. dag_id=dag_with_postgres_operator, task_id=create_postgres_table, execution_date=20220108T000000, start_date=20220731T134007, end_date=20220731T134008
[2022-07-31 13:40:08,357] {standard_task_runner.py:97} ERROR - Failed to execute job 115 for task create_postgres_table (The conn_id `postgres_localhost` isn't defined; 2387)
[2022-07-31 13:40:08,373] {local_task_job.py:156} INFO - Task exited with return code 1
[2022-07-31 13:40:08,440] {local_task_job.py:273} INFO - 0 downstream tasks scheduled from follow-on schedule check
