[2022-07-30 19:09:17,941] {taskinstance.py:1159} INFO - Dependencies all met for <TaskInstance: dag_with_postgres_operator.create_postgres_table scheduled__2022-02-06T00:00:00+00:00 [queued]>
[2022-07-30 19:09:17,955] {taskinstance.py:1159} INFO - Dependencies all met for <TaskInstance: dag_with_postgres_operator.create_postgres_table scheduled__2022-02-06T00:00:00+00:00 [queued]>
[2022-07-30 19:09:17,955] {taskinstance.py:1356} INFO - 
--------------------------------------------------------------------------------
[2022-07-30 19:09:17,955] {taskinstance.py:1357} INFO - Starting attempt 4 of 6
[2022-07-30 19:09:17,955] {taskinstance.py:1358} INFO - 
--------------------------------------------------------------------------------
[2022-07-30 19:09:17,977] {taskinstance.py:1377} INFO - Executing <Task(PostgresOperator): create_postgres_table> on 2022-02-06 00:00:00+00:00
[2022-07-30 19:09:17,981] {standard_task_runner.py:52} INFO - Started process 5240 to run task
[2022-07-30 19:09:17,983] {standard_task_runner.py:79} INFO - Running: ['***', 'tasks', 'run', 'dag_with_postgres_operator', 'create_postgres_table', 'scheduled__2022-02-06T00:00:00+00:00', '--job-id', '340', '--raw', '--subdir', 'DAGS_FOLDER/DAGWithPostgresOperator.py', '--cfg-path', '/tmp/tmp7sx1sz1k', '--error-file', '/tmp/tmp58g1aq4h']
[2022-07-30 19:09:17,984] {standard_task_runner.py:80} INFO - Job 340: Subtask create_postgres_table
[2022-07-30 19:09:18,050] {task_command.py:369} INFO - Running <TaskInstance: dag_with_postgres_operator.create_postgres_table scheduled__2022-02-06T00:00:00+00:00 [running]> on host 66bf18ec08cc
[2022-07-30 19:09:18,142] {taskinstance.py:1571} INFO - Exporting the following env vars:
AIRFLOW_CTX_DAG_OWNER=yosr
AIRFLOW_CTX_DAG_ID=dag_with_postgres_operator
AIRFLOW_CTX_TASK_ID=create_postgres_table
AIRFLOW_CTX_EXECUTION_DATE=2022-02-06T00:00:00+00:00
AIRFLOW_CTX_TRY_NUMBER=4
AIRFLOW_CTX_DAG_RUN_ID=scheduled__2022-02-06T00:00:00+00:00
[2022-07-30 19:09:18,155] {base.py:68} INFO - Using connection ID 'postgres_localhost' for task execution.
[2022-07-30 19:09:18,156] {taskinstance.py:1889} ERROR - Task failed with exception
Traceback (most recent call last):
  File "/home/airflow/.local/lib/python3.7/site-packages/airflow/providers/postgres/operators/postgres.py", line 92, in execute
    self.hook.run(self.sql, self.autocommit, parameters=self.parameters)
  File "/home/airflow/.local/lib/python3.7/site-packages/airflow/hooks/dbapi.py", line 181, in run
    with closing(self.get_conn()) as conn:
  File "/home/airflow/.local/lib/python3.7/site-packages/airflow/providers/postgres/hooks/postgres.py", line 113, in get_conn
    self.conn = psycopg2.connect(**conn_args)
  File "/home/airflow/.local/lib/python3.7/site-packages/psycopg2/__init__.py", line 122, in connect
    conn = _connect(dsn, connection_factory=connection_factory, **kwasync)
psycopg2.OperationalError: could not translate host name "host.docker.internal " to address: Name or service not known

[2022-07-30 19:09:18,168] {taskinstance.py:1400} INFO - Marking task as UP_FOR_RETRY. dag_id=dag_with_postgres_operator, task_id=create_postgres_table, execution_date=20220206T000000, start_date=20220730T190917, end_date=20220730T190918
[2022-07-30 19:09:18,182] {standard_task_runner.py:97} ERROR - Failed to execute job 340 for task create_postgres_table (could not translate host name "host.docker.internal " to address: Name or service not known
; 5240)
[2022-07-30 19:09:18,201] {local_task_job.py:156} INFO - Task exited with return code 1
[2022-07-30 19:09:18,368] {local_task_job.py:273} INFO - 0 downstream tasks scheduled from follow-on schedule check
[2022-07-31 10:11:34,948] {taskinstance.py:1159} INFO - Dependencies all met for <TaskInstance: dag_with_postgres_operator.create_postgres_table scheduled__2022-02-06T00:00:00+00:00 [queued]>
[2022-07-31 10:11:34,965] {taskinstance.py:1159} INFO - Dependencies all met for <TaskInstance: dag_with_postgres_operator.create_postgres_table scheduled__2022-02-06T00:00:00+00:00 [queued]>
[2022-07-31 10:11:34,966] {taskinstance.py:1356} INFO - 
--------------------------------------------------------------------------------
[2022-07-31 10:11:34,966] {taskinstance.py:1357} INFO - Starting attempt 4 of 6
[2022-07-31 10:11:34,966] {taskinstance.py:1358} INFO - 
--------------------------------------------------------------------------------
[2022-07-31 10:11:34,993] {taskinstance.py:1377} INFO - Executing <Task(PostgresOperator): create_postgres_table> on 2022-02-06 00:00:00+00:00
[2022-07-31 10:11:34,998] {standard_task_runner.py:52} INFO - Started process 1718 to run task
[2022-07-31 10:11:35,004] {standard_task_runner.py:79} INFO - Running: ['***', 'tasks', 'run', 'dag_with_postgres_operator', 'create_postgres_table', 'scheduled__2022-02-06T00:00:00+00:00', '--job-id', '1352', '--raw', '--subdir', 'DAGS_FOLDER/DAGWithPostgresOperator.py', '--cfg-path', '/tmp/tmpb1hyl1j4', '--error-file', '/tmp/tmppw8yq_qj']
[2022-07-31 10:11:35,005] {standard_task_runner.py:80} INFO - Job 1352: Subtask create_postgres_table
[2022-07-31 10:11:35,092] {task_command.py:369} INFO - Running <TaskInstance: dag_with_postgres_operator.create_postgres_table scheduled__2022-02-06T00:00:00+00:00 [running]> on host 66bf18ec08cc
[2022-07-31 10:11:35,203] {taskinstance.py:1571} INFO - Exporting the following env vars:
AIRFLOW_CTX_DAG_OWNER=yosr
AIRFLOW_CTX_DAG_ID=dag_with_postgres_operator
AIRFLOW_CTX_TASK_ID=create_postgres_table
AIRFLOW_CTX_EXECUTION_DATE=2022-02-06T00:00:00+00:00
AIRFLOW_CTX_TRY_NUMBER=4
AIRFLOW_CTX_DAG_RUN_ID=scheduled__2022-02-06T00:00:00+00:00
[2022-07-31 10:11:35,224] {base.py:68} INFO - Using connection ID 'postgres_localhost' for task execution.
[2022-07-31 10:11:35,226] {taskinstance.py:1889} ERROR - Task failed with exception
Traceback (most recent call last):
  File "/home/airflow/.local/lib/python3.7/site-packages/airflow/providers/postgres/operators/postgres.py", line 92, in execute
    self.hook.run(self.sql, self.autocommit, parameters=self.parameters)
  File "/home/airflow/.local/lib/python3.7/site-packages/airflow/hooks/dbapi.py", line 181, in run
    with closing(self.get_conn()) as conn:
  File "/home/airflow/.local/lib/python3.7/site-packages/airflow/providers/postgres/hooks/postgres.py", line 113, in get_conn
    self.conn = psycopg2.connect(**conn_args)
  File "/home/airflow/.local/lib/python3.7/site-packages/psycopg2/__init__.py", line 122, in connect
    conn = _connect(dsn, connection_factory=connection_factory, **kwasync)
psycopg2.OperationalError: could not translate host name "host.docker.local " to address: Name or service not known

[2022-07-31 10:11:35,245] {taskinstance.py:1400} INFO - Marking task as UP_FOR_RETRY. dag_id=dag_with_postgres_operator, task_id=create_postgres_table, execution_date=20220206T000000, start_date=20220731T101134, end_date=20220731T101135
[2022-07-31 10:11:35,263] {standard_task_runner.py:97} ERROR - Failed to execute job 1352 for task create_postgres_table (could not translate host name "host.docker.local " to address: Name or service not known
; 1718)
[2022-07-31 10:11:35,304] {local_task_job.py:156} INFO - Task exited with return code 1
[2022-07-31 10:11:35,386] {local_task_job.py:273} INFO - 0 downstream tasks scheduled from follow-on schedule check
[2022-07-31 14:40:53,582] {taskinstance.py:1159} INFO - Dependencies all met for <TaskInstance: dag_with_postgres_operator.create_postgres_table scheduled__2022-02-06T00:00:00+00:00 [queued]>
[2022-07-31 14:40:53,603] {taskinstance.py:1159} INFO - Dependencies all met for <TaskInstance: dag_with_postgres_operator.create_postgres_table scheduled__2022-02-06T00:00:00+00:00 [queued]>
[2022-07-31 14:40:53,603] {taskinstance.py:1356} INFO - 
--------------------------------------------------------------------------------
[2022-07-31 14:40:53,603] {taskinstance.py:1357} INFO - Starting attempt 4 of 6
[2022-07-31 14:40:53,603] {taskinstance.py:1358} INFO - 
--------------------------------------------------------------------------------
[2022-07-31 14:40:53,626] {taskinstance.py:1377} INFO - Executing <Task(PostgresOperator): create_postgres_table> on 2022-02-06 00:00:00+00:00
[2022-07-31 14:40:53,633] {standard_task_runner.py:52} INFO - Started process 5672 to run task
[2022-07-31 14:40:53,643] {standard_task_runner.py:79} INFO - Running: ['***', 'tasks', 'run', 'dag_with_postgres_operator', 'create_postgres_table', 'scheduled__2022-02-06T00:00:00+00:00', '--job-id', '344', '--raw', '--subdir', 'DAGS_FOLDER/DAGWithPostgresOperator.py', '--cfg-path', '/tmp/tmpgzy3ah8y', '--error-file', '/tmp/tmpwqe9qmkf']
[2022-07-31 14:40:53,643] {standard_task_runner.py:80} INFO - Job 344: Subtask create_postgres_table
[2022-07-31 14:40:53,776] {task_command.py:369} INFO - Running <TaskInstance: dag_with_postgres_operator.create_postgres_table scheduled__2022-02-06T00:00:00+00:00 [running]> on host 4688dd3b7141
[2022-07-31 14:40:53,917] {taskinstance.py:1571} INFO - Exporting the following env vars:
AIRFLOW_CTX_DAG_OWNER=yosr
AIRFLOW_CTX_DAG_ID=dag_with_postgres_operator
AIRFLOW_CTX_TASK_ID=create_postgres_table
AIRFLOW_CTX_EXECUTION_DATE=2022-02-06T00:00:00+00:00
AIRFLOW_CTX_TRY_NUMBER=4
AIRFLOW_CTX_DAG_RUN_ID=scheduled__2022-02-06T00:00:00+00:00
[2022-07-31 14:40:53,944] {base.py:68} INFO - Using connection ID 'postgres_localhost' for task execution.
[2022-07-31 14:41:08,960] {taskinstance.py:1889} ERROR - Task failed with exception
Traceback (most recent call last):
  File "/home/airflow/.local/lib/python3.7/site-packages/airflow/providers/postgres/operators/postgres.py", line 92, in execute
    self.hook.run(self.sql, self.autocommit, parameters=self.parameters)
  File "/home/airflow/.local/lib/python3.7/site-packages/airflow/hooks/dbapi.py", line 181, in run
    with closing(self.get_conn()) as conn:
  File "/home/airflow/.local/lib/python3.7/site-packages/airflow/providers/postgres/hooks/postgres.py", line 113, in get_conn
    self.conn = psycopg2.connect(**conn_args)
  File "/home/airflow/.local/lib/python3.7/site-packages/psycopg2/__init__.py", line 122, in connect
    conn = _connect(dsn, connection_factory=connection_factory, **kwasync)
psycopg2.OperationalError: could not translate host name "host.docker.local" to address: Temporary failure in name resolution

[2022-07-31 14:41:08,983] {taskinstance.py:1400} INFO - Marking task as UP_FOR_RETRY. dag_id=dag_with_postgres_operator, task_id=create_postgres_table, execution_date=20220206T000000, start_date=20220731T144053, end_date=20220731T144108
[2022-07-31 14:41:09,007] {standard_task_runner.py:97} ERROR - Failed to execute job 344 for task create_postgres_table (could not translate host name "host.docker.local" to address: Temporary failure in name resolution
; 5672)
[2022-07-31 14:41:09,032] {local_task_job.py:156} INFO - Task exited with return code 1
[2022-07-31 14:41:09,078] {local_task_job.py:273} INFO - 0 downstream tasks scheduled from follow-on schedule check
