[2022-07-30 17:38:11,598] {taskinstance.py:1159} INFO - Dependencies all met for <TaskInstance: dag_with_postgres_operator.create_postgres_table scheduled__2021-12-20T00:00:00+00:00 [queued]>
[2022-07-30 17:38:11,618] {taskinstance.py:1159} INFO - Dependencies all met for <TaskInstance: dag_with_postgres_operator.create_postgres_table scheduled__2021-12-20T00:00:00+00:00 [queued]>
[2022-07-30 17:38:11,618] {taskinstance.py:1356} INFO - 
--------------------------------------------------------------------------------
[2022-07-30 17:38:11,618] {taskinstance.py:1357} INFO - Starting attempt 1 of 6
[2022-07-30 17:38:11,618] {taskinstance.py:1358} INFO - 
--------------------------------------------------------------------------------
[2022-07-30 17:38:11,652] {taskinstance.py:1377} INFO - Executing <Task(PostgresOperator): create_postgres_table> on 2021-12-20 00:00:00+00:00
[2022-07-30 17:38:11,658] {standard_task_runner.py:52} INFO - Started process 365 to run task
[2022-07-30 17:38:11,661] {standard_task_runner.py:79} INFO - Running: ['***', 'tasks', 'run', 'dag_with_postgres_operator', 'create_postgres_table', 'scheduled__2021-12-20T00:00:00+00:00', '--job-id', '4', '--raw', '--subdir', 'DAGS_FOLDER/DAGWithPostgresOperator.py', '--cfg-path', '/tmp/tmp1d1fq1d7', '--error-file', '/tmp/tmp53prvrp9']
[2022-07-30 17:38:11,662] {standard_task_runner.py:80} INFO - Job 4: Subtask create_postgres_table
[2022-07-30 17:38:11,770] {task_command.py:369} INFO - Running <TaskInstance: dag_with_postgres_operator.create_postgres_table scheduled__2021-12-20T00:00:00+00:00 [running]> on host 66bf18ec08cc
[2022-07-30 17:38:11,913] {taskinstance.py:1571} INFO - Exporting the following env vars:
AIRFLOW_CTX_DAG_OWNER=yosr
AIRFLOW_CTX_DAG_ID=dag_with_postgres_operator
AIRFLOW_CTX_TASK_ID=create_postgres_table
AIRFLOW_CTX_EXECUTION_DATE=2021-12-20T00:00:00+00:00
AIRFLOW_CTX_TRY_NUMBER=1
AIRFLOW_CTX_DAG_RUN_ID=scheduled__2021-12-20T00:00:00+00:00
[2022-07-30 17:38:11,958] {taskinstance.py:1889} ERROR - Task failed with exception
Traceback (most recent call last):
  File "/home/airflow/.local/lib/python3.7/site-packages/airflow/providers/postgres/operators/postgres.py", line 92, in execute
    self.hook.run(self.sql, self.autocommit, parameters=self.parameters)
  File "/home/airflow/.local/lib/python3.7/site-packages/airflow/hooks/dbapi.py", line 181, in run
    with closing(self.get_conn()) as conn:
  File "/home/airflow/.local/lib/python3.7/site-packages/airflow/providers/postgres/hooks/postgres.py", line 86, in get_conn
    conn = deepcopy(self.connection or self.get_connection(conn_id))
  File "/home/airflow/.local/lib/python3.7/site-packages/airflow/hooks/base.py", line 67, in get_connection
    conn = Connection.get_connection_from_secrets(conn_id)
  File "/home/airflow/.local/lib/python3.7/site-packages/airflow/models/connection.py", line 430, in get_connection_from_secrets
    raise AirflowNotFoundException(f"The conn_id `{conn_id}` isn't defined")
airflow.exceptions.AirflowNotFoundException: The conn_id `postgres_localhost` isn't defined
[2022-07-30 17:38:11,966] {taskinstance.py:1400} INFO - Marking task as UP_FOR_RETRY. dag_id=dag_with_postgres_operator, task_id=create_postgres_table, execution_date=20211220T000000, start_date=20220730T173811, end_date=20220730T173811
[2022-07-30 17:38:11,990] {standard_task_runner.py:97} ERROR - Failed to execute job 4 for task create_postgres_table (The conn_id `postgres_localhost` isn't defined; 365)
[2022-07-30 17:38:12,044] {local_task_job.py:156} INFO - Task exited with return code 1
[2022-07-30 17:38:12,115] {local_task_job.py:273} INFO - 0 downstream tasks scheduled from follow-on schedule check
[2022-07-30 23:44:45,673] {taskinstance.py:1159} INFO - Dependencies all met for <TaskInstance: dag_with_postgres_operator.create_postgres_table scheduled__2021-12-20T00:00:00+00:00 [queued]>
[2022-07-30 23:44:45,694] {taskinstance.py:1159} INFO - Dependencies all met for <TaskInstance: dag_with_postgres_operator.create_postgres_table scheduled__2021-12-20T00:00:00+00:00 [queued]>
[2022-07-30 23:44:45,694] {taskinstance.py:1356} INFO - 
--------------------------------------------------------------------------------
[2022-07-30 23:44:45,694] {taskinstance.py:1357} INFO - Starting attempt 1 of 6
[2022-07-30 23:44:45,694] {taskinstance.py:1358} INFO - 
--------------------------------------------------------------------------------
[2022-07-30 23:44:45,716] {taskinstance.py:1377} INFO - Executing <Task(PostgresOperator): create_postgres_table> on 2021-12-20 00:00:00+00:00
[2022-07-30 23:44:45,720] {standard_task_runner.py:52} INFO - Started process 4294 to run task
[2022-07-30 23:44:45,724] {standard_task_runner.py:79} INFO - Running: ['***', 'tasks', 'run', 'dag_with_postgres_operator', 'create_postgres_table', 'scheduled__2021-12-20T00:00:00+00:00', '--job-id', '1012', '--raw', '--subdir', 'DAGS_FOLDER/DAGWithPostgresOperator.py', '--cfg-path', '/tmp/tmphc73r1r3', '--error-file', '/tmp/tmpdrordvhf']
[2022-07-30 23:44:45,724] {standard_task_runner.py:80} INFO - Job 1012: Subtask create_postgres_table
[2022-07-30 23:44:45,801] {task_command.py:369} INFO - Running <TaskInstance: dag_with_postgres_operator.create_postgres_table scheduled__2021-12-20T00:00:00+00:00 [running]> on host 66bf18ec08cc
[2022-07-30 23:44:45,901] {taskinstance.py:1571} INFO - Exporting the following env vars:
AIRFLOW_CTX_DAG_OWNER=yosr
AIRFLOW_CTX_DAG_ID=dag_with_postgres_operator
AIRFLOW_CTX_TASK_ID=create_postgres_table
AIRFLOW_CTX_EXECUTION_DATE=2021-12-20T00:00:00+00:00
AIRFLOW_CTX_TRY_NUMBER=1
AIRFLOW_CTX_DAG_RUN_ID=scheduled__2021-12-20T00:00:00+00:00
[2022-07-30 23:44:45,920] {base.py:68} INFO - Using connection ID 'postgres_localhost' for task execution.
[2022-07-30 23:44:45,922] {taskinstance.py:1889} ERROR - Task failed with exception
Traceback (most recent call last):
  File "/home/airflow/.local/lib/python3.7/site-packages/airflow/providers/postgres/operators/postgres.py", line 92, in execute
    self.hook.run(self.sql, self.autocommit, parameters=self.parameters)
  File "/home/airflow/.local/lib/python3.7/site-packages/airflow/hooks/dbapi.py", line 181, in run
    with closing(self.get_conn()) as conn:
  File "/home/airflow/.local/lib/python3.7/site-packages/airflow/providers/postgres/hooks/postgres.py", line 113, in get_conn
    self.conn = psycopg2.connect(**conn_args)
  File "/home/airflow/.local/lib/python3.7/site-packages/psycopg2/__init__.py", line 122, in connect
    conn = _connect(dsn, connection_factory=connection_factory, **kwasync)
psycopg2.OperationalError: could not translate host name "host.docker.local " to address: Name or service not known

[2022-07-30 23:44:45,942] {taskinstance.py:1400} INFO - Marking task as UP_FOR_RETRY. dag_id=dag_with_postgres_operator, task_id=create_postgres_table, execution_date=20211220T000000, start_date=20220730T234445, end_date=20220730T234445
[2022-07-30 23:44:45,966] {standard_task_runner.py:97} ERROR - Failed to execute job 1012 for task create_postgres_table (could not translate host name "host.docker.local " to address: Name or service not known
; 4294)
[2022-07-30 23:44:45,989] {local_task_job.py:156} INFO - Task exited with return code 1
[2022-07-30 23:44:46,053] {local_task_job.py:273} INFO - 0 downstream tasks scheduled from follow-on schedule check
[2022-07-31 10:26:01,192] {taskinstance.py:1159} INFO - Dependencies all met for <TaskInstance: dag_with_postgres_operator.create_postgres_table scheduled__2021-12-20T00:00:00+00:00 [queued]>
[2022-07-31 10:26:01,214] {taskinstance.py:1159} INFO - Dependencies all met for <TaskInstance: dag_with_postgres_operator.create_postgres_table scheduled__2021-12-20T00:00:00+00:00 [queued]>
[2022-07-31 10:26:01,214] {taskinstance.py:1356} INFO - 
--------------------------------------------------------------------------------
[2022-07-31 10:26:01,214] {taskinstance.py:1357} INFO - Starting attempt 1 of 6
[2022-07-31 10:26:01,214] {taskinstance.py:1358} INFO - 
--------------------------------------------------------------------------------
[2022-07-31 10:26:01,239] {taskinstance.py:1377} INFO - Executing <Task(PostgresOperator): create_postgres_table> on 2021-12-20 00:00:00+00:00
[2022-07-31 10:26:01,244] {standard_task_runner.py:52} INFO - Started process 2512 to run task
[2022-07-31 10:26:01,249] {standard_task_runner.py:79} INFO - Running: ['***', 'tasks', 'run', 'dag_with_postgres_operator', 'create_postgres_table', 'scheduled__2021-12-20T00:00:00+00:00', '--job-id', '1414', '--raw', '--subdir', 'DAGS_FOLDER/DAGWithPostgresOperator.py', '--cfg-path', '/tmp/tmpua49q7kc', '--error-file', '/tmp/tmpouq6b51d']
[2022-07-31 10:26:01,250] {standard_task_runner.py:80} INFO - Job 1414: Subtask create_postgres_table
[2022-07-31 10:26:01,333] {task_command.py:369} INFO - Running <TaskInstance: dag_with_postgres_operator.create_postgres_table scheduled__2021-12-20T00:00:00+00:00 [running]> on host 66bf18ec08cc
[2022-07-31 10:26:01,437] {taskinstance.py:1571} INFO - Exporting the following env vars:
AIRFLOW_CTX_DAG_OWNER=yosr
AIRFLOW_CTX_DAG_ID=dag_with_postgres_operator
AIRFLOW_CTX_TASK_ID=create_postgres_table
AIRFLOW_CTX_EXECUTION_DATE=2021-12-20T00:00:00+00:00
AIRFLOW_CTX_TRY_NUMBER=1
AIRFLOW_CTX_DAG_RUN_ID=scheduled__2021-12-20T00:00:00+00:00
[2022-07-31 10:26:01,453] {base.py:68} INFO - Using connection ID 'postgres_localhost' for task execution.
[2022-07-31 10:26:01,454] {taskinstance.py:1889} ERROR - Task failed with exception
Traceback (most recent call last):
  File "/home/airflow/.local/lib/python3.7/site-packages/airflow/providers/postgres/operators/postgres.py", line 92, in execute
    self.hook.run(self.sql, self.autocommit, parameters=self.parameters)
  File "/home/airflow/.local/lib/python3.7/site-packages/airflow/hooks/dbapi.py", line 181, in run
    with closing(self.get_conn()) as conn:
  File "/home/airflow/.local/lib/python3.7/site-packages/airflow/providers/postgres/hooks/postgres.py", line 113, in get_conn
    self.conn = psycopg2.connect(**conn_args)
  File "/home/airflow/.local/lib/python3.7/site-packages/psycopg2/__init__.py", line 122, in connect
    conn = _connect(dsn, connection_factory=connection_factory, **kwasync)
psycopg2.OperationalError: could not translate host name "host.docker.local " to address: Name or service not known

[2022-07-31 10:26:01,467] {taskinstance.py:1400} INFO - Marking task as UP_FOR_RETRY. dag_id=dag_with_postgres_operator, task_id=create_postgres_table, execution_date=20211220T000000, start_date=20220731T102601, end_date=20220731T102601
[2022-07-31 10:26:01,484] {standard_task_runner.py:97} ERROR - Failed to execute job 1414 for task create_postgres_table (could not translate host name "host.docker.local " to address: Name or service not known
; 2512)
[2022-07-31 10:26:01,506] {local_task_job.py:156} INFO - Task exited with return code 1
[2022-07-31 10:26:01,608] {local_task_job.py:273} INFO - 0 downstream tasks scheduled from follow-on schedule check
[2022-07-31 10:38:09,940] {taskinstance.py:1159} INFO - Dependencies all met for <TaskInstance: dag_with_postgres_operator.create_postgres_table scheduled__2021-12-20T00:00:00+00:00 [queued]>
[2022-07-31 10:38:09,963] {taskinstance.py:1159} INFO - Dependencies all met for <TaskInstance: dag_with_postgres_operator.create_postgres_table scheduled__2021-12-20T00:00:00+00:00 [queued]>
[2022-07-31 10:38:09,963] {taskinstance.py:1356} INFO - 
--------------------------------------------------------------------------------
[2022-07-31 10:38:09,963] {taskinstance.py:1357} INFO - Starting attempt 1 of 6
[2022-07-31 10:38:09,963] {taskinstance.py:1358} INFO - 
--------------------------------------------------------------------------------
[2022-07-31 10:38:09,992] {taskinstance.py:1377} INFO - Executing <Task(PostgresOperator): create_postgres_table> on 2021-12-20 00:00:00+00:00
[2022-07-31 10:38:09,997] {standard_task_runner.py:52} INFO - Started process 3158 to run task
[2022-07-31 10:38:10,003] {standard_task_runner.py:79} INFO - Running: ['***', 'tasks', 'run', 'dag_with_postgres_operator', 'create_postgres_table', 'scheduled__2021-12-20T00:00:00+00:00', '--job-id', '1462', '--raw', '--subdir', 'DAGS_FOLDER/DAGWithPostgresOperator.py', '--cfg-path', '/tmp/tmprlxuve33', '--error-file', '/tmp/tmpb4kn3kok']
[2022-07-31 10:38:10,003] {standard_task_runner.py:80} INFO - Job 1462: Subtask create_postgres_table
[2022-07-31 10:38:10,106] {task_command.py:369} INFO - Running <TaskInstance: dag_with_postgres_operator.create_postgres_table scheduled__2021-12-20T00:00:00+00:00 [running]> on host 66bf18ec08cc
[2022-07-31 10:38:10,247] {taskinstance.py:1571} INFO - Exporting the following env vars:
AIRFLOW_CTX_DAG_OWNER=yosr
AIRFLOW_CTX_DAG_ID=dag_with_postgres_operator
AIRFLOW_CTX_TASK_ID=create_postgres_table
AIRFLOW_CTX_EXECUTION_DATE=2021-12-20T00:00:00+00:00
AIRFLOW_CTX_TRY_NUMBER=1
AIRFLOW_CTX_DAG_RUN_ID=scheduled__2021-12-20T00:00:00+00:00
[2022-07-31 10:38:10,275] {base.py:68} INFO - Using connection ID 'postgres_localhost' for task execution.
[2022-07-31 10:38:10,277] {taskinstance.py:1889} ERROR - Task failed with exception
Traceback (most recent call last):
  File "/home/airflow/.local/lib/python3.7/site-packages/airflow/providers/postgres/operators/postgres.py", line 92, in execute
    self.hook.run(self.sql, self.autocommit, parameters=self.parameters)
  File "/home/airflow/.local/lib/python3.7/site-packages/airflow/hooks/dbapi.py", line 181, in run
    with closing(self.get_conn()) as conn:
  File "/home/airflow/.local/lib/python3.7/site-packages/airflow/providers/postgres/hooks/postgres.py", line 113, in get_conn
    self.conn = psycopg2.connect(**conn_args)
  File "/home/airflow/.local/lib/python3.7/site-packages/psycopg2/__init__.py", line 122, in connect
    conn = _connect(dsn, connection_factory=connection_factory, **kwasync)
psycopg2.OperationalError: could not translate host name "host.docker.internal " to address: Name or service not known

[2022-07-31 10:38:10,297] {taskinstance.py:1400} INFO - Marking task as UP_FOR_RETRY. dag_id=dag_with_postgres_operator, task_id=create_postgres_table, execution_date=20211220T000000, start_date=20220731T103809, end_date=20220731T103810
[2022-07-31 10:38:10,322] {standard_task_runner.py:97} ERROR - Failed to execute job 1462 for task create_postgres_table (could not translate host name "host.docker.internal " to address: Name or service not known
; 3158)
[2022-07-31 10:38:10,354] {local_task_job.py:156} INFO - Task exited with return code 1
[2022-07-31 10:38:10,463] {local_task_job.py:273} INFO - 0 downstream tasks scheduled from follow-on schedule check
[2022-07-31 13:09:54,876] {taskinstance.py:1159} INFO - Dependencies all met for <TaskInstance: dag_with_postgres_operator.create_postgres_table scheduled__2021-12-20T00:00:00+00:00 [queued]>
[2022-07-31 13:09:54,893] {taskinstance.py:1159} INFO - Dependencies all met for <TaskInstance: dag_with_postgres_operator.create_postgres_table scheduled__2021-12-20T00:00:00+00:00 [queued]>
[2022-07-31 13:09:54,893] {taskinstance.py:1356} INFO - 
--------------------------------------------------------------------------------
[2022-07-31 13:09:54,893] {taskinstance.py:1357} INFO - Starting attempt 1 of 6
[2022-07-31 13:09:54,893] {taskinstance.py:1358} INFO - 
--------------------------------------------------------------------------------
[2022-07-31 13:09:54,916] {taskinstance.py:1377} INFO - Executing <Task(PostgresOperator): create_postgres_table> on 2021-12-20 00:00:00+00:00
[2022-07-31 13:09:54,921] {standard_task_runner.py:52} INFO - Started process 767 to run task
[2022-07-31 13:09:54,924] {standard_task_runner.py:79} INFO - Running: ['***', 'tasks', 'run', 'dag_with_postgres_operator', 'create_postgres_table', 'scheduled__2021-12-20T00:00:00+00:00', '--job-id', '4', '--raw', '--subdir', 'DAGS_FOLDER/DAGWithPostgresOperator.py', '--cfg-path', '/tmp/tmppuc_c4w8', '--error-file', '/tmp/tmpjr7qy7rv']
[2022-07-31 13:09:54,924] {standard_task_runner.py:80} INFO - Job 4: Subtask create_postgres_table
[2022-07-31 13:09:54,996] {task_command.py:369} INFO - Running <TaskInstance: dag_with_postgres_operator.create_postgres_table scheduled__2021-12-20T00:00:00+00:00 [running]> on host 4688dd3b7141
[2022-07-31 13:09:55,113] {taskinstance.py:1571} INFO - Exporting the following env vars:
AIRFLOW_CTX_DAG_OWNER=yosr
AIRFLOW_CTX_DAG_ID=dag_with_postgres_operator
AIRFLOW_CTX_TASK_ID=create_postgres_table
AIRFLOW_CTX_EXECUTION_DATE=2021-12-20T00:00:00+00:00
AIRFLOW_CTX_TRY_NUMBER=1
AIRFLOW_CTX_DAG_RUN_ID=scheduled__2021-12-20T00:00:00+00:00
[2022-07-31 13:09:55,189] {taskinstance.py:1889} ERROR - Task failed with exception
Traceback (most recent call last):
  File "/home/airflow/.local/lib/python3.7/site-packages/airflow/providers/postgres/operators/postgres.py", line 92, in execute
    self.hook.run(self.sql, self.autocommit, parameters=self.parameters)
  File "/home/airflow/.local/lib/python3.7/site-packages/airflow/hooks/dbapi.py", line 181, in run
    with closing(self.get_conn()) as conn:
  File "/home/airflow/.local/lib/python3.7/site-packages/airflow/providers/postgres/hooks/postgres.py", line 86, in get_conn
    conn = deepcopy(self.connection or self.get_connection(conn_id))
  File "/home/airflow/.local/lib/python3.7/site-packages/airflow/hooks/base.py", line 67, in get_connection
    conn = Connection.get_connection_from_secrets(conn_id)
  File "/home/airflow/.local/lib/python3.7/site-packages/airflow/models/connection.py", line 430, in get_connection_from_secrets
    raise AirflowNotFoundException(f"The conn_id `{conn_id}` isn't defined")
airflow.exceptions.AirflowNotFoundException: The conn_id `postgres_localhost` isn't defined
[2022-07-31 13:09:55,194] {taskinstance.py:1400} INFO - Marking task as UP_FOR_RETRY. dag_id=dag_with_postgres_operator, task_id=create_postgres_table, execution_date=20211220T000000, start_date=20220731T130954, end_date=20220731T130955
[2022-07-31 13:09:55,211] {standard_task_runner.py:97} ERROR - Failed to execute job 4 for task create_postgres_table (The conn_id `postgres_localhost` isn't defined; 767)
[2022-07-31 13:09:55,224] {local_task_job.py:156} INFO - Task exited with return code 1
[2022-07-31 13:09:55,272] {local_task_job.py:273} INFO - 0 downstream tasks scheduled from follow-on schedule check
