[2022-07-30 19:39:39,171] {taskinstance.py:1159} INFO - Dependencies all met for <TaskInstance: dag_with_postgres_operator.create_postgres_table scheduled__2022-03-01T00:00:00+00:00 [queued]>
[2022-07-30 19:39:39,191] {taskinstance.py:1159} INFO - Dependencies all met for <TaskInstance: dag_with_postgres_operator.create_postgres_table scheduled__2022-03-01T00:00:00+00:00 [queued]>
[2022-07-30 19:39:39,191] {taskinstance.py:1356} INFO - 
--------------------------------------------------------------------------------
[2022-07-30 19:39:39,191] {taskinstance.py:1357} INFO - Starting attempt 5 of 6
[2022-07-30 19:39:39,191] {taskinstance.py:1358} INFO - 
--------------------------------------------------------------------------------
[2022-07-30 19:39:39,213] {taskinstance.py:1377} INFO - Executing <Task(PostgresOperator): create_postgres_table> on 2022-03-01 00:00:00+00:00
[2022-07-30 19:39:39,231] {standard_task_runner.py:52} INFO - Started process 6883 to run task
[2022-07-30 19:39:39,235] {standard_task_runner.py:79} INFO - Running: ['***', 'tasks', 'run', 'dag_with_postgres_operator', 'create_postgres_table', 'scheduled__2022-03-01T00:00:00+00:00', '--job-id', '463', '--raw', '--subdir', 'DAGS_FOLDER/DAGWithPostgresOperator.py', '--cfg-path', '/tmp/tmpfiibw6hs', '--error-file', '/tmp/tmpsrcs9bt4']
[2022-07-30 19:39:39,236] {standard_task_runner.py:80} INFO - Job 463: Subtask create_postgres_table
[2022-07-30 19:39:39,409] {task_command.py:369} INFO - Running <TaskInstance: dag_with_postgres_operator.create_postgres_table scheduled__2022-03-01T00:00:00+00:00 [running]> on host 66bf18ec08cc
[2022-07-30 19:39:39,523] {taskinstance.py:1571} INFO - Exporting the following env vars:
AIRFLOW_CTX_DAG_OWNER=yosr
AIRFLOW_CTX_DAG_ID=dag_with_postgres_operator
AIRFLOW_CTX_TASK_ID=create_postgres_table
AIRFLOW_CTX_EXECUTION_DATE=2022-03-01T00:00:00+00:00
AIRFLOW_CTX_TRY_NUMBER=5
AIRFLOW_CTX_DAG_RUN_ID=scheduled__2022-03-01T00:00:00+00:00
[2022-07-30 19:39:39,543] {base.py:68} INFO - Using connection ID 'postgres_localhost' for task execution.
[2022-07-30 19:39:39,544] {taskinstance.py:1889} ERROR - Task failed with exception
Traceback (most recent call last):
  File "/home/airflow/.local/lib/python3.7/site-packages/airflow/providers/postgres/operators/postgres.py", line 92, in execute
    self.hook.run(self.sql, self.autocommit, parameters=self.parameters)
  File "/home/airflow/.local/lib/python3.7/site-packages/airflow/hooks/dbapi.py", line 181, in run
    with closing(self.get_conn()) as conn:
  File "/home/airflow/.local/lib/python3.7/site-packages/airflow/providers/postgres/hooks/postgres.py", line 113, in get_conn
    self.conn = psycopg2.connect(**conn_args)
  File "/home/airflow/.local/lib/python3.7/site-packages/psycopg2/__init__.py", line 122, in connect
    conn = _connect(dsn, connection_factory=connection_factory, **kwasync)
psycopg2.OperationalError: could not translate host name "host.docker.internal " to address: Name or service not known

[2022-07-30 19:39:39,559] {taskinstance.py:1400} INFO - Marking task as UP_FOR_RETRY. dag_id=dag_with_postgres_operator, task_id=create_postgres_table, execution_date=20220301T000000, start_date=20220730T193939, end_date=20220730T193939
[2022-07-30 19:39:39,577] {standard_task_runner.py:97} ERROR - Failed to execute job 463 for task create_postgres_table (could not translate host name "host.docker.internal " to address: Name or service not known
; 6883)
[2022-07-30 19:39:39,603] {local_task_job.py:156} INFO - Task exited with return code 1
[2022-07-30 19:39:39,685] {local_task_job.py:273} INFO - 0 downstream tasks scheduled from follow-on schedule check
[2022-07-31 15:11:35,719] {taskinstance.py:1159} INFO - Dependencies all met for <TaskInstance: dag_with_postgres_operator.create_postgres_table scheduled__2022-03-01T00:00:00+00:00 [queued]>
[2022-07-31 15:11:35,744] {taskinstance.py:1159} INFO - Dependencies all met for <TaskInstance: dag_with_postgres_operator.create_postgres_table scheduled__2022-03-01T00:00:00+00:00 [queued]>
[2022-07-31 15:11:35,744] {taskinstance.py:1356} INFO - 
--------------------------------------------------------------------------------
[2022-07-31 15:11:35,744] {taskinstance.py:1357} INFO - Starting attempt 5 of 6
[2022-07-31 15:11:35,745] {taskinstance.py:1358} INFO - 
--------------------------------------------------------------------------------
[2022-07-31 15:11:35,776] {taskinstance.py:1377} INFO - Executing <Task(PostgresOperator): create_postgres_table> on 2022-03-01 00:00:00+00:00
[2022-07-31 15:11:35,784] {standard_task_runner.py:52} INFO - Started process 7362 to run task
[2022-07-31 15:11:35,801] {standard_task_runner.py:79} INFO - Running: ['***', 'tasks', 'run', 'dag_with_postgres_operator', 'create_postgres_table', 'scheduled__2022-03-01T00:00:00+00:00', '--job-id', '489', '--raw', '--subdir', 'DAGS_FOLDER/DAGWithPostgresOperator.py', '--cfg-path', '/tmp/tmppt0f3iiw', '--error-file', '/tmp/tmpj6u3t6ro']
[2022-07-31 15:11:35,802] {standard_task_runner.py:80} INFO - Job 489: Subtask create_postgres_table
[2022-07-31 15:11:35,925] {task_command.py:369} INFO - Running <TaskInstance: dag_with_postgres_operator.create_postgres_table scheduled__2022-03-01T00:00:00+00:00 [running]> on host 4688dd3b7141
[2022-07-31 15:11:35,983] {taskinstance.py:1889} ERROR - Task failed with exception
Traceback (most recent call last):
  File "/home/airflow/.local/lib/python3.7/site-packages/airflow/models/taskinstance.py", line 1451, in _run_raw_task
    self._execute_task_with_callbacks(context, test_mode)
  File "/home/airflow/.local/lib/python3.7/site-packages/airflow/models/taskinstance.py", line 1555, in _execute_task_with_callbacks
    task_orig = self.render_templates(context=context)
  File "/home/airflow/.local/lib/python3.7/site-packages/airflow/models/taskinstance.py", line 2202, in render_templates
    rendered_task = self.task.render_template_fields(context)
  File "/home/airflow/.local/lib/python3.7/site-packages/airflow/models/baseoperator.py", line 1179, in render_template_fields
    self._do_render_template_fields(self, self.template_fields, context, jinja_env, set())
  File "/home/airflow/.local/lib/python3.7/site-packages/airflow/utils/session.py", line 71, in wrapper
    return func(*args, session=session, **kwargs)
  File "/home/airflow/.local/lib/python3.7/site-packages/airflow/models/abstractoperator.py", line 348, in _do_render_template_fields
    seen_oids,
  File "/home/airflow/.local/lib/python3.7/site-packages/airflow/models/abstractoperator.py", line 385, in render_template
    template = jinja_env.get_template(value)
  File "/home/airflow/.local/lib/python3.7/site-packages/jinja2/environment.py", line 997, in get_template
    return self._load_template(name, globals)
  File "/home/airflow/.local/lib/python3.7/site-packages/jinja2/environment.py", line 958, in _load_template
    template = self.loader.load(self, name, self.make_globals(globals))
  File "/home/airflow/.local/lib/python3.7/site-packages/jinja2/loaders.py", line 125, in load
    source, filename, uptodate = self.get_source(environment, name)
  File "/home/airflow/.local/lib/python3.7/site-packages/jinja2/loaders.py", line 214, in get_source
    raise TemplateNotFound(template)
jinja2.exceptions.TemplateNotFound: /data/postgres/pet_schema.sql
[2022-07-31 15:11:36,007] {taskinstance.py:1400} INFO - Marking task as UP_FOR_RETRY. dag_id=dag_with_postgres_operator, task_id=create_postgres_table, execution_date=20220301T000000, start_date=20220731T151135, end_date=20220731T151136
[2022-07-31 15:11:36,027] {standard_task_runner.py:97} ERROR - Failed to execute job 489 for task create_postgres_table (/data/postgres/pet_schema.sql; 7362)
[2022-07-31 15:11:36,053] {local_task_job.py:156} INFO - Task exited with return code 1
[2022-07-31 15:11:36,166] {local_task_job.py:273} INFO - 0 downstream tasks scheduled from follow-on schedule check
