[2022-07-30 17:53:29,796] {taskinstance.py:1159} INFO - Dependencies all met for <TaskInstance: dag_with_postgres_operator.create_postgres_table scheduled__2021-12-21T00:00:00+00:00 [queued]>
[2022-07-30 17:53:29,817] {taskinstance.py:1159} INFO - Dependencies all met for <TaskInstance: dag_with_postgres_operator.create_postgres_table scheduled__2021-12-21T00:00:00+00:00 [queued]>
[2022-07-30 17:53:29,817] {taskinstance.py:1356} INFO - 
--------------------------------------------------------------------------------
[2022-07-30 17:53:29,817] {taskinstance.py:1357} INFO - Starting attempt 4 of 6
[2022-07-30 17:53:29,817] {taskinstance.py:1358} INFO - 
--------------------------------------------------------------------------------
[2022-07-30 17:53:29,843] {taskinstance.py:1377} INFO - Executing <Task(PostgresOperator): create_postgres_table> on 2021-12-21 00:00:00+00:00
[2022-07-30 17:53:29,849] {standard_task_runner.py:52} INFO - Started process 1157 to run task
[2022-07-30 17:53:29,853] {standard_task_runner.py:79} INFO - Running: ['***', 'tasks', 'run', 'dag_with_postgres_operator', 'create_postgres_table', 'scheduled__2021-12-21T00:00:00+00:00', '--job-id', '53', '--raw', '--subdir', 'DAGS_FOLDER/DAGWithPostgresOperator.py', '--cfg-path', '/tmp/tmp33k5yje8', '--error-file', '/tmp/tmplzrwl9jp']
[2022-07-30 17:53:29,853] {standard_task_runner.py:80} INFO - Job 53: Subtask create_postgres_table
[2022-07-30 17:53:29,933] {task_command.py:369} INFO - Running <TaskInstance: dag_with_postgres_operator.create_postgres_table scheduled__2021-12-21T00:00:00+00:00 [running]> on host 66bf18ec08cc
[2022-07-30 17:53:30,034] {taskinstance.py:1571} INFO - Exporting the following env vars:
AIRFLOW_CTX_DAG_OWNER=yosr
AIRFLOW_CTX_DAG_ID=dag_with_postgres_operator
AIRFLOW_CTX_TASK_ID=create_postgres_table
AIRFLOW_CTX_EXECUTION_DATE=2021-12-21T00:00:00+00:00
AIRFLOW_CTX_TRY_NUMBER=4
AIRFLOW_CTX_DAG_RUN_ID=scheduled__2021-12-21T00:00:00+00:00
[2022-07-30 17:53:30,049] {base.py:68} INFO - Using connection ID 'postgres_localhost' for task execution.
[2022-07-30 17:53:30,050] {taskinstance.py:1889} ERROR - Task failed with exception
Traceback (most recent call last):
  File "/home/airflow/.local/lib/python3.7/site-packages/airflow/providers/postgres/operators/postgres.py", line 92, in execute
    self.hook.run(self.sql, self.autocommit, parameters=self.parameters)
  File "/home/airflow/.local/lib/python3.7/site-packages/airflow/hooks/dbapi.py", line 181, in run
    with closing(self.get_conn()) as conn:
  File "/home/airflow/.local/lib/python3.7/site-packages/airflow/providers/postgres/hooks/postgres.py", line 113, in get_conn
    self.conn = psycopg2.connect(**conn_args)
  File "/home/airflow/.local/lib/python3.7/site-packages/psycopg2/__init__.py", line 122, in connect
    conn = _connect(dsn, connection_factory=connection_factory, **kwasync)
psycopg2.OperationalError: could not translate host name "host.docker.internal " to address: Name or service not known

[2022-07-30 17:53:30,062] {taskinstance.py:1400} INFO - Marking task as UP_FOR_RETRY. dag_id=dag_with_postgres_operator, task_id=create_postgres_table, execution_date=20211221T000000, start_date=20220730T175329, end_date=20220730T175330
[2022-07-30 17:53:30,077] {standard_task_runner.py:97} ERROR - Failed to execute job 53 for task create_postgres_table (could not translate host name "host.docker.internal " to address: Name or service not known
; 1157)
[2022-07-30 17:53:30,111] {local_task_job.py:156} INFO - Task exited with return code 1
[2022-07-30 17:53:30,207] {local_task_job.py:273} INFO - 0 downstream tasks scheduled from follow-on schedule check
[2022-07-30 23:59:48,774] {taskinstance.py:1159} INFO - Dependencies all met for <TaskInstance: dag_with_postgres_operator.create_postgres_table scheduled__2021-12-21T00:00:00+00:00 [queued]>
[2022-07-30 23:59:48,806] {taskinstance.py:1159} INFO - Dependencies all met for <TaskInstance: dag_with_postgres_operator.create_postgres_table scheduled__2021-12-21T00:00:00+00:00 [queued]>
[2022-07-30 23:59:48,806] {taskinstance.py:1356} INFO - 
--------------------------------------------------------------------------------
[2022-07-30 23:59:48,807] {taskinstance.py:1357} INFO - Starting attempt 4 of 6
[2022-07-30 23:59:48,807] {taskinstance.py:1358} INFO - 
--------------------------------------------------------------------------------
[2022-07-30 23:59:48,829] {taskinstance.py:1377} INFO - Executing <Task(PostgresOperator): create_postgres_table> on 2021-12-21 00:00:00+00:00
[2022-07-30 23:59:48,835] {standard_task_runner.py:52} INFO - Started process 5081 to run task
[2022-07-30 23:59:48,840] {standard_task_runner.py:79} INFO - Running: ['***', 'tasks', 'run', 'dag_with_postgres_operator', 'create_postgres_table', 'scheduled__2021-12-21T00:00:00+00:00', '--job-id', '1060', '--raw', '--subdir', 'DAGS_FOLDER/DAGWithPostgresOperator.py', '--cfg-path', '/tmp/tmpt3grv2sk', '--error-file', '/tmp/tmpvxwn1uij']
[2022-07-30 23:59:48,840] {standard_task_runner.py:80} INFO - Job 1060: Subtask create_postgres_table
[2022-07-30 23:59:48,919] {task_command.py:369} INFO - Running <TaskInstance: dag_with_postgres_operator.create_postgres_table scheduled__2021-12-21T00:00:00+00:00 [running]> on host 66bf18ec08cc
[2022-07-30 23:59:49,022] {taskinstance.py:1571} INFO - Exporting the following env vars:
AIRFLOW_CTX_DAG_OWNER=yosr
AIRFLOW_CTX_DAG_ID=dag_with_postgres_operator
AIRFLOW_CTX_TASK_ID=create_postgres_table
AIRFLOW_CTX_EXECUTION_DATE=2021-12-21T00:00:00+00:00
AIRFLOW_CTX_TRY_NUMBER=4
AIRFLOW_CTX_DAG_RUN_ID=scheduled__2021-12-21T00:00:00+00:00
[2022-07-30 23:59:49,038] {base.py:68} INFO - Using connection ID 'postgres_localhost' for task execution.
[2022-07-30 23:59:49,040] {taskinstance.py:1889} ERROR - Task failed with exception
Traceback (most recent call last):
  File "/home/airflow/.local/lib/python3.7/site-packages/airflow/providers/postgres/operators/postgres.py", line 92, in execute
    self.hook.run(self.sql, self.autocommit, parameters=self.parameters)
  File "/home/airflow/.local/lib/python3.7/site-packages/airflow/hooks/dbapi.py", line 181, in run
    with closing(self.get_conn()) as conn:
  File "/home/airflow/.local/lib/python3.7/site-packages/airflow/providers/postgres/hooks/postgres.py", line 113, in get_conn
    self.conn = psycopg2.connect(**conn_args)
  File "/home/airflow/.local/lib/python3.7/site-packages/psycopg2/__init__.py", line 122, in connect
    conn = _connect(dsn, connection_factory=connection_factory, **kwasync)
psycopg2.OperationalError: could not translate host name "host.docker.local " to address: Name or service not known

[2022-07-30 23:59:49,060] {taskinstance.py:1400} INFO - Marking task as UP_FOR_RETRY. dag_id=dag_with_postgres_operator, task_id=create_postgres_table, execution_date=20211221T000000, start_date=20220730T235948, end_date=20220730T235949
[2022-07-30 23:59:49,084] {standard_task_runner.py:97} ERROR - Failed to execute job 1060 for task create_postgres_table (could not translate host name "host.docker.local " to address: Name or service not known
; 5081)
[2022-07-30 23:59:49,097] {local_task_job.py:156} INFO - Task exited with return code 1
[2022-07-30 23:59:49,161] {local_task_job.py:273} INFO - 0 downstream tasks scheduled from follow-on schedule check
[2022-07-31 10:53:13,463] {taskinstance.py:1159} INFO - Dependencies all met for <TaskInstance: dag_with_postgres_operator.create_postgres_table scheduled__2021-12-21T00:00:00+00:00 [queued]>
[2022-07-31 10:53:13,488] {taskinstance.py:1159} INFO - Dependencies all met for <TaskInstance: dag_with_postgres_operator.create_postgres_table scheduled__2021-12-21T00:00:00+00:00 [queued]>
[2022-07-31 10:53:13,489] {taskinstance.py:1356} INFO - 
--------------------------------------------------------------------------------
[2022-07-31 10:53:13,489] {taskinstance.py:1357} INFO - Starting attempt 4 of 6
[2022-07-31 10:53:13,489] {taskinstance.py:1358} INFO - 
--------------------------------------------------------------------------------
[2022-07-31 10:53:13,508] {taskinstance.py:1377} INFO - Executing <Task(PostgresOperator): create_postgres_table> on 2021-12-21 00:00:00+00:00
[2022-07-31 10:53:13,514] {standard_task_runner.py:52} INFO - Started process 3953 to run task
[2022-07-31 10:53:13,517] {standard_task_runner.py:79} INFO - Running: ['***', 'tasks', 'run', 'dag_with_postgres_operator', 'create_postgres_table', 'scheduled__2021-12-21T00:00:00+00:00', '--job-id', '1512', '--raw', '--subdir', 'DAGS_FOLDER/DAGWithPostgresOperator.py', '--cfg-path', '/tmp/tmpqopc1ysf', '--error-file', '/tmp/tmpqr530dag']
[2022-07-31 10:53:13,518] {standard_task_runner.py:80} INFO - Job 1512: Subtask create_postgres_table
[2022-07-31 10:53:13,592] {task_command.py:369} INFO - Running <TaskInstance: dag_with_postgres_operator.create_postgres_table scheduled__2021-12-21T00:00:00+00:00 [running]> on host 66bf18ec08cc
[2022-07-31 10:53:13,715] {taskinstance.py:1571} INFO - Exporting the following env vars:
AIRFLOW_CTX_DAG_OWNER=yosr
AIRFLOW_CTX_DAG_ID=dag_with_postgres_operator
AIRFLOW_CTX_TASK_ID=create_postgres_table
AIRFLOW_CTX_EXECUTION_DATE=2021-12-21T00:00:00+00:00
AIRFLOW_CTX_TRY_NUMBER=4
AIRFLOW_CTX_DAG_RUN_ID=scheduled__2021-12-21T00:00:00+00:00
[2022-07-31 10:53:13,731] {base.py:68} INFO - Using connection ID 'postgres_localhost' for task execution.
[2022-07-31 10:53:13,733] {taskinstance.py:1889} ERROR - Task failed with exception
Traceback (most recent call last):
  File "/home/airflow/.local/lib/python3.7/site-packages/airflow/providers/postgres/operators/postgres.py", line 92, in execute
    self.hook.run(self.sql, self.autocommit, parameters=self.parameters)
  File "/home/airflow/.local/lib/python3.7/site-packages/airflow/hooks/dbapi.py", line 181, in run
    with closing(self.get_conn()) as conn:
  File "/home/airflow/.local/lib/python3.7/site-packages/airflow/providers/postgres/hooks/postgres.py", line 113, in get_conn
    self.conn = psycopg2.connect(**conn_args)
  File "/home/airflow/.local/lib/python3.7/site-packages/psycopg2/__init__.py", line 122, in connect
    conn = _connect(dsn, connection_factory=connection_factory, **kwasync)
psycopg2.OperationalError: could not translate host name "host.docker.internal " to address: Name or service not known

[2022-07-31 10:53:13,753] {taskinstance.py:1400} INFO - Marking task as UP_FOR_RETRY. dag_id=dag_with_postgres_operator, task_id=create_postgres_table, execution_date=20211221T000000, start_date=20220731T105313, end_date=20220731T105313
[2022-07-31 10:53:13,775] {standard_task_runner.py:97} ERROR - Failed to execute job 1512 for task create_postgres_table (could not translate host name "host.docker.internal " to address: Name or service not known
; 3953)
[2022-07-31 10:53:13,819] {local_task_job.py:156} INFO - Task exited with return code 1
[2022-07-31 10:53:13,926] {local_task_job.py:273} INFO - 0 downstream tasks scheduled from follow-on schedule check
[2022-07-31 13:24:58,202] {taskinstance.py:1159} INFO - Dependencies all met for <TaskInstance: dag_with_postgres_operator.create_postgres_table scheduled__2021-12-21T00:00:00+00:00 [queued]>
[2022-07-31 13:24:58,220] {taskinstance.py:1159} INFO - Dependencies all met for <TaskInstance: dag_with_postgres_operator.create_postgres_table scheduled__2021-12-21T00:00:00+00:00 [queued]>
[2022-07-31 13:24:58,220] {taskinstance.py:1356} INFO - 
--------------------------------------------------------------------------------
[2022-07-31 13:24:58,221] {taskinstance.py:1357} INFO - Starting attempt 4 of 6
[2022-07-31 13:24:58,221] {taskinstance.py:1358} INFO - 
--------------------------------------------------------------------------------
[2022-07-31 13:24:58,241] {taskinstance.py:1377} INFO - Executing <Task(PostgresOperator): create_postgres_table> on 2021-12-21 00:00:00+00:00
[2022-07-31 13:24:58,246] {standard_task_runner.py:52} INFO - Started process 1550 to run task
[2022-07-31 13:24:58,250] {standard_task_runner.py:79} INFO - Running: ['***', 'tasks', 'run', 'dag_with_postgres_operator', 'create_postgres_table', 'scheduled__2021-12-21T00:00:00+00:00', '--job-id', '52', '--raw', '--subdir', 'DAGS_FOLDER/DAGWithPostgresOperator.py', '--cfg-path', '/tmp/tmpy_f2eey3', '--error-file', '/tmp/tmpod_ukt0w']
[2022-07-31 13:24:58,250] {standard_task_runner.py:80} INFO - Job 52: Subtask create_postgres_table
[2022-07-31 13:24:58,342] {task_command.py:369} INFO - Running <TaskInstance: dag_with_postgres_operator.create_postgres_table scheduled__2021-12-21T00:00:00+00:00 [running]> on host 4688dd3b7141
[2022-07-31 13:24:58,453] {taskinstance.py:1571} INFO - Exporting the following env vars:
AIRFLOW_CTX_DAG_OWNER=yosr
AIRFLOW_CTX_DAG_ID=dag_with_postgres_operator
AIRFLOW_CTX_TASK_ID=create_postgres_table
AIRFLOW_CTX_EXECUTION_DATE=2021-12-21T00:00:00+00:00
AIRFLOW_CTX_TRY_NUMBER=4
AIRFLOW_CTX_DAG_RUN_ID=scheduled__2021-12-21T00:00:00+00:00
[2022-07-31 13:24:58,493] {taskinstance.py:1889} ERROR - Task failed with exception
Traceback (most recent call last):
  File "/home/airflow/.local/lib/python3.7/site-packages/airflow/providers/postgres/operators/postgres.py", line 92, in execute
    self.hook.run(self.sql, self.autocommit, parameters=self.parameters)
  File "/home/airflow/.local/lib/python3.7/site-packages/airflow/hooks/dbapi.py", line 181, in run
    with closing(self.get_conn()) as conn:
  File "/home/airflow/.local/lib/python3.7/site-packages/airflow/providers/postgres/hooks/postgres.py", line 86, in get_conn
    conn = deepcopy(self.connection or self.get_connection(conn_id))
  File "/home/airflow/.local/lib/python3.7/site-packages/airflow/hooks/base.py", line 67, in get_connection
    conn = Connection.get_connection_from_secrets(conn_id)
  File "/home/airflow/.local/lib/python3.7/site-packages/airflow/models/connection.py", line 430, in get_connection_from_secrets
    raise AirflowNotFoundException(f"The conn_id `{conn_id}` isn't defined")
airflow.exceptions.AirflowNotFoundException: The conn_id `postgres_localhost` isn't defined
[2022-07-31 13:24:58,499] {taskinstance.py:1400} INFO - Marking task as UP_FOR_RETRY. dag_id=dag_with_postgres_operator, task_id=create_postgres_table, execution_date=20211221T000000, start_date=20220731T132458, end_date=20220731T132458
[2022-07-31 13:24:58,519] {standard_task_runner.py:97} ERROR - Failed to execute job 52 for task create_postgres_table (The conn_id `postgres_localhost` isn't defined; 1550)
[2022-07-31 13:24:58,548] {local_task_job.py:156} INFO - Task exited with return code 1
[2022-07-31 13:24:58,612] {local_task_job.py:273} INFO - 0 downstream tasks scheduled from follow-on schedule check
