[2022-07-30 17:38:12,071] {taskinstance.py:1159} INFO - Dependencies all met for <TaskInstance: dag_with_postgres_operator.create_postgres_table scheduled__2021-12-22T00:00:00+00:00 [queued]>
[2022-07-30 17:38:12,089] {taskinstance.py:1159} INFO - Dependencies all met for <TaskInstance: dag_with_postgres_operator.create_postgres_table scheduled__2021-12-22T00:00:00+00:00 [queued]>
[2022-07-30 17:38:12,089] {taskinstance.py:1356} INFO - 
--------------------------------------------------------------------------------
[2022-07-30 17:38:12,089] {taskinstance.py:1357} INFO - Starting attempt 1 of 6
[2022-07-30 17:38:12,089] {taskinstance.py:1358} INFO - 
--------------------------------------------------------------------------------
[2022-07-30 17:38:12,110] {taskinstance.py:1377} INFO - Executing <Task(PostgresOperator): create_postgres_table> on 2021-12-22 00:00:00+00:00
[2022-07-30 17:38:12,121] {standard_task_runner.py:52} INFO - Started process 370 to run task
[2022-07-30 17:38:12,123] {standard_task_runner.py:79} INFO - Running: ['***', 'tasks', 'run', 'dag_with_postgres_operator', 'create_postgres_table', 'scheduled__2021-12-22T00:00:00+00:00', '--job-id', '6', '--raw', '--subdir', 'DAGS_FOLDER/DAGWithPostgresOperator.py', '--cfg-path', '/tmp/tmpyvqjn1bc', '--error-file', '/tmp/tmp71qjm_9j']
[2022-07-30 17:38:12,124] {standard_task_runner.py:80} INFO - Job 6: Subtask create_postgres_table
[2022-07-30 17:38:12,221] {task_command.py:369} INFO - Running <TaskInstance: dag_with_postgres_operator.create_postgres_table scheduled__2021-12-22T00:00:00+00:00 [running]> on host 66bf18ec08cc
[2022-07-30 17:38:12,338] {taskinstance.py:1571} INFO - Exporting the following env vars:
AIRFLOW_CTX_DAG_OWNER=yosr
AIRFLOW_CTX_DAG_ID=dag_with_postgres_operator
AIRFLOW_CTX_TASK_ID=create_postgres_table
AIRFLOW_CTX_EXECUTION_DATE=2021-12-22T00:00:00+00:00
AIRFLOW_CTX_TRY_NUMBER=1
AIRFLOW_CTX_DAG_RUN_ID=scheduled__2021-12-22T00:00:00+00:00
[2022-07-30 17:38:12,376] {taskinstance.py:1889} ERROR - Task failed with exception
Traceback (most recent call last):
  File "/home/airflow/.local/lib/python3.7/site-packages/airflow/providers/postgres/operators/postgres.py", line 92, in execute
    self.hook.run(self.sql, self.autocommit, parameters=self.parameters)
  File "/home/airflow/.local/lib/python3.7/site-packages/airflow/hooks/dbapi.py", line 181, in run
    with closing(self.get_conn()) as conn:
  File "/home/airflow/.local/lib/python3.7/site-packages/airflow/providers/postgres/hooks/postgres.py", line 86, in get_conn
    conn = deepcopy(self.connection or self.get_connection(conn_id))
  File "/home/airflow/.local/lib/python3.7/site-packages/airflow/hooks/base.py", line 67, in get_connection
    conn = Connection.get_connection_from_secrets(conn_id)
  File "/home/airflow/.local/lib/python3.7/site-packages/airflow/models/connection.py", line 430, in get_connection_from_secrets
    raise AirflowNotFoundException(f"The conn_id `{conn_id}` isn't defined")
airflow.exceptions.AirflowNotFoundException: The conn_id `postgres_localhost` isn't defined
[2022-07-30 17:38:12,391] {taskinstance.py:1400} INFO - Marking task as UP_FOR_RETRY. dag_id=dag_with_postgres_operator, task_id=create_postgres_table, execution_date=20211222T000000, start_date=20220730T173812, end_date=20220730T173812
[2022-07-30 17:38:12,422] {standard_task_runner.py:97} ERROR - Failed to execute job 6 for task create_postgres_table (The conn_id `postgres_localhost` isn't defined; 370)
[2022-07-30 17:38:12,472] {local_task_job.py:156} INFO - Task exited with return code 1
[2022-07-30 17:38:12,630] {local_task_job.py:273} INFO - 0 downstream tasks scheduled from follow-on schedule check
[2022-07-30 23:44:46,113] {taskinstance.py:1159} INFO - Dependencies all met for <TaskInstance: dag_with_postgres_operator.create_postgres_table scheduled__2021-12-22T00:00:00+00:00 [queued]>
[2022-07-30 23:44:46,134] {taskinstance.py:1159} INFO - Dependencies all met for <TaskInstance: dag_with_postgres_operator.create_postgres_table scheduled__2021-12-22T00:00:00+00:00 [queued]>
[2022-07-30 23:44:46,135] {taskinstance.py:1356} INFO - 
--------------------------------------------------------------------------------
[2022-07-30 23:44:46,135] {taskinstance.py:1357} INFO - Starting attempt 1 of 6
[2022-07-30 23:44:46,135] {taskinstance.py:1358} INFO - 
--------------------------------------------------------------------------------
[2022-07-30 23:44:46,156] {taskinstance.py:1377} INFO - Executing <Task(PostgresOperator): create_postgres_table> on 2021-12-22 00:00:00+00:00
[2022-07-30 23:44:46,160] {standard_task_runner.py:52} INFO - Started process 4298 to run task
[2022-07-30 23:44:46,163] {standard_task_runner.py:79} INFO - Running: ['***', 'tasks', 'run', 'dag_with_postgres_operator', 'create_postgres_table', 'scheduled__2021-12-22T00:00:00+00:00', '--job-id', '1014', '--raw', '--subdir', 'DAGS_FOLDER/DAGWithPostgresOperator.py', '--cfg-path', '/tmp/tmpp_szt2gq', '--error-file', '/tmp/tmpt1ovoiis']
[2022-07-30 23:44:46,163] {standard_task_runner.py:80} INFO - Job 1014: Subtask create_postgres_table
[2022-07-30 23:44:46,232] {task_command.py:369} INFO - Running <TaskInstance: dag_with_postgres_operator.create_postgres_table scheduled__2021-12-22T00:00:00+00:00 [running]> on host 66bf18ec08cc
[2022-07-30 23:44:46,333] {taskinstance.py:1571} INFO - Exporting the following env vars:
AIRFLOW_CTX_DAG_OWNER=yosr
AIRFLOW_CTX_DAG_ID=dag_with_postgres_operator
AIRFLOW_CTX_TASK_ID=create_postgres_table
AIRFLOW_CTX_EXECUTION_DATE=2021-12-22T00:00:00+00:00
AIRFLOW_CTX_TRY_NUMBER=1
AIRFLOW_CTX_DAG_RUN_ID=scheduled__2021-12-22T00:00:00+00:00
[2022-07-30 23:44:46,349] {base.py:68} INFO - Using connection ID 'postgres_localhost' for task execution.
[2022-07-30 23:44:46,351] {taskinstance.py:1889} ERROR - Task failed with exception
Traceback (most recent call last):
  File "/home/airflow/.local/lib/python3.7/site-packages/airflow/providers/postgres/operators/postgres.py", line 92, in execute
    self.hook.run(self.sql, self.autocommit, parameters=self.parameters)
  File "/home/airflow/.local/lib/python3.7/site-packages/airflow/hooks/dbapi.py", line 181, in run
    with closing(self.get_conn()) as conn:
  File "/home/airflow/.local/lib/python3.7/site-packages/airflow/providers/postgres/hooks/postgres.py", line 113, in get_conn
    self.conn = psycopg2.connect(**conn_args)
  File "/home/airflow/.local/lib/python3.7/site-packages/psycopg2/__init__.py", line 122, in connect
    conn = _connect(dsn, connection_factory=connection_factory, **kwasync)
psycopg2.OperationalError: could not translate host name "host.docker.local " to address: Name or service not known

[2022-07-30 23:44:46,366] {taskinstance.py:1400} INFO - Marking task as UP_FOR_RETRY. dag_id=dag_with_postgres_operator, task_id=create_postgres_table, execution_date=20211222T000000, start_date=20220730T234446, end_date=20220730T234446
[2022-07-30 23:44:46,389] {standard_task_runner.py:97} ERROR - Failed to execute job 1014 for task create_postgres_table (could not translate host name "host.docker.local " to address: Name or service not known
; 4298)
[2022-07-30 23:44:46,423] {local_task_job.py:156} INFO - Task exited with return code 1
[2022-07-30 23:44:46,482] {local_task_job.py:273} INFO - 0 downstream tasks scheduled from follow-on schedule check
[2022-07-31 10:26:01,596] {taskinstance.py:1159} INFO - Dependencies all met for <TaskInstance: dag_with_postgres_operator.create_postgres_table scheduled__2021-12-22T00:00:00+00:00 [queued]>
[2022-07-31 10:26:01,614] {taskinstance.py:1159} INFO - Dependencies all met for <TaskInstance: dag_with_postgres_operator.create_postgres_table scheduled__2021-12-22T00:00:00+00:00 [queued]>
[2022-07-31 10:26:01,615] {taskinstance.py:1356} INFO - 
--------------------------------------------------------------------------------
[2022-07-31 10:26:01,615] {taskinstance.py:1357} INFO - Starting attempt 1 of 6
[2022-07-31 10:26:01,615] {taskinstance.py:1358} INFO - 
--------------------------------------------------------------------------------
[2022-07-31 10:26:01,638] {taskinstance.py:1377} INFO - Executing <Task(PostgresOperator): create_postgres_table> on 2021-12-22 00:00:00+00:00
[2022-07-31 10:26:01,643] {standard_task_runner.py:52} INFO - Started process 2516 to run task
[2022-07-31 10:26:01,647] {standard_task_runner.py:79} INFO - Running: ['***', 'tasks', 'run', 'dag_with_postgres_operator', 'create_postgres_table', 'scheduled__2021-12-22T00:00:00+00:00', '--job-id', '1416', '--raw', '--subdir', 'DAGS_FOLDER/DAGWithPostgresOperator.py', '--cfg-path', '/tmp/tmp64nizspy', '--error-file', '/tmp/tmpanfkdk5y']
[2022-07-31 10:26:01,647] {standard_task_runner.py:80} INFO - Job 1416: Subtask create_postgres_table
[2022-07-31 10:26:01,730] {task_command.py:369} INFO - Running <TaskInstance: dag_with_postgres_operator.create_postgres_table scheduled__2021-12-22T00:00:00+00:00 [running]> on host 66bf18ec08cc
[2022-07-31 10:26:01,842] {taskinstance.py:1571} INFO - Exporting the following env vars:
AIRFLOW_CTX_DAG_OWNER=yosr
AIRFLOW_CTX_DAG_ID=dag_with_postgres_operator
AIRFLOW_CTX_TASK_ID=create_postgres_table
AIRFLOW_CTX_EXECUTION_DATE=2021-12-22T00:00:00+00:00
AIRFLOW_CTX_TRY_NUMBER=1
AIRFLOW_CTX_DAG_RUN_ID=scheduled__2021-12-22T00:00:00+00:00
[2022-07-31 10:26:01,858] {base.py:68} INFO - Using connection ID 'postgres_localhost' for task execution.
[2022-07-31 10:26:01,859] {taskinstance.py:1889} ERROR - Task failed with exception
Traceback (most recent call last):
  File "/home/airflow/.local/lib/python3.7/site-packages/airflow/providers/postgres/operators/postgres.py", line 92, in execute
    self.hook.run(self.sql, self.autocommit, parameters=self.parameters)
  File "/home/airflow/.local/lib/python3.7/site-packages/airflow/hooks/dbapi.py", line 181, in run
    with closing(self.get_conn()) as conn:
  File "/home/airflow/.local/lib/python3.7/site-packages/airflow/providers/postgres/hooks/postgres.py", line 113, in get_conn
    self.conn = psycopg2.connect(**conn_args)
  File "/home/airflow/.local/lib/python3.7/site-packages/psycopg2/__init__.py", line 122, in connect
    conn = _connect(dsn, connection_factory=connection_factory, **kwasync)
psycopg2.OperationalError: could not translate host name "host.docker.local " to address: Name or service not known

[2022-07-31 10:26:01,872] {taskinstance.py:1400} INFO - Marking task as UP_FOR_RETRY. dag_id=dag_with_postgres_operator, task_id=create_postgres_table, execution_date=20211222T000000, start_date=20220731T102601, end_date=20220731T102601
[2022-07-31 10:26:01,894] {standard_task_runner.py:97} ERROR - Failed to execute job 1416 for task create_postgres_table (could not translate host name "host.docker.local " to address: Name or service not known
; 2516)
[2022-07-31 10:26:01,905] {local_task_job.py:156} INFO - Task exited with return code 1
[2022-07-31 10:26:01,963] {local_task_job.py:273} INFO - 0 downstream tasks scheduled from follow-on schedule check
[2022-07-31 10:38:10,450] {taskinstance.py:1159} INFO - Dependencies all met for <TaskInstance: dag_with_postgres_operator.create_postgres_table scheduled__2021-12-22T00:00:00+00:00 [queued]>
[2022-07-31 10:38:10,471] {taskinstance.py:1159} INFO - Dependencies all met for <TaskInstance: dag_with_postgres_operator.create_postgres_table scheduled__2021-12-22T00:00:00+00:00 [queued]>
[2022-07-31 10:38:10,471] {taskinstance.py:1356} INFO - 
--------------------------------------------------------------------------------
[2022-07-31 10:38:10,472] {taskinstance.py:1357} INFO - Starting attempt 1 of 6
[2022-07-31 10:38:10,472] {taskinstance.py:1358} INFO - 
--------------------------------------------------------------------------------
[2022-07-31 10:38:10,491] {taskinstance.py:1377} INFO - Executing <Task(PostgresOperator): create_postgres_table> on 2021-12-22 00:00:00+00:00
[2022-07-31 10:38:10,496] {standard_task_runner.py:52} INFO - Started process 3169 to run task
[2022-07-31 10:38:10,502] {standard_task_runner.py:79} INFO - Running: ['***', 'tasks', 'run', 'dag_with_postgres_operator', 'create_postgres_table', 'scheduled__2021-12-22T00:00:00+00:00', '--job-id', '1464', '--raw', '--subdir', 'DAGS_FOLDER/DAGWithPostgresOperator.py', '--cfg-path', '/tmp/tmp1s4x22qb', '--error-file', '/tmp/tmplaz2jccm']
[2022-07-31 10:38:10,502] {standard_task_runner.py:80} INFO - Job 1464: Subtask create_postgres_table
[2022-07-31 10:38:10,595] {task_command.py:369} INFO - Running <TaskInstance: dag_with_postgres_operator.create_postgres_table scheduled__2021-12-22T00:00:00+00:00 [running]> on host 66bf18ec08cc
[2022-07-31 10:38:10,705] {taskinstance.py:1571} INFO - Exporting the following env vars:
AIRFLOW_CTX_DAG_OWNER=yosr
AIRFLOW_CTX_DAG_ID=dag_with_postgres_operator
AIRFLOW_CTX_TASK_ID=create_postgres_table
AIRFLOW_CTX_EXECUTION_DATE=2021-12-22T00:00:00+00:00
AIRFLOW_CTX_TRY_NUMBER=1
AIRFLOW_CTX_DAG_RUN_ID=scheduled__2021-12-22T00:00:00+00:00
[2022-07-31 10:38:10,719] {base.py:68} INFO - Using connection ID 'postgres_localhost' for task execution.
[2022-07-31 10:38:10,721] {taskinstance.py:1889} ERROR - Task failed with exception
Traceback (most recent call last):
  File "/home/airflow/.local/lib/python3.7/site-packages/airflow/providers/postgres/operators/postgres.py", line 92, in execute
    self.hook.run(self.sql, self.autocommit, parameters=self.parameters)
  File "/home/airflow/.local/lib/python3.7/site-packages/airflow/hooks/dbapi.py", line 181, in run
    with closing(self.get_conn()) as conn:
  File "/home/airflow/.local/lib/python3.7/site-packages/airflow/providers/postgres/hooks/postgres.py", line 113, in get_conn
    self.conn = psycopg2.connect(**conn_args)
  File "/home/airflow/.local/lib/python3.7/site-packages/psycopg2/__init__.py", line 122, in connect
    conn = _connect(dsn, connection_factory=connection_factory, **kwasync)
psycopg2.OperationalError: could not translate host name "host.docker.internal " to address: Name or service not known

[2022-07-31 10:38:10,737] {taskinstance.py:1400} INFO - Marking task as UP_FOR_RETRY. dag_id=dag_with_postgres_operator, task_id=create_postgres_table, execution_date=20211222T000000, start_date=20220731T103810, end_date=20220731T103810
[2022-07-31 10:38:10,766] {standard_task_runner.py:97} ERROR - Failed to execute job 1464 for task create_postgres_table (could not translate host name "host.docker.internal " to address: Name or service not known
; 3169)
[2022-07-31 10:38:10,802] {local_task_job.py:156} INFO - Task exited with return code 1
[2022-07-31 10:38:10,871] {local_task_job.py:273} INFO - 0 downstream tasks scheduled from follow-on schedule check
[2022-07-31 13:09:55,251] {taskinstance.py:1159} INFO - Dependencies all met for <TaskInstance: dag_with_postgres_operator.create_postgres_table scheduled__2021-12-22T00:00:00+00:00 [queued]>
[2022-07-31 13:09:55,264] {taskinstance.py:1159} INFO - Dependencies all met for <TaskInstance: dag_with_postgres_operator.create_postgres_table scheduled__2021-12-22T00:00:00+00:00 [queued]>
[2022-07-31 13:09:55,265] {taskinstance.py:1356} INFO - 
--------------------------------------------------------------------------------
[2022-07-31 13:09:55,265] {taskinstance.py:1357} INFO - Starting attempt 1 of 6
[2022-07-31 13:09:55,265] {taskinstance.py:1358} INFO - 
--------------------------------------------------------------------------------
[2022-07-31 13:09:55,286] {taskinstance.py:1377} INFO - Executing <Task(PostgresOperator): create_postgres_table> on 2021-12-22 00:00:00+00:00
[2022-07-31 13:09:55,291] {standard_task_runner.py:52} INFO - Started process 771 to run task
[2022-07-31 13:09:55,299] {standard_task_runner.py:79} INFO - Running: ['***', 'tasks', 'run', 'dag_with_postgres_operator', 'create_postgres_table', 'scheduled__2021-12-22T00:00:00+00:00', '--job-id', '6', '--raw', '--subdir', 'DAGS_FOLDER/DAGWithPostgresOperator.py', '--cfg-path', '/tmp/tmp_1jh3_si', '--error-file', '/tmp/tmp7rwkyx9c']
[2022-07-31 13:09:55,299] {standard_task_runner.py:80} INFO - Job 6: Subtask create_postgres_table
[2022-07-31 13:09:55,381] {task_command.py:369} INFO - Running <TaskInstance: dag_with_postgres_operator.create_postgres_table scheduled__2021-12-22T00:00:00+00:00 [running]> on host 4688dd3b7141
[2022-07-31 13:09:55,498] {taskinstance.py:1571} INFO - Exporting the following env vars:
AIRFLOW_CTX_DAG_OWNER=yosr
AIRFLOW_CTX_DAG_ID=dag_with_postgres_operator
AIRFLOW_CTX_TASK_ID=create_postgres_table
AIRFLOW_CTX_EXECUTION_DATE=2021-12-22T00:00:00+00:00
AIRFLOW_CTX_TRY_NUMBER=1
AIRFLOW_CTX_DAG_RUN_ID=scheduled__2021-12-22T00:00:00+00:00
[2022-07-31 13:09:55,537] {taskinstance.py:1889} ERROR - Task failed with exception
Traceback (most recent call last):
  File "/home/airflow/.local/lib/python3.7/site-packages/airflow/providers/postgres/operators/postgres.py", line 92, in execute
    self.hook.run(self.sql, self.autocommit, parameters=self.parameters)
  File "/home/airflow/.local/lib/python3.7/site-packages/airflow/hooks/dbapi.py", line 181, in run
    with closing(self.get_conn()) as conn:
  File "/home/airflow/.local/lib/python3.7/site-packages/airflow/providers/postgres/hooks/postgres.py", line 86, in get_conn
    conn = deepcopy(self.connection or self.get_connection(conn_id))
  File "/home/airflow/.local/lib/python3.7/site-packages/airflow/hooks/base.py", line 67, in get_connection
    conn = Connection.get_connection_from_secrets(conn_id)
  File "/home/airflow/.local/lib/python3.7/site-packages/airflow/models/connection.py", line 430, in get_connection_from_secrets
    raise AirflowNotFoundException(f"The conn_id `{conn_id}` isn't defined")
airflow.exceptions.AirflowNotFoundException: The conn_id `postgres_localhost` isn't defined
[2022-07-31 13:09:55,543] {taskinstance.py:1400} INFO - Marking task as UP_FOR_RETRY. dag_id=dag_with_postgres_operator, task_id=create_postgres_table, execution_date=20211222T000000, start_date=20220731T130955, end_date=20220731T130955
[2022-07-31 13:09:55,562] {standard_task_runner.py:97} ERROR - Failed to execute job 6 for task create_postgres_table (The conn_id `postgres_localhost` isn't defined; 771)
[2022-07-31 13:09:55,595] {local_task_job.py:156} INFO - Task exited with return code 1
[2022-07-31 13:09:55,649] {local_task_job.py:273} INFO - 0 downstream tasks scheduled from follow-on schedule check
