[2022-07-30 18:39:06,356] {taskinstance.py:1159} INFO - Dependencies all met for <TaskInstance: dag_with_postgres_operator.create_postgres_table scheduled__2022-02-04T00:00:00+00:00 [queued]>
[2022-07-30 18:39:06,372] {taskinstance.py:1159} INFO - Dependencies all met for <TaskInstance: dag_with_postgres_operator.create_postgres_table scheduled__2022-02-04T00:00:00+00:00 [queued]>
[2022-07-30 18:39:06,372] {taskinstance.py:1356} INFO - 
--------------------------------------------------------------------------------
[2022-07-30 18:39:06,372] {taskinstance.py:1357} INFO - Starting attempt 3 of 6
[2022-07-30 18:39:06,372] {taskinstance.py:1358} INFO - 
--------------------------------------------------------------------------------
[2022-07-30 18:39:06,393] {taskinstance.py:1377} INFO - Executing <Task(PostgresOperator): create_postgres_table> on 2022-02-04 00:00:00+00:00
[2022-07-30 18:39:06,398] {standard_task_runner.py:52} INFO - Started process 3640 to run task
[2022-07-30 18:39:06,402] {standard_task_runner.py:79} INFO - Running: ['***', 'tasks', 'run', 'dag_with_postgres_operator', 'create_postgres_table', 'scheduled__2022-02-04T00:00:00+00:00', '--job-id', '242', '--raw', '--subdir', 'DAGS_FOLDER/DAGWithPostgresOperator.py', '--cfg-path', '/tmp/tmpv35tghjx', '--error-file', '/tmp/tmpt7g9949c']
[2022-07-30 18:39:06,402] {standard_task_runner.py:80} INFO - Job 242: Subtask create_postgres_table
[2022-07-30 18:39:06,468] {task_command.py:369} INFO - Running <TaskInstance: dag_with_postgres_operator.create_postgres_table scheduled__2022-02-04T00:00:00+00:00 [running]> on host 66bf18ec08cc
[2022-07-30 18:39:06,545] {taskinstance.py:1571} INFO - Exporting the following env vars:
AIRFLOW_CTX_DAG_OWNER=yosr
AIRFLOW_CTX_DAG_ID=dag_with_postgres_operator
AIRFLOW_CTX_TASK_ID=create_postgres_table
AIRFLOW_CTX_EXECUTION_DATE=2022-02-04T00:00:00+00:00
AIRFLOW_CTX_TRY_NUMBER=3
AIRFLOW_CTX_DAG_RUN_ID=scheduled__2022-02-04T00:00:00+00:00
[2022-07-30 18:39:06,558] {base.py:68} INFO - Using connection ID 'postgres_localhost' for task execution.
[2022-07-30 18:39:06,559] {taskinstance.py:1889} ERROR - Task failed with exception
Traceback (most recent call last):
  File "/home/airflow/.local/lib/python3.7/site-packages/airflow/providers/postgres/operators/postgres.py", line 92, in execute
    self.hook.run(self.sql, self.autocommit, parameters=self.parameters)
  File "/home/airflow/.local/lib/python3.7/site-packages/airflow/hooks/dbapi.py", line 181, in run
    with closing(self.get_conn()) as conn:
  File "/home/airflow/.local/lib/python3.7/site-packages/airflow/providers/postgres/hooks/postgres.py", line 113, in get_conn
    self.conn = psycopg2.connect(**conn_args)
  File "/home/airflow/.local/lib/python3.7/site-packages/psycopg2/__init__.py", line 122, in connect
    conn = _connect(dsn, connection_factory=connection_factory, **kwasync)
psycopg2.OperationalError: could not translate host name "host.docker.internal " to address: Name or service not known

[2022-07-30 18:39:06,570] {taskinstance.py:1400} INFO - Marking task as UP_FOR_RETRY. dag_id=dag_with_postgres_operator, task_id=create_postgres_table, execution_date=20220204T000000, start_date=20220730T183906, end_date=20220730T183906
[2022-07-30 18:39:06,583] {standard_task_runner.py:97} ERROR - Failed to execute job 242 for task create_postgres_table (could not translate host name "host.docker.internal " to address: Name or service not known
; 3640)
[2022-07-30 18:39:06,618] {local_task_job.py:156} INFO - Task exited with return code 1
[2022-07-30 18:39:06,663] {local_task_job.py:273} INFO - 0 downstream tasks scheduled from follow-on schedule check
[2022-07-31 09:41:04,130] {taskinstance.py:1159} INFO - Dependencies all met for <TaskInstance: dag_with_postgres_operator.create_postgres_table scheduled__2022-02-04T00:00:00+00:00 [queued]>
[2022-07-31 09:41:04,302] {taskinstance.py:1159} INFO - Dependencies all met for <TaskInstance: dag_with_postgres_operator.create_postgres_table scheduled__2022-02-04T00:00:00+00:00 [queued]>
[2022-07-31 09:41:04,302] {taskinstance.py:1356} INFO - 
--------------------------------------------------------------------------------
[2022-07-31 09:41:04,303] {taskinstance.py:1357} INFO - Starting attempt 3 of 6
[2022-07-31 09:41:04,303] {taskinstance.py:1358} INFO - 
--------------------------------------------------------------------------------
[2022-07-31 09:41:04,579] {taskinstance.py:1377} INFO - Executing <Task(PostgresOperator): create_postgres_table> on 2022-02-04 00:00:00+00:00
[2022-07-31 09:41:04,638] {standard_task_runner.py:52} INFO - Started process 106 to run task
[2022-07-31 09:41:04,829] {standard_task_runner.py:79} INFO - Running: ['***', 'tasks', 'run', 'dag_with_postgres_operator', 'create_postgres_table', 'scheduled__2022-02-04T00:00:00+00:00', '--job-id', '1248', '--raw', '--subdir', 'DAGS_FOLDER/DAGWithPostgresOperator.py', '--cfg-path', '/tmp/tmpdwiytx8g', '--error-file', '/tmp/tmpxot11v2s']
[2022-07-31 09:41:04,829] {standard_task_runner.py:80} INFO - Job 1248: Subtask create_postgres_table
[2022-07-31 09:41:05,505] {task_command.py:369} INFO - Running <TaskInstance: dag_with_postgres_operator.create_postgres_table scheduled__2022-02-04T00:00:00+00:00 [running]> on host 66bf18ec08cc
[2022-07-31 09:41:05,999] {taskinstance.py:1571} INFO - Exporting the following env vars:
AIRFLOW_CTX_DAG_OWNER=yosr
AIRFLOW_CTX_DAG_ID=dag_with_postgres_operator
AIRFLOW_CTX_TASK_ID=create_postgres_table
AIRFLOW_CTX_EXECUTION_DATE=2022-02-04T00:00:00+00:00
AIRFLOW_CTX_TRY_NUMBER=3
AIRFLOW_CTX_DAG_RUN_ID=scheduled__2022-02-04T00:00:00+00:00
[2022-07-31 09:41:06,069] {base.py:68} INFO - Using connection ID 'postgres_localhost' for task execution.
[2022-07-31 09:41:06,070] {taskinstance.py:1889} ERROR - Task failed with exception
Traceback (most recent call last):
  File "/home/airflow/.local/lib/python3.7/site-packages/airflow/providers/postgres/operators/postgres.py", line 92, in execute
    self.hook.run(self.sql, self.autocommit, parameters=self.parameters)
  File "/home/airflow/.local/lib/python3.7/site-packages/airflow/hooks/dbapi.py", line 181, in run
    with closing(self.get_conn()) as conn:
  File "/home/airflow/.local/lib/python3.7/site-packages/airflow/providers/postgres/hooks/postgres.py", line 113, in get_conn
    self.conn = psycopg2.connect(**conn_args)
  File "/home/airflow/.local/lib/python3.7/site-packages/psycopg2/__init__.py", line 122, in connect
    conn = _connect(dsn, connection_factory=connection_factory, **kwasync)
psycopg2.OperationalError: could not translate host name "host.docker.local " to address: Name or service not known

[2022-07-31 09:41:06,095] {taskinstance.py:1400} INFO - Marking task as UP_FOR_RETRY. dag_id=dag_with_postgres_operator, task_id=create_postgres_table, execution_date=20220204T000000, start_date=20220731T094104, end_date=20220731T094106
[2022-07-31 09:41:06,122] {standard_task_runner.py:97} ERROR - Failed to execute job 1248 for task create_postgres_table (could not translate host name "host.docker.local " to address: Name or service not known
; 106)
[2022-07-31 09:41:06,153] {local_task_job.py:156} INFO - Task exited with return code 1
[2022-07-31 09:41:06,369] {local_task_job.py:273} INFO - 0 downstream tasks scheduled from follow-on schedule check
[2022-07-31 14:10:28,967] {taskinstance.py:1159} INFO - Dependencies all met for <TaskInstance: dag_with_postgres_operator.create_postgres_table scheduled__2022-02-04T00:00:00+00:00 [queued]>
[2022-07-31 14:10:28,988] {taskinstance.py:1159} INFO - Dependencies all met for <TaskInstance: dag_with_postgres_operator.create_postgres_table scheduled__2022-02-04T00:00:00+00:00 [queued]>
[2022-07-31 14:10:28,988] {taskinstance.py:1356} INFO - 
--------------------------------------------------------------------------------
[2022-07-31 14:10:28,988] {taskinstance.py:1357} INFO - Starting attempt 3 of 6
[2022-07-31 14:10:28,988] {taskinstance.py:1358} INFO - 
--------------------------------------------------------------------------------
[2022-07-31 14:10:29,011] {taskinstance.py:1377} INFO - Executing <Task(PostgresOperator): create_postgres_table> on 2022-02-04 00:00:00+00:00
[2022-07-31 14:10:29,017] {standard_task_runner.py:52} INFO - Started process 4046 to run task
[2022-07-31 14:10:29,020] {standard_task_runner.py:79} INFO - Running: ['***', 'tasks', 'run', 'dag_with_postgres_operator', 'create_postgres_table', 'scheduled__2022-02-04T00:00:00+00:00', '--job-id', '241', '--raw', '--subdir', 'DAGS_FOLDER/DAGWithPostgresOperator.py', '--cfg-path', '/tmp/tmpw0ynoadn', '--error-file', '/tmp/tmpmt2jeudn']
[2022-07-31 14:10:29,020] {standard_task_runner.py:80} INFO - Job 241: Subtask create_postgres_table
[2022-07-31 14:10:29,105] {task_command.py:369} INFO - Running <TaskInstance: dag_with_postgres_operator.create_postgres_table scheduled__2022-02-04T00:00:00+00:00 [running]> on host 4688dd3b7141
[2022-07-31 14:10:29,207] {taskinstance.py:1571} INFO - Exporting the following env vars:
AIRFLOW_CTX_DAG_OWNER=yosr
AIRFLOW_CTX_DAG_ID=dag_with_postgres_operator
AIRFLOW_CTX_TASK_ID=create_postgres_table
AIRFLOW_CTX_EXECUTION_DATE=2022-02-04T00:00:00+00:00
AIRFLOW_CTX_TRY_NUMBER=3
AIRFLOW_CTX_DAG_RUN_ID=scheduled__2022-02-04T00:00:00+00:00
[2022-07-31 14:10:29,243] {taskinstance.py:1889} ERROR - Task failed with exception
Traceback (most recent call last):
  File "/home/airflow/.local/lib/python3.7/site-packages/airflow/providers/postgres/operators/postgres.py", line 92, in execute
    self.hook.run(self.sql, self.autocommit, parameters=self.parameters)
  File "/home/airflow/.local/lib/python3.7/site-packages/airflow/hooks/dbapi.py", line 181, in run
    with closing(self.get_conn()) as conn:
  File "/home/airflow/.local/lib/python3.7/site-packages/airflow/providers/postgres/hooks/postgres.py", line 86, in get_conn
    conn = deepcopy(self.connection or self.get_connection(conn_id))
  File "/home/airflow/.local/lib/python3.7/site-packages/airflow/hooks/base.py", line 67, in get_connection
    conn = Connection.get_connection_from_secrets(conn_id)
  File "/home/airflow/.local/lib/python3.7/site-packages/airflow/models/connection.py", line 430, in get_connection_from_secrets
    raise AirflowNotFoundException(f"The conn_id `{conn_id}` isn't defined")
airflow.exceptions.AirflowNotFoundException: The conn_id `postgres_localhost` isn't defined
[2022-07-31 14:10:29,248] {taskinstance.py:1400} INFO - Marking task as UP_FOR_RETRY. dag_id=dag_with_postgres_operator, task_id=create_postgres_table, execution_date=20220204T000000, start_date=20220731T141028, end_date=20220731T141029
[2022-07-31 14:10:29,268] {standard_task_runner.py:97} ERROR - Failed to execute job 241 for task create_postgres_table (The conn_id `postgres_localhost` isn't defined; 4046)
[2022-07-31 14:10:29,279] {local_task_job.py:156} INFO - Task exited with return code 1
[2022-07-31 14:10:29,326] {local_task_job.py:273} INFO - 0 downstream tasks scheduled from follow-on schedule check
