[2022-07-30 18:49:04,302] {taskinstance.py:1159} INFO - Dependencies all met for <TaskInstance: dag_with_postgres_operator.create_postgres_table scheduled__2022-01-27T00:00:00+00:00 [queued]>
[2022-07-30 18:49:04,317] {taskinstance.py:1159} INFO - Dependencies all met for <TaskInstance: dag_with_postgres_operator.create_postgres_table scheduled__2022-01-27T00:00:00+00:00 [queued]>
[2022-07-30 18:49:04,317] {taskinstance.py:1356} INFO - 
--------------------------------------------------------------------------------
[2022-07-30 18:49:04,318] {taskinstance.py:1357} INFO - Starting attempt 5 of 6
[2022-07-30 18:49:04,318] {taskinstance.py:1358} INFO - 
--------------------------------------------------------------------------------
[2022-07-30 18:49:04,335] {taskinstance.py:1377} INFO - Executing <Task(PostgresOperator): create_postgres_table> on 2022-01-27 00:00:00+00:00
[2022-07-30 18:49:04,340] {standard_task_runner.py:52} INFO - Started process 4155 to run task
[2022-07-30 18:49:04,344] {standard_task_runner.py:79} INFO - Running: ['***', 'tasks', 'run', 'dag_with_postgres_operator', 'create_postgres_table', 'scheduled__2022-01-27T00:00:00+00:00', '--job-id', '265', '--raw', '--subdir', 'DAGS_FOLDER/DAGWithPostgresOperator.py', '--cfg-path', '/tmp/tmpc4v7h7k1', '--error-file', '/tmp/tmpgm9fze1o']
[2022-07-30 18:49:04,344] {standard_task_runner.py:80} INFO - Job 265: Subtask create_postgres_table
[2022-07-30 18:49:04,411] {task_command.py:369} INFO - Running <TaskInstance: dag_with_postgres_operator.create_postgres_table scheduled__2022-01-27T00:00:00+00:00 [running]> on host 66bf18ec08cc
[2022-07-30 18:49:04,497] {taskinstance.py:1571} INFO - Exporting the following env vars:
AIRFLOW_CTX_DAG_OWNER=yosr
AIRFLOW_CTX_DAG_ID=dag_with_postgres_operator
AIRFLOW_CTX_TASK_ID=create_postgres_table
AIRFLOW_CTX_EXECUTION_DATE=2022-01-27T00:00:00+00:00
AIRFLOW_CTX_TRY_NUMBER=5
AIRFLOW_CTX_DAG_RUN_ID=scheduled__2022-01-27T00:00:00+00:00
[2022-07-30 18:49:04,509] {base.py:68} INFO - Using connection ID 'postgres_localhost' for task execution.
[2022-07-30 18:49:04,510] {taskinstance.py:1889} ERROR - Task failed with exception
Traceback (most recent call last):
  File "/home/airflow/.local/lib/python3.7/site-packages/airflow/providers/postgres/operators/postgres.py", line 92, in execute
    self.hook.run(self.sql, self.autocommit, parameters=self.parameters)
  File "/home/airflow/.local/lib/python3.7/site-packages/airflow/hooks/dbapi.py", line 181, in run
    with closing(self.get_conn()) as conn:
  File "/home/airflow/.local/lib/python3.7/site-packages/airflow/providers/postgres/hooks/postgres.py", line 113, in get_conn
    self.conn = psycopg2.connect(**conn_args)
  File "/home/airflow/.local/lib/python3.7/site-packages/psycopg2/__init__.py", line 122, in connect
    conn = _connect(dsn, connection_factory=connection_factory, **kwasync)
psycopg2.OperationalError: could not translate host name "host.docker.internal " to address: Name or service not known

[2022-07-30 18:49:04,520] {taskinstance.py:1400} INFO - Marking task as UP_FOR_RETRY. dag_id=dag_with_postgres_operator, task_id=create_postgres_table, execution_date=20220127T000000, start_date=20220730T184904, end_date=20220730T184904
[2022-07-30 18:49:04,534] {standard_task_runner.py:97} ERROR - Failed to execute job 265 for task create_postgres_table (could not translate host name "host.docker.internal " to address: Name or service not known
; 4155)
[2022-07-30 18:49:04,561] {local_task_job.py:156} INFO - Task exited with return code 1
[2022-07-30 18:49:04,606] {local_task_job.py:273} INFO - 0 downstream tasks scheduled from follow-on schedule check
[2022-07-31 09:51:10,234] {taskinstance.py:1159} INFO - Dependencies all met for <TaskInstance: dag_with_postgres_operator.create_postgres_table scheduled__2022-01-27T00:00:00+00:00 [queued]>
[2022-07-31 09:51:10,283] {taskinstance.py:1159} INFO - Dependencies all met for <TaskInstance: dag_with_postgres_operator.create_postgres_table scheduled__2022-01-27T00:00:00+00:00 [queued]>
[2022-07-31 09:51:10,283] {taskinstance.py:1356} INFO - 
--------------------------------------------------------------------------------
[2022-07-31 09:51:10,284] {taskinstance.py:1357} INFO - Starting attempt 5 of 6
[2022-07-31 09:51:10,284] {taskinstance.py:1358} INFO - 
--------------------------------------------------------------------------------
[2022-07-31 09:51:10,348] {taskinstance.py:1377} INFO - Executing <Task(PostgresOperator): create_postgres_table> on 2022-01-27 00:00:00+00:00
[2022-07-31 09:51:10,353] {standard_task_runner.py:52} INFO - Started process 636 to run task
[2022-07-31 09:51:10,363] {standard_task_runner.py:79} INFO - Running: ['***', 'tasks', 'run', 'dag_with_postgres_operator', 'create_postgres_table', 'scheduled__2022-01-27T00:00:00+00:00', '--job-id', '1281', '--raw', '--subdir', 'DAGS_FOLDER/DAGWithPostgresOperator.py', '--cfg-path', '/tmp/tmpcvzujv0i', '--error-file', '/tmp/tmp89lxj8x4']
[2022-07-31 09:51:10,363] {standard_task_runner.py:80} INFO - Job 1281: Subtask create_postgres_table
[2022-07-31 09:51:10,931] {task_command.py:369} INFO - Running <TaskInstance: dag_with_postgres_operator.create_postgres_table scheduled__2022-01-27T00:00:00+00:00 [running]> on host 66bf18ec08cc
[2022-07-31 09:51:11,331] {taskinstance.py:1571} INFO - Exporting the following env vars:
AIRFLOW_CTX_DAG_OWNER=yosr
AIRFLOW_CTX_DAG_ID=dag_with_postgres_operator
AIRFLOW_CTX_TASK_ID=create_postgres_table
AIRFLOW_CTX_EXECUTION_DATE=2022-01-27T00:00:00+00:00
AIRFLOW_CTX_TRY_NUMBER=5
AIRFLOW_CTX_DAG_RUN_ID=scheduled__2022-01-27T00:00:00+00:00
[2022-07-31 09:51:11,373] {base.py:68} INFO - Using connection ID 'postgres_localhost' for task execution.
[2022-07-31 09:51:11,375] {taskinstance.py:1889} ERROR - Task failed with exception
Traceback (most recent call last):
  File "/home/airflow/.local/lib/python3.7/site-packages/airflow/providers/postgres/operators/postgres.py", line 92, in execute
    self.hook.run(self.sql, self.autocommit, parameters=self.parameters)
  File "/home/airflow/.local/lib/python3.7/site-packages/airflow/hooks/dbapi.py", line 181, in run
    with closing(self.get_conn()) as conn:
  File "/home/airflow/.local/lib/python3.7/site-packages/airflow/providers/postgres/hooks/postgres.py", line 113, in get_conn
    self.conn = psycopg2.connect(**conn_args)
  File "/home/airflow/.local/lib/python3.7/site-packages/psycopg2/__init__.py", line 122, in connect
    conn = _connect(dsn, connection_factory=connection_factory, **kwasync)
psycopg2.OperationalError: could not translate host name "host.docker.local " to address: Name or service not known

[2022-07-31 09:51:11,423] {taskinstance.py:1400} INFO - Marking task as UP_FOR_RETRY. dag_id=dag_with_postgres_operator, task_id=create_postgres_table, execution_date=20220127T000000, start_date=20220731T095110, end_date=20220731T095111
[2022-07-31 09:51:11,464] {standard_task_runner.py:97} ERROR - Failed to execute job 1281 for task create_postgres_table (could not translate host name "host.docker.local " to address: Name or service not known
; 636)
[2022-07-31 09:51:11,504] {local_task_job.py:156} INFO - Task exited with return code 1
[2022-07-31 09:51:11,633] {local_task_job.py:273} INFO - 0 downstream tasks scheduled from follow-on schedule check
[2022-07-31 14:20:27,317] {taskinstance.py:1159} INFO - Dependencies all met for <TaskInstance: dag_with_postgres_operator.create_postgres_table scheduled__2022-01-27T00:00:00+00:00 [queued]>
[2022-07-31 14:20:27,349] {taskinstance.py:1159} INFO - Dependencies all met for <TaskInstance: dag_with_postgres_operator.create_postgres_table scheduled__2022-01-27T00:00:00+00:00 [queued]>
[2022-07-31 14:20:27,349] {taskinstance.py:1356} INFO - 
--------------------------------------------------------------------------------
[2022-07-31 14:20:27,349] {taskinstance.py:1357} INFO - Starting attempt 5 of 6
[2022-07-31 14:20:27,350] {taskinstance.py:1358} INFO - 
--------------------------------------------------------------------------------
[2022-07-31 14:20:27,369] {taskinstance.py:1377} INFO - Executing <Task(PostgresOperator): create_postgres_table> on 2022-01-27 00:00:00+00:00
[2022-07-31 14:20:27,376] {standard_task_runner.py:52} INFO - Started process 4548 to run task
[2022-07-31 14:20:27,381] {standard_task_runner.py:79} INFO - Running: ['***', 'tasks', 'run', 'dag_with_postgres_operator', 'create_postgres_table', 'scheduled__2022-01-27T00:00:00+00:00', '--job-id', '262', '--raw', '--subdir', 'DAGS_FOLDER/DAGWithPostgresOperator.py', '--cfg-path', '/tmp/tmpnoueyv_n', '--error-file', '/tmp/tmptwr6zacb']
[2022-07-31 14:20:27,381] {standard_task_runner.py:80} INFO - Job 262: Subtask create_postgres_table
[2022-07-31 14:20:27,473] {task_command.py:369} INFO - Running <TaskInstance: dag_with_postgres_operator.create_postgres_table scheduled__2022-01-27T00:00:00+00:00 [running]> on host 4688dd3b7141
[2022-07-31 14:20:27,586] {taskinstance.py:1571} INFO - Exporting the following env vars:
AIRFLOW_CTX_DAG_OWNER=yosr
AIRFLOW_CTX_DAG_ID=dag_with_postgres_operator
AIRFLOW_CTX_TASK_ID=create_postgres_table
AIRFLOW_CTX_EXECUTION_DATE=2022-01-27T00:00:00+00:00
AIRFLOW_CTX_TRY_NUMBER=5
AIRFLOW_CTX_DAG_RUN_ID=scheduled__2022-01-27T00:00:00+00:00
[2022-07-31 14:20:27,675] {taskinstance.py:1889} ERROR - Task failed with exception
Traceback (most recent call last):
  File "/home/airflow/.local/lib/python3.7/site-packages/airflow/providers/postgres/operators/postgres.py", line 92, in execute
    self.hook.run(self.sql, self.autocommit, parameters=self.parameters)
  File "/home/airflow/.local/lib/python3.7/site-packages/airflow/hooks/dbapi.py", line 181, in run
    with closing(self.get_conn()) as conn:
  File "/home/airflow/.local/lib/python3.7/site-packages/airflow/providers/postgres/hooks/postgres.py", line 86, in get_conn
    conn = deepcopy(self.connection or self.get_connection(conn_id))
  File "/home/airflow/.local/lib/python3.7/site-packages/airflow/hooks/base.py", line 67, in get_connection
    conn = Connection.get_connection_from_secrets(conn_id)
  File "/home/airflow/.local/lib/python3.7/site-packages/airflow/models/connection.py", line 430, in get_connection_from_secrets
    raise AirflowNotFoundException(f"The conn_id `{conn_id}` isn't defined")
airflow.exceptions.AirflowNotFoundException: The conn_id `postgres_localhost` isn't defined
[2022-07-31 14:20:27,685] {taskinstance.py:1400} INFO - Marking task as UP_FOR_RETRY. dag_id=dag_with_postgres_operator, task_id=create_postgres_table, execution_date=20220127T000000, start_date=20220731T142027, end_date=20220731T142027
[2022-07-31 14:20:27,706] {standard_task_runner.py:97} ERROR - Failed to execute job 262 for task create_postgres_table (The conn_id `postgres_localhost` isn't defined; 4548)
[2022-07-31 14:20:27,725] {local_task_job.py:156} INFO - Task exited with return code 1
[2022-07-31 14:20:27,795] {local_task_job.py:273} INFO - 0 downstream tasks scheduled from follow-on schedule check
