[2022-07-30 18:59:16,401] {taskinstance.py:1159} INFO - Dependencies all met for <TaskInstance: dag_with_postgres_operator.create_postgres_table scheduled__2022-02-05T00:00:00+00:00 [queued]>
[2022-07-30 18:59:16,415] {taskinstance.py:1159} INFO - Dependencies all met for <TaskInstance: dag_with_postgres_operator.create_postgres_table scheduled__2022-02-05T00:00:00+00:00 [queued]>
[2022-07-30 18:59:16,416] {taskinstance.py:1356} INFO - 
--------------------------------------------------------------------------------
[2022-07-30 18:59:16,416] {taskinstance.py:1357} INFO - Starting attempt 2 of 6
[2022-07-30 18:59:16,416] {taskinstance.py:1358} INFO - 
--------------------------------------------------------------------------------
[2022-07-30 18:59:16,431] {taskinstance.py:1377} INFO - Executing <Task(PostgresOperator): create_postgres_table> on 2022-02-05 00:00:00+00:00
[2022-07-30 18:59:16,435] {standard_task_runner.py:52} INFO - Started process 4717 to run task
[2022-07-30 18:59:16,440] {standard_task_runner.py:79} INFO - Running: ['***', 'tasks', 'run', 'dag_with_postgres_operator', 'create_postgres_table', 'scheduled__2022-02-05T00:00:00+00:00', '--job-id', '307', '--raw', '--subdir', 'DAGS_FOLDER/DAGWithPostgresOperator.py', '--cfg-path', '/tmp/tmpx9fn19kl', '--error-file', '/tmp/tmpm8jpt3f3']
[2022-07-30 18:59:16,441] {standard_task_runner.py:80} INFO - Job 307: Subtask create_postgres_table
[2022-07-30 18:59:16,500] {task_command.py:369} INFO - Running <TaskInstance: dag_with_postgres_operator.create_postgres_table scheduled__2022-02-05T00:00:00+00:00 [running]> on host 66bf18ec08cc
[2022-07-30 18:59:16,578] {taskinstance.py:1571} INFO - Exporting the following env vars:
AIRFLOW_CTX_DAG_OWNER=yosr
AIRFLOW_CTX_DAG_ID=dag_with_postgres_operator
AIRFLOW_CTX_TASK_ID=create_postgres_table
AIRFLOW_CTX_EXECUTION_DATE=2022-02-05T00:00:00+00:00
AIRFLOW_CTX_TRY_NUMBER=2
AIRFLOW_CTX_DAG_RUN_ID=scheduled__2022-02-05T00:00:00+00:00
[2022-07-30 18:59:16,590] {base.py:68} INFO - Using connection ID 'postgres_localhost' for task execution.
[2022-07-30 18:59:16,590] {taskinstance.py:1889} ERROR - Task failed with exception
Traceback (most recent call last):
  File "/home/airflow/.local/lib/python3.7/site-packages/airflow/providers/postgres/operators/postgres.py", line 92, in execute
    self.hook.run(self.sql, self.autocommit, parameters=self.parameters)
  File "/home/airflow/.local/lib/python3.7/site-packages/airflow/hooks/dbapi.py", line 181, in run
    with closing(self.get_conn()) as conn:
  File "/home/airflow/.local/lib/python3.7/site-packages/airflow/providers/postgres/hooks/postgres.py", line 113, in get_conn
    self.conn = psycopg2.connect(**conn_args)
  File "/home/airflow/.local/lib/python3.7/site-packages/psycopg2/__init__.py", line 122, in connect
    conn = _connect(dsn, connection_factory=connection_factory, **kwasync)
psycopg2.OperationalError: could not translate host name "host.docker.internal " to address: Name or service not known

[2022-07-30 18:59:16,601] {taskinstance.py:1400} INFO - Marking task as UP_FOR_RETRY. dag_id=dag_with_postgres_operator, task_id=create_postgres_table, execution_date=20220205T000000, start_date=20220730T185916, end_date=20220730T185916
[2022-07-30 18:59:16,615] {standard_task_runner.py:97} ERROR - Failed to execute job 307 for task create_postgres_table (could not translate host name "host.docker.internal " to address: Name or service not known
; 4717)
[2022-07-30 18:59:16,656] {local_task_job.py:156} INFO - Task exited with return code 1
[2022-07-30 18:59:16,707] {local_task_job.py:273} INFO - 0 downstream tasks scheduled from follow-on schedule check
[2022-07-31 10:01:32,045] {taskinstance.py:1159} INFO - Dependencies all met for <TaskInstance: dag_with_postgres_operator.create_postgres_table scheduled__2022-02-05T00:00:00+00:00 [queued]>
[2022-07-31 10:01:32,061] {taskinstance.py:1159} INFO - Dependencies all met for <TaskInstance: dag_with_postgres_operator.create_postgres_table scheduled__2022-02-05T00:00:00+00:00 [queued]>
[2022-07-31 10:01:32,061] {taskinstance.py:1356} INFO - 
--------------------------------------------------------------------------------
[2022-07-31 10:01:32,061] {taskinstance.py:1357} INFO - Starting attempt 2 of 6
[2022-07-31 10:01:32,061] {taskinstance.py:1358} INFO - 
--------------------------------------------------------------------------------
[2022-07-31 10:01:32,084] {taskinstance.py:1377} INFO - Executing <Task(PostgresOperator): create_postgres_table> on 2022-02-05 00:00:00+00:00
[2022-07-31 10:01:32,088] {standard_task_runner.py:52} INFO - Started process 1188 to run task
[2022-07-31 10:01:32,091] {standard_task_runner.py:79} INFO - Running: ['***', 'tasks', 'run', 'dag_with_postgres_operator', 'create_postgres_table', 'scheduled__2022-02-05T00:00:00+00:00', '--job-id', '1317', '--raw', '--subdir', 'DAGS_FOLDER/DAGWithPostgresOperator.py', '--cfg-path', '/tmp/tmp26pwkj2o', '--error-file', '/tmp/tmpchue1e0c']
[2022-07-31 10:01:32,092] {standard_task_runner.py:80} INFO - Job 1317: Subtask create_postgres_table
[2022-07-31 10:01:32,157] {task_command.py:369} INFO - Running <TaskInstance: dag_with_postgres_operator.create_postgres_table scheduled__2022-02-05T00:00:00+00:00 [running]> on host 66bf18ec08cc
[2022-07-31 10:01:32,249] {taskinstance.py:1571} INFO - Exporting the following env vars:
AIRFLOW_CTX_DAG_OWNER=yosr
AIRFLOW_CTX_DAG_ID=dag_with_postgres_operator
AIRFLOW_CTX_TASK_ID=create_postgres_table
AIRFLOW_CTX_EXECUTION_DATE=2022-02-05T00:00:00+00:00
AIRFLOW_CTX_TRY_NUMBER=2
AIRFLOW_CTX_DAG_RUN_ID=scheduled__2022-02-05T00:00:00+00:00
[2022-07-31 10:01:32,263] {base.py:68} INFO - Using connection ID 'postgres_localhost' for task execution.
[2022-07-31 10:01:32,264] {taskinstance.py:1889} ERROR - Task failed with exception
Traceback (most recent call last):
  File "/home/airflow/.local/lib/python3.7/site-packages/airflow/providers/postgres/operators/postgres.py", line 92, in execute
    self.hook.run(self.sql, self.autocommit, parameters=self.parameters)
  File "/home/airflow/.local/lib/python3.7/site-packages/airflow/hooks/dbapi.py", line 181, in run
    with closing(self.get_conn()) as conn:
  File "/home/airflow/.local/lib/python3.7/site-packages/airflow/providers/postgres/hooks/postgres.py", line 113, in get_conn
    self.conn = psycopg2.connect(**conn_args)
  File "/home/airflow/.local/lib/python3.7/site-packages/psycopg2/__init__.py", line 122, in connect
    conn = _connect(dsn, connection_factory=connection_factory, **kwasync)
psycopg2.OperationalError: could not translate host name "host.docker.local " to address: Name or service not known

[2022-07-31 10:01:32,276] {taskinstance.py:1400} INFO - Marking task as UP_FOR_RETRY. dag_id=dag_with_postgres_operator, task_id=create_postgres_table, execution_date=20220205T000000, start_date=20220731T100132, end_date=20220731T100132
[2022-07-31 10:01:32,294] {standard_task_runner.py:97} ERROR - Failed to execute job 1317 for task create_postgres_table (could not translate host name "host.docker.local " to address: Name or service not known
; 1188)
[2022-07-31 10:01:32,314] {local_task_job.py:156} INFO - Task exited with return code 1
[2022-07-31 10:01:32,446] {local_task_job.py:273} INFO - 0 downstream tasks scheduled from follow-on schedule check
[2022-07-31 14:30:35,764] {taskinstance.py:1159} INFO - Dependencies all met for <TaskInstance: dag_with_postgres_operator.create_postgres_table scheduled__2022-02-05T00:00:00+00:00 [queued]>
[2022-07-31 14:30:35,782] {taskinstance.py:1159} INFO - Dependencies all met for <TaskInstance: dag_with_postgres_operator.create_postgres_table scheduled__2022-02-05T00:00:00+00:00 [queued]>
[2022-07-31 14:30:35,782] {taskinstance.py:1356} INFO - 
--------------------------------------------------------------------------------
[2022-07-31 14:30:35,782] {taskinstance.py:1357} INFO - Starting attempt 2 of 6
[2022-07-31 14:30:35,783] {taskinstance.py:1358} INFO - 
--------------------------------------------------------------------------------
[2022-07-31 14:30:35,803] {taskinstance.py:1377} INFO - Executing <Task(PostgresOperator): create_postgres_table> on 2022-02-05 00:00:00+00:00
[2022-07-31 14:30:35,809] {standard_task_runner.py:52} INFO - Started process 5111 to run task
[2022-07-31 14:30:35,815] {standard_task_runner.py:79} INFO - Running: ['***', 'tasks', 'run', 'dag_with_postgres_operator', 'create_postgres_table', 'scheduled__2022-02-05T00:00:00+00:00', '--job-id', '307', '--raw', '--subdir', 'DAGS_FOLDER/DAGWithPostgresOperator.py', '--cfg-path', '/tmp/tmp7f3ef5an', '--error-file', '/tmp/tmpr9td792u']
[2022-07-31 14:30:35,815] {standard_task_runner.py:80} INFO - Job 307: Subtask create_postgres_table
[2022-07-31 14:30:35,894] {task_command.py:369} INFO - Running <TaskInstance: dag_with_postgres_operator.create_postgres_table scheduled__2022-02-05T00:00:00+00:00 [running]> on host 4688dd3b7141
[2022-07-31 14:30:36,002] {taskinstance.py:1571} INFO - Exporting the following env vars:
AIRFLOW_CTX_DAG_OWNER=yosr
AIRFLOW_CTX_DAG_ID=dag_with_postgres_operator
AIRFLOW_CTX_TASK_ID=create_postgres_table
AIRFLOW_CTX_EXECUTION_DATE=2022-02-05T00:00:00+00:00
AIRFLOW_CTX_TRY_NUMBER=2
AIRFLOW_CTX_DAG_RUN_ID=scheduled__2022-02-05T00:00:00+00:00
[2022-07-31 14:30:36,125] {taskinstance.py:1889} ERROR - Task failed with exception
Traceback (most recent call last):
  File "/home/airflow/.local/lib/python3.7/site-packages/airflow/providers/postgres/operators/postgres.py", line 92, in execute
    self.hook.run(self.sql, self.autocommit, parameters=self.parameters)
  File "/home/airflow/.local/lib/python3.7/site-packages/airflow/hooks/dbapi.py", line 181, in run
    with closing(self.get_conn()) as conn:
  File "/home/airflow/.local/lib/python3.7/site-packages/airflow/providers/postgres/hooks/postgres.py", line 86, in get_conn
    conn = deepcopy(self.connection or self.get_connection(conn_id))
  File "/home/airflow/.local/lib/python3.7/site-packages/airflow/hooks/base.py", line 67, in get_connection
    conn = Connection.get_connection_from_secrets(conn_id)
  File "/home/airflow/.local/lib/python3.7/site-packages/airflow/models/connection.py", line 430, in get_connection_from_secrets
    raise AirflowNotFoundException(f"The conn_id `{conn_id}` isn't defined")
airflow.exceptions.AirflowNotFoundException: The conn_id `postgres_localhost` isn't defined
[2022-07-31 14:30:36,130] {taskinstance.py:1400} INFO - Marking task as UP_FOR_RETRY. dag_id=dag_with_postgres_operator, task_id=create_postgres_table, execution_date=20220205T000000, start_date=20220731T143035, end_date=20220731T143036
[2022-07-31 14:30:36,151] {standard_task_runner.py:97} ERROR - Failed to execute job 307 for task create_postgres_table (The conn_id `postgres_localhost` isn't defined; 5111)
[2022-07-31 14:30:36,193] {local_task_job.py:156} INFO - Task exited with return code 1
[2022-07-31 14:30:36,266] {local_task_job.py:273} INFO - 0 downstream tasks scheduled from follow-on schedule check
