[2022-07-30 18:28:59,656] {taskinstance.py:1159} INFO - Dependencies all met for <TaskInstance: dag_with_postgres_operator.create_postgres_table scheduled__2022-01-23T00:00:00+00:00 [queued]>
[2022-07-30 18:28:59,676] {taskinstance.py:1159} INFO - Dependencies all met for <TaskInstance: dag_with_postgres_operator.create_postgres_table scheduled__2022-01-23T00:00:00+00:00 [queued]>
[2022-07-30 18:28:59,676] {taskinstance.py:1356} INFO - 
--------------------------------------------------------------------------------
[2022-07-30 18:28:59,676] {taskinstance.py:1357} INFO - Starting attempt 1 of 6
[2022-07-30 18:28:59,676] {taskinstance.py:1358} INFO - 
--------------------------------------------------------------------------------
[2022-07-30 18:28:59,700] {taskinstance.py:1377} INFO - Executing <Task(PostgresOperator): create_postgres_table> on 2022-01-23 00:00:00+00:00
[2022-07-30 18:28:59,706] {standard_task_runner.py:52} INFO - Started process 3086 to run task
[2022-07-30 18:28:59,709] {standard_task_runner.py:79} INFO - Running: ['***', 'tasks', 'run', 'dag_with_postgres_operator', 'create_postgres_table', 'scheduled__2022-01-23T00:00:00+00:00', '--job-id', '198', '--raw', '--subdir', 'DAGS_FOLDER/DAGWithPostgresOperator.py', '--cfg-path', '/tmp/tmppp4wlmvl', '--error-file', '/tmp/tmpxrmt25he']
[2022-07-30 18:28:59,710] {standard_task_runner.py:80} INFO - Job 198: Subtask create_postgres_table
[2022-07-30 18:28:59,788] {task_command.py:369} INFO - Running <TaskInstance: dag_with_postgres_operator.create_postgres_table scheduled__2022-01-23T00:00:00+00:00 [running]> on host 66bf18ec08cc
[2022-07-30 18:28:59,896] {taskinstance.py:1571} INFO - Exporting the following env vars:
AIRFLOW_CTX_DAG_OWNER=yosr
AIRFLOW_CTX_DAG_ID=dag_with_postgres_operator
AIRFLOW_CTX_TASK_ID=create_postgres_table
AIRFLOW_CTX_EXECUTION_DATE=2022-01-23T00:00:00+00:00
AIRFLOW_CTX_TRY_NUMBER=1
AIRFLOW_CTX_DAG_RUN_ID=scheduled__2022-01-23T00:00:00+00:00
[2022-07-30 18:28:59,911] {base.py:68} INFO - Using connection ID 'postgres_localhost' for task execution.
[2022-07-30 18:28:59,912] {taskinstance.py:1889} ERROR - Task failed with exception
Traceback (most recent call last):
  File "/home/airflow/.local/lib/python3.7/site-packages/airflow/providers/postgres/operators/postgres.py", line 92, in execute
    self.hook.run(self.sql, self.autocommit, parameters=self.parameters)
  File "/home/airflow/.local/lib/python3.7/site-packages/airflow/hooks/dbapi.py", line 181, in run
    with closing(self.get_conn()) as conn:
  File "/home/airflow/.local/lib/python3.7/site-packages/airflow/providers/postgres/hooks/postgres.py", line 113, in get_conn
    self.conn = psycopg2.connect(**conn_args)
  File "/home/airflow/.local/lib/python3.7/site-packages/psycopg2/__init__.py", line 122, in connect
    conn = _connect(dsn, connection_factory=connection_factory, **kwasync)
psycopg2.OperationalError: could not translate host name "host.docker.internal " to address: Name or service not known

[2022-07-30 18:28:59,927] {taskinstance.py:1400} INFO - Marking task as UP_FOR_RETRY. dag_id=dag_with_postgres_operator, task_id=create_postgres_table, execution_date=20220123T000000, start_date=20220730T182859, end_date=20220730T182859
[2022-07-30 18:28:59,953] {standard_task_runner.py:97} ERROR - Failed to execute job 198 for task create_postgres_table (could not translate host name "host.docker.internal " to address: Name or service not known
; 3086)
[2022-07-30 18:28:59,972] {local_task_job.py:156} INFO - Task exited with return code 1
[2022-07-30 18:29:00,037] {local_task_job.py:273} INFO - 0 downstream tasks scheduled from follow-on schedule check
[2022-07-31 00:35:17,375] {taskinstance.py:1159} INFO - Dependencies all met for <TaskInstance: dag_with_postgres_operator.create_postgres_table scheduled__2022-01-23T00:00:00+00:00 [queued]>
[2022-07-31 00:35:17,394] {taskinstance.py:1159} INFO - Dependencies all met for <TaskInstance: dag_with_postgres_operator.create_postgres_table scheduled__2022-01-23T00:00:00+00:00 [queued]>
[2022-07-31 00:35:17,394] {taskinstance.py:1356} INFO - 
--------------------------------------------------------------------------------
[2022-07-31 00:35:17,394] {taskinstance.py:1357} INFO - Starting attempt 1 of 6
[2022-07-31 00:35:17,394] {taskinstance.py:1358} INFO - 
--------------------------------------------------------------------------------
[2022-07-31 00:35:17,417] {taskinstance.py:1377} INFO - Executing <Task(PostgresOperator): create_postgres_table> on 2022-01-23 00:00:00+00:00
[2022-07-31 00:35:17,422] {standard_task_runner.py:52} INFO - Started process 7017 to run task
[2022-07-31 00:35:17,424] {standard_task_runner.py:79} INFO - Running: ['***', 'tasks', 'run', 'dag_with_postgres_operator', 'create_postgres_table', 'scheduled__2022-01-23T00:00:00+00:00', '--job-id', '1206', '--raw', '--subdir', 'DAGS_FOLDER/DAGWithPostgresOperator.py', '--cfg-path', '/tmp/tmpuvlsmbyb', '--error-file', '/tmp/tmpmglqt9zn']
[2022-07-31 00:35:17,425] {standard_task_runner.py:80} INFO - Job 1206: Subtask create_postgres_table
[2022-07-31 00:35:17,496] {task_command.py:369} INFO - Running <TaskInstance: dag_with_postgres_operator.create_postgres_table scheduled__2022-01-23T00:00:00+00:00 [running]> on host 66bf18ec08cc
[2022-07-31 00:35:17,599] {taskinstance.py:1571} INFO - Exporting the following env vars:
AIRFLOW_CTX_DAG_OWNER=yosr
AIRFLOW_CTX_DAG_ID=dag_with_postgres_operator
AIRFLOW_CTX_TASK_ID=create_postgres_table
AIRFLOW_CTX_EXECUTION_DATE=2022-01-23T00:00:00+00:00
AIRFLOW_CTX_TRY_NUMBER=1
AIRFLOW_CTX_DAG_RUN_ID=scheduled__2022-01-23T00:00:00+00:00
[2022-07-31 00:35:17,612] {base.py:68} INFO - Using connection ID 'postgres_localhost' for task execution.
[2022-07-31 00:35:17,613] {taskinstance.py:1889} ERROR - Task failed with exception
Traceback (most recent call last):
  File "/home/airflow/.local/lib/python3.7/site-packages/airflow/providers/postgres/operators/postgres.py", line 92, in execute
    self.hook.run(self.sql, self.autocommit, parameters=self.parameters)
  File "/home/airflow/.local/lib/python3.7/site-packages/airflow/hooks/dbapi.py", line 181, in run
    with closing(self.get_conn()) as conn:
  File "/home/airflow/.local/lib/python3.7/site-packages/airflow/providers/postgres/hooks/postgres.py", line 113, in get_conn
    self.conn = psycopg2.connect(**conn_args)
  File "/home/airflow/.local/lib/python3.7/site-packages/psycopg2/__init__.py", line 122, in connect
    conn = _connect(dsn, connection_factory=connection_factory, **kwasync)
psycopg2.OperationalError: could not translate host name "host.docker.local " to address: Name or service not known

[2022-07-31 00:35:17,628] {taskinstance.py:1400} INFO - Marking task as UP_FOR_RETRY. dag_id=dag_with_postgres_operator, task_id=create_postgres_table, execution_date=20220123T000000, start_date=20220731T003517, end_date=20220731T003517
[2022-07-31 00:35:17,647] {standard_task_runner.py:97} ERROR - Failed to execute job 1206 for task create_postgres_table (could not translate host name "host.docker.local " to address: Name or service not known
; 7017)
[2022-07-31 00:35:17,683] {local_task_job.py:156} INFO - Task exited with return code 1
[2022-07-31 00:35:17,741] {local_task_job.py:273} INFO - 0 downstream tasks scheduled from follow-on schedule check
[2022-07-31 11:30:12,796] {taskinstance.py:1159} INFO - Dependencies all met for <TaskInstance: dag_with_postgres_operator.create_postgres_table scheduled__2022-01-23T00:00:00+00:00 [queued]>
[2022-07-31 11:30:12,816] {taskinstance.py:1159} INFO - Dependencies all met for <TaskInstance: dag_with_postgres_operator.create_postgres_table scheduled__2022-01-23T00:00:00+00:00 [queued]>
[2022-07-31 11:30:12,816] {taskinstance.py:1356} INFO - 
--------------------------------------------------------------------------------
[2022-07-31 11:30:12,817] {taskinstance.py:1357} INFO - Starting attempt 1 of 6
[2022-07-31 11:30:12,817] {taskinstance.py:1358} INFO - 
--------------------------------------------------------------------------------
[2022-07-31 11:30:12,846] {taskinstance.py:1377} INFO - Executing <Task(PostgresOperator): create_postgres_table> on 2022-01-23 00:00:00+00:00
[2022-07-31 11:30:12,853] {standard_task_runner.py:52} INFO - Started process 5956 to run task
[2022-07-31 11:30:12,856] {standard_task_runner.py:79} INFO - Running: ['***', 'tasks', 'run', 'dag_with_postgres_operator', 'create_postgres_table', 'scheduled__2022-01-23T00:00:00+00:00', '--job-id', '1657', '--raw', '--subdir', 'DAGS_FOLDER/DAGWithPostgresOperator.py', '--cfg-path', '/tmp/tmpa27kr9xp', '--error-file', '/tmp/tmphfxkb9s3']
[2022-07-31 11:30:12,856] {standard_task_runner.py:80} INFO - Job 1657: Subtask create_postgres_table
[2022-07-31 11:30:12,949] {task_command.py:369} INFO - Running <TaskInstance: dag_with_postgres_operator.create_postgres_table scheduled__2022-01-23T00:00:00+00:00 [running]> on host 66bf18ec08cc
[2022-07-31 11:30:13,054] {taskinstance.py:1571} INFO - Exporting the following env vars:
AIRFLOW_CTX_DAG_OWNER=yosr
AIRFLOW_CTX_DAG_ID=dag_with_postgres_operator
AIRFLOW_CTX_TASK_ID=create_postgres_table
AIRFLOW_CTX_EXECUTION_DATE=2022-01-23T00:00:00+00:00
AIRFLOW_CTX_TRY_NUMBER=1
AIRFLOW_CTX_DAG_RUN_ID=scheduled__2022-01-23T00:00:00+00:00
[2022-07-31 11:30:13,066] {base.py:68} INFO - Using connection ID 'postgres_localhost' for task execution.
[2022-07-31 11:30:38,094] {taskinstance.py:1889} ERROR - Task failed with exception
Traceback (most recent call last):
  File "/home/airflow/.local/lib/python3.7/site-packages/airflow/providers/postgres/operators/postgres.py", line 92, in execute
    self.hook.run(self.sql, self.autocommit, parameters=self.parameters)
  File "/home/airflow/.local/lib/python3.7/site-packages/airflow/hooks/dbapi.py", line 181, in run
    with closing(self.get_conn()) as conn:
  File "/home/airflow/.local/lib/python3.7/site-packages/airflow/providers/postgres/hooks/postgres.py", line 113, in get_conn
    self.conn = psycopg2.connect(**conn_args)
  File "/home/airflow/.local/lib/python3.7/site-packages/psycopg2/__init__.py", line 122, in connect
    conn = _connect(dsn, connection_factory=connection_factory, **kwasync)
psycopg2.OperationalError: could not translate host name "host.docker.internal" to address: Temporary failure in name resolution

[2022-07-31 11:30:38,107] {taskinstance.py:1400} INFO - Marking task as UP_FOR_RETRY. dag_id=dag_with_postgres_operator, task_id=create_postgres_table, execution_date=20220123T000000, start_date=20220731T113012, end_date=20220731T113038
[2022-07-31 11:30:38,121] {standard_task_runner.py:97} ERROR - Failed to execute job 1657 for task create_postgres_table (could not translate host name "host.docker.internal" to address: Temporary failure in name resolution
; 5956)
[2022-07-31 11:30:38,143] {local_task_job.py:156} INFO - Task exited with return code 1
[2022-07-31 11:30:38,173] {local_task_job.py:273} INFO - 0 downstream tasks scheduled from follow-on schedule check
[2022-07-31 14:00:22,459] {taskinstance.py:1159} INFO - Dependencies all met for <TaskInstance: dag_with_postgres_operator.create_postgres_table scheduled__2022-01-23T00:00:00+00:00 [queued]>
[2022-07-31 14:00:22,482] {taskinstance.py:1159} INFO - Dependencies all met for <TaskInstance: dag_with_postgres_operator.create_postgres_table scheduled__2022-01-23T00:00:00+00:00 [queued]>
[2022-07-31 14:00:22,483] {taskinstance.py:1356} INFO - 
--------------------------------------------------------------------------------
[2022-07-31 14:00:22,483] {taskinstance.py:1357} INFO - Starting attempt 1 of 6
[2022-07-31 14:00:22,483] {taskinstance.py:1358} INFO - 
--------------------------------------------------------------------------------
[2022-07-31 14:00:22,521] {taskinstance.py:1377} INFO - Executing <Task(PostgresOperator): create_postgres_table> on 2022-01-23 00:00:00+00:00
[2022-07-31 14:00:22,527] {standard_task_runner.py:52} INFO - Started process 3488 to run task
[2022-07-31 14:00:22,532] {standard_task_runner.py:79} INFO - Running: ['***', 'tasks', 'run', 'dag_with_postgres_operator', 'create_postgres_table', 'scheduled__2022-01-23T00:00:00+00:00', '--job-id', '198', '--raw', '--subdir', 'DAGS_FOLDER/DAGWithPostgresOperator.py', '--cfg-path', '/tmp/tmp1hiy9soj', '--error-file', '/tmp/tmpvllybm9u']
[2022-07-31 14:00:22,533] {standard_task_runner.py:80} INFO - Job 198: Subtask create_postgres_table
[2022-07-31 14:00:22,647] {task_command.py:369} INFO - Running <TaskInstance: dag_with_postgres_operator.create_postgres_table scheduled__2022-01-23T00:00:00+00:00 [running]> on host 4688dd3b7141
[2022-07-31 14:00:22,802] {taskinstance.py:1571} INFO - Exporting the following env vars:
AIRFLOW_CTX_DAG_OWNER=yosr
AIRFLOW_CTX_DAG_ID=dag_with_postgres_operator
AIRFLOW_CTX_TASK_ID=create_postgres_table
AIRFLOW_CTX_EXECUTION_DATE=2022-01-23T00:00:00+00:00
AIRFLOW_CTX_TRY_NUMBER=1
AIRFLOW_CTX_DAG_RUN_ID=scheduled__2022-01-23T00:00:00+00:00
[2022-07-31 14:00:22,870] {taskinstance.py:1889} ERROR - Task failed with exception
Traceback (most recent call last):
  File "/home/airflow/.local/lib/python3.7/site-packages/airflow/providers/postgres/operators/postgres.py", line 92, in execute
    self.hook.run(self.sql, self.autocommit, parameters=self.parameters)
  File "/home/airflow/.local/lib/python3.7/site-packages/airflow/hooks/dbapi.py", line 181, in run
    with closing(self.get_conn()) as conn:
  File "/home/airflow/.local/lib/python3.7/site-packages/airflow/providers/postgres/hooks/postgres.py", line 86, in get_conn
    conn = deepcopy(self.connection or self.get_connection(conn_id))
  File "/home/airflow/.local/lib/python3.7/site-packages/airflow/hooks/base.py", line 67, in get_connection
    conn = Connection.get_connection_from_secrets(conn_id)
  File "/home/airflow/.local/lib/python3.7/site-packages/airflow/models/connection.py", line 430, in get_connection_from_secrets
    raise AirflowNotFoundException(f"The conn_id `{conn_id}` isn't defined")
airflow.exceptions.AirflowNotFoundException: The conn_id `postgres_localhost` isn't defined
[2022-07-31 14:00:22,879] {taskinstance.py:1400} INFO - Marking task as UP_FOR_RETRY. dag_id=dag_with_postgres_operator, task_id=create_postgres_table, execution_date=20220123T000000, start_date=20220731T140022, end_date=20220731T140022
[2022-07-31 14:00:22,901] {standard_task_runner.py:97} ERROR - Failed to execute job 198 for task create_postgres_table (The conn_id `postgres_localhost` isn't defined; 3488)
[2022-07-31 14:00:22,915] {local_task_job.py:156} INFO - Task exited with return code 1
[2022-07-31 14:00:23,053] {local_task_job.py:273} INFO - 0 downstream tasks scheduled from follow-on schedule check
