[2022-07-30 18:23:52,965] {taskinstance.py:1159} INFO - Dependencies all met for <TaskInstance: dag_with_postgres_operator.create_postgres_table scheduled__2022-01-11T00:00:00+00:00 [queued]>
[2022-07-30 18:23:52,981] {taskinstance.py:1159} INFO - Dependencies all met for <TaskInstance: dag_with_postgres_operator.create_postgres_table scheduled__2022-01-11T00:00:00+00:00 [queued]>
[2022-07-30 18:23:52,982] {taskinstance.py:1356} INFO - 
--------------------------------------------------------------------------------
[2022-07-30 18:23:52,982] {taskinstance.py:1357} INFO - Starting attempt 5 of 6
[2022-07-30 18:23:52,982] {taskinstance.py:1358} INFO - 
--------------------------------------------------------------------------------
[2022-07-30 18:23:53,001] {taskinstance.py:1377} INFO - Executing <Task(PostgresOperator): create_postgres_table> on 2022-01-11 00:00:00+00:00
[2022-07-30 18:23:53,007] {standard_task_runner.py:52} INFO - Started process 2799 to run task
[2022-07-30 18:23:53,009] {standard_task_runner.py:79} INFO - Running: ['***', 'tasks', 'run', 'dag_with_postgres_operator', 'create_postgres_table', 'scheduled__2022-01-11T00:00:00+00:00', '--job-id', '170', '--raw', '--subdir', 'DAGS_FOLDER/DAGWithPostgresOperator.py', '--cfg-path', '/tmp/tmpedu2gbfj', '--error-file', '/tmp/tmpijy85d0s']
[2022-07-30 18:23:53,010] {standard_task_runner.py:80} INFO - Job 170: Subtask create_postgres_table
[2022-07-30 18:23:53,086] {task_command.py:369} INFO - Running <TaskInstance: dag_with_postgres_operator.create_postgres_table scheduled__2022-01-11T00:00:00+00:00 [running]> on host 66bf18ec08cc
[2022-07-30 18:23:53,188] {taskinstance.py:1571} INFO - Exporting the following env vars:
AIRFLOW_CTX_DAG_OWNER=yosr
AIRFLOW_CTX_DAG_ID=dag_with_postgres_operator
AIRFLOW_CTX_TASK_ID=create_postgres_table
AIRFLOW_CTX_EXECUTION_DATE=2022-01-11T00:00:00+00:00
AIRFLOW_CTX_TRY_NUMBER=5
AIRFLOW_CTX_DAG_RUN_ID=scheduled__2022-01-11T00:00:00+00:00
[2022-07-30 18:23:53,202] {base.py:68} INFO - Using connection ID 'postgres_localhost' for task execution.
[2022-07-30 18:23:53,203] {taskinstance.py:1889} ERROR - Task failed with exception
Traceback (most recent call last):
  File "/home/airflow/.local/lib/python3.7/site-packages/airflow/providers/postgres/operators/postgres.py", line 92, in execute
    self.hook.run(self.sql, self.autocommit, parameters=self.parameters)
  File "/home/airflow/.local/lib/python3.7/site-packages/airflow/hooks/dbapi.py", line 181, in run
    with closing(self.get_conn()) as conn:
  File "/home/airflow/.local/lib/python3.7/site-packages/airflow/providers/postgres/hooks/postgres.py", line 113, in get_conn
    self.conn = psycopg2.connect(**conn_args)
  File "/home/airflow/.local/lib/python3.7/site-packages/psycopg2/__init__.py", line 122, in connect
    conn = _connect(dsn, connection_factory=connection_factory, **kwasync)
psycopg2.OperationalError: could not translate host name "host.docker.internal " to address: Name or service not known

[2022-07-30 18:23:53,216] {taskinstance.py:1400} INFO - Marking task as UP_FOR_RETRY. dag_id=dag_with_postgres_operator, task_id=create_postgres_table, execution_date=20220111T000000, start_date=20220730T182352, end_date=20220730T182353
[2022-07-30 18:23:53,234] {standard_task_runner.py:97} ERROR - Failed to execute job 170 for task create_postgres_table (could not translate host name "host.docker.internal " to address: Name or service not known
; 2799)
[2022-07-30 18:23:53,270] {local_task_job.py:156} INFO - Task exited with return code 1
[2022-07-30 18:23:53,326] {local_task_job.py:273} INFO - 0 downstream tasks scheduled from follow-on schedule check
[2022-07-31 00:30:06,115] {taskinstance.py:1159} INFO - Dependencies all met for <TaskInstance: dag_with_postgres_operator.create_postgres_table scheduled__2022-01-11T00:00:00+00:00 [queued]>
[2022-07-31 00:30:06,133] {taskinstance.py:1159} INFO - Dependencies all met for <TaskInstance: dag_with_postgres_operator.create_postgres_table scheduled__2022-01-11T00:00:00+00:00 [queued]>
[2022-07-31 00:30:06,134] {taskinstance.py:1356} INFO - 
--------------------------------------------------------------------------------
[2022-07-31 00:30:06,134] {taskinstance.py:1357} INFO - Starting attempt 5 of 6
[2022-07-31 00:30:06,134] {taskinstance.py:1358} INFO - 
--------------------------------------------------------------------------------
[2022-07-31 00:30:06,155] {taskinstance.py:1377} INFO - Executing <Task(PostgresOperator): create_postgres_table> on 2022-01-11 00:00:00+00:00
[2022-07-31 00:30:06,160] {standard_task_runner.py:52} INFO - Started process 6722 to run task
[2022-07-31 00:30:06,163] {standard_task_runner.py:79} INFO - Running: ['***', 'tasks', 'run', 'dag_with_postgres_operator', 'create_postgres_table', 'scheduled__2022-01-11T00:00:00+00:00', '--job-id', '1177', '--raw', '--subdir', 'DAGS_FOLDER/DAGWithPostgresOperator.py', '--cfg-path', '/tmp/tmpfs84hr0_', '--error-file', '/tmp/tmp87wnxmz1']
[2022-07-31 00:30:06,164] {standard_task_runner.py:80} INFO - Job 1177: Subtask create_postgres_table
[2022-07-31 00:30:06,247] {task_command.py:369} INFO - Running <TaskInstance: dag_with_postgres_operator.create_postgres_table scheduled__2022-01-11T00:00:00+00:00 [running]> on host 66bf18ec08cc
[2022-07-31 00:30:06,405] {taskinstance.py:1571} INFO - Exporting the following env vars:
AIRFLOW_CTX_DAG_OWNER=yosr
AIRFLOW_CTX_DAG_ID=dag_with_postgres_operator
AIRFLOW_CTX_TASK_ID=create_postgres_table
AIRFLOW_CTX_EXECUTION_DATE=2022-01-11T00:00:00+00:00
AIRFLOW_CTX_TRY_NUMBER=5
AIRFLOW_CTX_DAG_RUN_ID=scheduled__2022-01-11T00:00:00+00:00
[2022-07-31 00:30:06,426] {base.py:68} INFO - Using connection ID 'postgres_localhost' for task execution.
[2022-07-31 00:30:06,428] {taskinstance.py:1889} ERROR - Task failed with exception
Traceback (most recent call last):
  File "/home/airflow/.local/lib/python3.7/site-packages/airflow/providers/postgres/operators/postgres.py", line 92, in execute
    self.hook.run(self.sql, self.autocommit, parameters=self.parameters)
  File "/home/airflow/.local/lib/python3.7/site-packages/airflow/hooks/dbapi.py", line 181, in run
    with closing(self.get_conn()) as conn:
  File "/home/airflow/.local/lib/python3.7/site-packages/airflow/providers/postgres/hooks/postgres.py", line 113, in get_conn
    self.conn = psycopg2.connect(**conn_args)
  File "/home/airflow/.local/lib/python3.7/site-packages/psycopg2/__init__.py", line 122, in connect
    conn = _connect(dsn, connection_factory=connection_factory, **kwasync)
psycopg2.OperationalError: could not translate host name "host.docker.local " to address: Name or service not known

[2022-07-31 00:30:06,449] {taskinstance.py:1400} INFO - Marking task as UP_FOR_RETRY. dag_id=dag_with_postgres_operator, task_id=create_postgres_table, execution_date=20220111T000000, start_date=20220731T003006, end_date=20220731T003006
[2022-07-31 00:30:06,472] {standard_task_runner.py:97} ERROR - Failed to execute job 1177 for task create_postgres_table (could not translate host name "host.docker.local " to address: Name or service not known
; 6722)
[2022-07-31 00:30:06,513] {local_task_job.py:156} INFO - Task exited with return code 1
[2022-07-31 00:30:06,705] {local_task_job.py:273} INFO - 0 downstream tasks scheduled from follow-on schedule check
[2022-07-31 11:24:21,438] {taskinstance.py:1159} INFO - Dependencies all met for <TaskInstance: dag_with_postgres_operator.create_postgres_table scheduled__2022-01-11T00:00:00+00:00 [queued]>
[2022-07-31 11:24:21,450] {taskinstance.py:1159} INFO - Dependencies all met for <TaskInstance: dag_with_postgres_operator.create_postgres_table scheduled__2022-01-11T00:00:00+00:00 [queued]>
[2022-07-31 11:24:21,450] {taskinstance.py:1356} INFO - 
--------------------------------------------------------------------------------
[2022-07-31 11:24:21,450] {taskinstance.py:1357} INFO - Starting attempt 5 of 6
[2022-07-31 11:24:21,450] {taskinstance.py:1358} INFO - 
--------------------------------------------------------------------------------
[2022-07-31 11:24:21,471] {taskinstance.py:1377} INFO - Executing <Task(PostgresOperator): create_postgres_table> on 2022-01-11 00:00:00+00:00
[2022-07-31 11:24:21,475] {standard_task_runner.py:52} INFO - Started process 5645 to run task
[2022-07-31 11:24:21,478] {standard_task_runner.py:79} INFO - Running: ['***', 'tasks', 'run', 'dag_with_postgres_operator', 'create_postgres_table', 'scheduled__2022-01-11T00:00:00+00:00', '--job-id', '1637', '--raw', '--subdir', 'DAGS_FOLDER/DAGWithPostgresOperator.py', '--cfg-path', '/tmp/tmp3f4uw2xm', '--error-file', '/tmp/tmprjliujp7']
[2022-07-31 11:24:21,478] {standard_task_runner.py:80} INFO - Job 1637: Subtask create_postgres_table
[2022-07-31 11:24:21,539] {task_command.py:369} INFO - Running <TaskInstance: dag_with_postgres_operator.create_postgres_table scheduled__2022-01-11T00:00:00+00:00 [running]> on host 66bf18ec08cc
[2022-07-31 11:24:21,622] {taskinstance.py:1571} INFO - Exporting the following env vars:
AIRFLOW_CTX_DAG_OWNER=yosr
AIRFLOW_CTX_DAG_ID=dag_with_postgres_operator
AIRFLOW_CTX_TASK_ID=create_postgres_table
AIRFLOW_CTX_EXECUTION_DATE=2022-01-11T00:00:00+00:00
AIRFLOW_CTX_TRY_NUMBER=5
AIRFLOW_CTX_DAG_RUN_ID=scheduled__2022-01-11T00:00:00+00:00
[2022-07-31 11:24:21,634] {base.py:68} INFO - Using connection ID 'postgres_localhost' for task execution.
[2022-07-31 11:24:46,645] {taskinstance.py:1889} ERROR - Task failed with exception
Traceback (most recent call last):
  File "/home/airflow/.local/lib/python3.7/site-packages/airflow/providers/postgres/operators/postgres.py", line 92, in execute
    self.hook.run(self.sql, self.autocommit, parameters=self.parameters)
  File "/home/airflow/.local/lib/python3.7/site-packages/airflow/hooks/dbapi.py", line 181, in run
    with closing(self.get_conn()) as conn:
  File "/home/airflow/.local/lib/python3.7/site-packages/airflow/providers/postgres/hooks/postgres.py", line 113, in get_conn
    self.conn = psycopg2.connect(**conn_args)
  File "/home/airflow/.local/lib/python3.7/site-packages/psycopg2/__init__.py", line 122, in connect
    conn = _connect(dsn, connection_factory=connection_factory, **kwasync)
psycopg2.OperationalError: could not translate host name "host.docker.internal" to address: No address associated with hostname

[2022-07-31 11:24:46,658] {taskinstance.py:1400} INFO - Marking task as UP_FOR_RETRY. dag_id=dag_with_postgres_operator, task_id=create_postgres_table, execution_date=20220111T000000, start_date=20220731T112421, end_date=20220731T112446
[2022-07-31 11:24:46,822] {standard_task_runner.py:97} ERROR - Failed to execute job 1637 for task create_postgres_table (could not translate host name "host.docker.internal" to address: No address associated with hostname
; 5645)
[2022-07-31 11:24:46,858] {local_task_job.py:156} INFO - Task exited with return code 1
[2022-07-31 11:24:46,888] {local_task_job.py:273} INFO - 0 downstream tasks scheduled from follow-on schedule check
[2022-07-31 13:55:12,707] {taskinstance.py:1159} INFO - Dependencies all met for <TaskInstance: dag_with_postgres_operator.create_postgres_table scheduled__2022-01-11T00:00:00+00:00 [queued]>
[2022-07-31 13:55:12,729] {taskinstance.py:1159} INFO - Dependencies all met for <TaskInstance: dag_with_postgres_operator.create_postgres_table scheduled__2022-01-11T00:00:00+00:00 [queued]>
[2022-07-31 13:55:12,729] {taskinstance.py:1356} INFO - 
--------------------------------------------------------------------------------
[2022-07-31 13:55:12,730] {taskinstance.py:1357} INFO - Starting attempt 5 of 6
[2022-07-31 13:55:12,730] {taskinstance.py:1358} INFO - 
--------------------------------------------------------------------------------
[2022-07-31 13:55:12,754] {taskinstance.py:1377} INFO - Executing <Task(PostgresOperator): create_postgres_table> on 2022-01-11 00:00:00+00:00
[2022-07-31 13:55:12,760] {standard_task_runner.py:52} INFO - Started process 3196 to run task
[2022-07-31 13:55:12,764] {standard_task_runner.py:79} INFO - Running: ['***', 'tasks', 'run', 'dag_with_postgres_operator', 'create_postgres_table', 'scheduled__2022-01-11T00:00:00+00:00', '--job-id', '168', '--raw', '--subdir', 'DAGS_FOLDER/DAGWithPostgresOperator.py', '--cfg-path', '/tmp/tmp68evipfq', '--error-file', '/tmp/tmpk8tlim7o']
[2022-07-31 13:55:12,764] {standard_task_runner.py:80} INFO - Job 168: Subtask create_postgres_table
[2022-07-31 13:55:12,858] {task_command.py:369} INFO - Running <TaskInstance: dag_with_postgres_operator.create_postgres_table scheduled__2022-01-11T00:00:00+00:00 [running]> on host 4688dd3b7141
[2022-07-31 13:55:12,974] {taskinstance.py:1571} INFO - Exporting the following env vars:
AIRFLOW_CTX_DAG_OWNER=yosr
AIRFLOW_CTX_DAG_ID=dag_with_postgres_operator
AIRFLOW_CTX_TASK_ID=create_postgres_table
AIRFLOW_CTX_EXECUTION_DATE=2022-01-11T00:00:00+00:00
AIRFLOW_CTX_TRY_NUMBER=5
AIRFLOW_CTX_DAG_RUN_ID=scheduled__2022-01-11T00:00:00+00:00
[2022-07-31 13:55:13,072] {taskinstance.py:1889} ERROR - Task failed with exception
Traceback (most recent call last):
  File "/home/airflow/.local/lib/python3.7/site-packages/airflow/providers/postgres/operators/postgres.py", line 92, in execute
    self.hook.run(self.sql, self.autocommit, parameters=self.parameters)
  File "/home/airflow/.local/lib/python3.7/site-packages/airflow/hooks/dbapi.py", line 181, in run
    with closing(self.get_conn()) as conn:
  File "/home/airflow/.local/lib/python3.7/site-packages/airflow/providers/postgres/hooks/postgres.py", line 86, in get_conn
    conn = deepcopy(self.connection or self.get_connection(conn_id))
  File "/home/airflow/.local/lib/python3.7/site-packages/airflow/hooks/base.py", line 67, in get_connection
    conn = Connection.get_connection_from_secrets(conn_id)
  File "/home/airflow/.local/lib/python3.7/site-packages/airflow/models/connection.py", line 430, in get_connection_from_secrets
    raise AirflowNotFoundException(f"The conn_id `{conn_id}` isn't defined")
airflow.exceptions.AirflowNotFoundException: The conn_id `postgres_localhost` isn't defined
[2022-07-31 13:55:13,079] {taskinstance.py:1400} INFO - Marking task as UP_FOR_RETRY. dag_id=dag_with_postgres_operator, task_id=create_postgres_table, execution_date=20220111T000000, start_date=20220731T135512, end_date=20220731T135513
[2022-07-31 13:55:13,098] {standard_task_runner.py:97} ERROR - Failed to execute job 168 for task create_postgres_table (The conn_id `postgres_localhost` isn't defined; 3196)
[2022-07-31 13:55:13,148] {local_task_job.py:156} INFO - Task exited with return code 1
[2022-07-31 13:55:13,216] {local_task_job.py:273} INFO - 0 downstream tasks scheduled from follow-on schedule check
