[2022-07-29 10:57:26,604] {taskinstance.py:1159} INFO - Dependencies all met for <TaskInstance: Second_one.first_task scheduled__2022-01-24T00:00:00+00:00 [queued]>
[2022-07-29 10:57:26,620] {taskinstance.py:1159} INFO - Dependencies all met for <TaskInstance: Second_one.first_task scheduled__2022-01-24T00:00:00+00:00 [queued]>
[2022-07-29 10:57:26,620] {taskinstance.py:1356} INFO - 
--------------------------------------------------------------------------------
[2022-07-29 10:57:26,620] {taskinstance.py:1357} INFO - Starting attempt 2 of 6
[2022-07-29 10:57:26,620] {taskinstance.py:1358} INFO - 
--------------------------------------------------------------------------------
[2022-07-29 10:57:26,645] {taskinstance.py:1377} INFO - Executing <Task(BashOperator): first_task> on 2022-01-24 00:00:00+00:00
[2022-07-29 10:57:26,651] {standard_task_runner.py:52} INFO - Started process 3272 to run task
[2022-07-29 10:57:26,655] {standard_task_runner.py:79} INFO - Running: ['***', 'tasks', 'run', 'Second_one', 'first_task', 'scheduled__2022-01-24T00:00:00+00:00', '--job-id', '265', '--raw', '--subdir', 'DAGS_FOLDER/Second_One.py', '--cfg-path', '/tmp/tmpjqqf0rfp', '--error-file', '/tmp/tmpxkgybaip']
[2022-07-29 10:57:26,656] {standard_task_runner.py:80} INFO - Job 265: Subtask first_task
[2022-07-29 10:57:26,735] {task_command.py:369} INFO - Running <TaskInstance: Second_one.first_task scheduled__2022-01-24T00:00:00+00:00 [running]> on host 9f0f006fc89d
[2022-07-29 10:57:26,848] {taskinstance.py:1571} INFO - Exporting the following env vars:
AIRFLOW_CTX_DAG_OWNER=yosr
AIRFLOW_CTX_DAG_ID=Second_one
AIRFLOW_CTX_TASK_ID=first_task
AIRFLOW_CTX_EXECUTION_DATE=2022-01-24T00:00:00+00:00
AIRFLOW_CTX_TRY_NUMBER=2
AIRFLOW_CTX_DAG_RUN_ID=scheduled__2022-01-24T00:00:00+00:00
[2022-07-29 10:57:26,849] {subprocess.py:62} INFO - Tmp dir root location: 
 /tmp
[2022-07-29 10:57:26,850] {subprocess.py:74} INFO - Running command: ['bash', '-c', "echo hello world, I'm the first task"]
[2022-07-29 10:57:26,862] {subprocess.py:85} INFO - Output:
[2022-07-29 10:57:26,865] {subprocess.py:92} INFO - bash: -c: line 1: unexpected EOF while looking for matching `''
[2022-07-29 10:57:26,865] {subprocess.py:92} INFO - bash: -c: line 2: syntax error: unexpected end of file
[2022-07-29 10:57:26,865] {subprocess.py:96} INFO - Command exited with return code 2
[2022-07-29 10:57:26,929] {taskinstance.py:1889} ERROR - Task failed with exception
Traceback (most recent call last):
  File "/home/airflow/.local/lib/python3.7/site-packages/airflow/operators/bash.py", line 195, in execute
    f'Bash command failed. The command returned a non-zero exit code {result.exit_code}.'
airflow.exceptions.AirflowException: Bash command failed. The command returned a non-zero exit code 2.
[2022-07-29 10:57:26,935] {taskinstance.py:1400} INFO - Marking task as UP_FOR_RETRY. dag_id=Second_one, task_id=first_task, execution_date=20220124T000000, start_date=20220729T105726, end_date=20220729T105726
[2022-07-29 10:57:26,956] {standard_task_runner.py:97} ERROR - Failed to execute job 265 for task first_task (Bash command failed. The command returned a non-zero exit code 2.; 3272)
[2022-07-29 10:57:26,995] {local_task_job.py:156} INFO - Task exited with return code 1
[2022-07-29 10:57:27,052] {local_task_job.py:273} INFO - 0 downstream tasks scheduled from follow-on schedule check
