[2022-07-29 10:59:27,145] {taskinstance.py:1159} INFO - Dependencies all met for <TaskInstance: Second_one.first_task scheduled__2022-01-22T00:00:00+00:00 [queued]>
[2022-07-29 10:59:27,161] {taskinstance.py:1159} INFO - Dependencies all met for <TaskInstance: Second_one.first_task scheduled__2022-01-22T00:00:00+00:00 [queued]>
[2022-07-29 10:59:27,161] {taskinstance.py:1356} INFO - 
--------------------------------------------------------------------------------
[2022-07-29 10:59:27,161] {taskinstance.py:1357} INFO - Starting attempt 3 of 6
[2022-07-29 10:59:27,162] {taskinstance.py:1358} INFO - 
--------------------------------------------------------------------------------
[2022-07-29 10:59:27,182] {taskinstance.py:1377} INFO - Executing <Task(BashOperator): first_task> on 2022-01-22 00:00:00+00:00
[2022-07-29 10:59:27,187] {standard_task_runner.py:52} INFO - Started process 3403 to run task
[2022-07-29 10:59:27,190] {standard_task_runner.py:79} INFO - Running: ['***', 'tasks', 'run', 'Second_one', 'first_task', 'scheduled__2022-01-22T00:00:00+00:00', '--job-id', '280', '--raw', '--subdir', 'DAGS_FOLDER/Second_One.py', '--cfg-path', '/tmp/tmpwt3z8vxg', '--error-file', '/tmp/tmp1etwm1wi']
[2022-07-29 10:59:27,191] {standard_task_runner.py:80} INFO - Job 280: Subtask first_task
[2022-07-29 10:59:27,271] {task_command.py:369} INFO - Running <TaskInstance: Second_one.first_task scheduled__2022-01-22T00:00:00+00:00 [running]> on host 9f0f006fc89d
[2022-07-29 10:59:27,370] {taskinstance.py:1571} INFO - Exporting the following env vars:
AIRFLOW_CTX_DAG_OWNER=yosr
AIRFLOW_CTX_DAG_ID=Second_one
AIRFLOW_CTX_TASK_ID=first_task
AIRFLOW_CTX_EXECUTION_DATE=2022-01-22T00:00:00+00:00
AIRFLOW_CTX_TRY_NUMBER=3
AIRFLOW_CTX_DAG_RUN_ID=scheduled__2022-01-22T00:00:00+00:00
[2022-07-29 10:59:27,371] {subprocess.py:62} INFO - Tmp dir root location: 
 /tmp
[2022-07-29 10:59:27,372] {subprocess.py:74} INFO - Running command: ['bash', '-c', "echo hello world, I'm the first task"]
[2022-07-29 10:59:27,386] {subprocess.py:85} INFO - Output:
[2022-07-29 10:59:27,388] {subprocess.py:92} INFO - bash: -c: line 1: unexpected EOF while looking for matching `''
[2022-07-29 10:59:27,388] {subprocess.py:92} INFO - bash: -c: line 2: syntax error: unexpected end of file
[2022-07-29 10:59:27,389] {subprocess.py:96} INFO - Command exited with return code 2
[2022-07-29 10:59:27,409] {taskinstance.py:1889} ERROR - Task failed with exception
Traceback (most recent call last):
  File "/home/airflow/.local/lib/python3.7/site-packages/airflow/operators/bash.py", line 195, in execute
    f'Bash command failed. The command returned a non-zero exit code {result.exit_code}.'
airflow.exceptions.AirflowException: Bash command failed. The command returned a non-zero exit code 2.
[2022-07-29 10:59:27,415] {taskinstance.py:1400} INFO - Marking task as UP_FOR_RETRY. dag_id=Second_one, task_id=first_task, execution_date=20220122T000000, start_date=20220729T105927, end_date=20220729T105927
[2022-07-29 10:59:27,433] {standard_task_runner.py:97} ERROR - Failed to execute job 280 for task first_task (Bash command failed. The command returned a non-zero exit code 2.; 3403)
[2022-07-29 10:59:27,449] {local_task_job.py:156} INFO - Task exited with return code 1
[2022-07-29 10:59:27,510] {local_task_job.py:273} INFO - 0 downstream tasks scheduled from follow-on schedule check
