[2022-07-30 19:14:23,332] {taskinstance.py:1159} INFO - Dependencies all met for <TaskInstance: dag_with_postgres_operator.create_postgres_table scheduled__2022-02-18T00:00:00+00:00 [queued]>
[2022-07-30 19:14:23,352] {taskinstance.py:1159} INFO - Dependencies all met for <TaskInstance: dag_with_postgres_operator.create_postgres_table scheduled__2022-02-18T00:00:00+00:00 [queued]>
[2022-07-30 19:14:23,354] {taskinstance.py:1356} INFO - 
--------------------------------------------------------------------------------
[2022-07-30 19:14:23,355] {taskinstance.py:1357} INFO - Starting attempt 5 of 6
[2022-07-30 19:14:23,356] {taskinstance.py:1358} INFO - 
--------------------------------------------------------------------------------
[2022-07-30 19:14:23,382] {taskinstance.py:1377} INFO - Executing <Task(PostgresOperator): create_postgres_table> on 2022-02-18 00:00:00+00:00
[2022-07-30 19:14:23,391] {standard_task_runner.py:52} INFO - Started process 5535 to run task
[2022-07-30 19:14:23,395] {standard_task_runner.py:79} INFO - Running: ['***', 'tasks', 'run', 'dag_with_postgres_operator', 'create_postgres_table', 'scheduled__2022-02-18T00:00:00+00:00', '--job-id', '366', '--raw', '--subdir', 'DAGS_FOLDER/DAGWithPostgresOperator.py', '--cfg-path', '/tmp/tmpzpfrozz_', '--error-file', '/tmp/tmp5xdt684b']
[2022-07-30 19:14:23,396] {standard_task_runner.py:80} INFO - Job 366: Subtask create_postgres_table
[2022-07-30 19:14:23,563] {task_command.py:369} INFO - Running <TaskInstance: dag_with_postgres_operator.create_postgres_table scheduled__2022-02-18T00:00:00+00:00 [running]> on host 66bf18ec08cc
[2022-07-30 19:14:23,682] {taskinstance.py:1571} INFO - Exporting the following env vars:
AIRFLOW_CTX_DAG_OWNER=yosr
AIRFLOW_CTX_DAG_ID=dag_with_postgres_operator
AIRFLOW_CTX_TASK_ID=create_postgres_table
AIRFLOW_CTX_EXECUTION_DATE=2022-02-18T00:00:00+00:00
AIRFLOW_CTX_TRY_NUMBER=5
AIRFLOW_CTX_DAG_RUN_ID=scheduled__2022-02-18T00:00:00+00:00
[2022-07-30 19:14:23,699] {base.py:68} INFO - Using connection ID 'postgres_localhost' for task execution.
[2022-07-30 19:14:23,701] {taskinstance.py:1889} ERROR - Task failed with exception
Traceback (most recent call last):
  File "/home/airflow/.local/lib/python3.7/site-packages/airflow/providers/postgres/operators/postgres.py", line 92, in execute
    self.hook.run(self.sql, self.autocommit, parameters=self.parameters)
  File "/home/airflow/.local/lib/python3.7/site-packages/airflow/hooks/dbapi.py", line 181, in run
    with closing(self.get_conn()) as conn:
  File "/home/airflow/.local/lib/python3.7/site-packages/airflow/providers/postgres/hooks/postgres.py", line 113, in get_conn
    self.conn = psycopg2.connect(**conn_args)
  File "/home/airflow/.local/lib/python3.7/site-packages/psycopg2/__init__.py", line 122, in connect
    conn = _connect(dsn, connection_factory=connection_factory, **kwasync)
psycopg2.OperationalError: could not translate host name "host.docker.internal " to address: Name or service not known

[2022-07-30 19:14:23,716] {taskinstance.py:1400} INFO - Marking task as UP_FOR_RETRY. dag_id=dag_with_postgres_operator, task_id=create_postgres_table, execution_date=20220218T000000, start_date=20220730T191423, end_date=20220730T191423
[2022-07-30 19:14:23,734] {standard_task_runner.py:97} ERROR - Failed to execute job 366 for task create_postgres_table (could not translate host name "host.docker.internal " to address: Name or service not known
; 5535)
[2022-07-30 19:14:23,749] {local_task_job.py:156} INFO - Task exited with return code 1
[2022-07-30 19:14:23,930] {local_task_job.py:273} INFO - 0 downstream tasks scheduled from follow-on schedule check
[2022-07-31 10:16:38,901] {taskinstance.py:1159} INFO - Dependencies all met for <TaskInstance: dag_with_postgres_operator.create_postgres_table scheduled__2022-02-18T00:00:00+00:00 [queued]>
[2022-07-31 10:16:38,918] {taskinstance.py:1159} INFO - Dependencies all met for <TaskInstance: dag_with_postgres_operator.create_postgres_table scheduled__2022-02-18T00:00:00+00:00 [queued]>
[2022-07-31 10:16:38,919] {taskinstance.py:1356} INFO - 
--------------------------------------------------------------------------------
[2022-07-31 10:16:38,919] {taskinstance.py:1357} INFO - Starting attempt 5 of 6
[2022-07-31 10:16:38,919] {taskinstance.py:1358} INFO - 
--------------------------------------------------------------------------------
[2022-07-31 10:16:38,943] {taskinstance.py:1377} INFO - Executing <Task(PostgresOperator): create_postgres_table> on 2022-02-18 00:00:00+00:00
[2022-07-31 10:16:38,950] {standard_task_runner.py:52} INFO - Started process 2006 to run task
[2022-07-31 10:16:38,955] {standard_task_runner.py:79} INFO - Running: ['***', 'tasks', 'run', 'dag_with_postgres_operator', 'create_postgres_table', 'scheduled__2022-02-18T00:00:00+00:00', '--job-id', '1378', '--raw', '--subdir', 'DAGS_FOLDER/DAGWithPostgresOperator.py', '--cfg-path', '/tmp/tmpnnnl8w6t', '--error-file', '/tmp/tmphb2j3xdf']
[2022-07-31 10:16:38,958] {standard_task_runner.py:80} INFO - Job 1378: Subtask create_postgres_table
[2022-07-31 10:16:39,036] {task_command.py:369} INFO - Running <TaskInstance: dag_with_postgres_operator.create_postgres_table scheduled__2022-02-18T00:00:00+00:00 [running]> on host 66bf18ec08cc
[2022-07-31 10:16:39,134] {taskinstance.py:1571} INFO - Exporting the following env vars:
AIRFLOW_CTX_DAG_OWNER=yosr
AIRFLOW_CTX_DAG_ID=dag_with_postgres_operator
AIRFLOW_CTX_TASK_ID=create_postgres_table
AIRFLOW_CTX_EXECUTION_DATE=2022-02-18T00:00:00+00:00
AIRFLOW_CTX_TRY_NUMBER=5
AIRFLOW_CTX_DAG_RUN_ID=scheduled__2022-02-18T00:00:00+00:00
[2022-07-31 10:16:39,144] {base.py:68} INFO - Using connection ID 'postgres_localhost' for task execution.
[2022-07-31 10:16:39,146] {taskinstance.py:1889} ERROR - Task failed with exception
Traceback (most recent call last):
  File "/home/airflow/.local/lib/python3.7/site-packages/airflow/providers/postgres/operators/postgres.py", line 92, in execute
    self.hook.run(self.sql, self.autocommit, parameters=self.parameters)
  File "/home/airflow/.local/lib/python3.7/site-packages/airflow/hooks/dbapi.py", line 181, in run
    with closing(self.get_conn()) as conn:
  File "/home/airflow/.local/lib/python3.7/site-packages/airflow/providers/postgres/hooks/postgres.py", line 113, in get_conn
    self.conn = psycopg2.connect(**conn_args)
  File "/home/airflow/.local/lib/python3.7/site-packages/psycopg2/__init__.py", line 122, in connect
    conn = _connect(dsn, connection_factory=connection_factory, **kwasync)
psycopg2.OperationalError: could not translate host name "host.docker.local " to address: Name or service not known

[2022-07-31 10:16:39,156] {taskinstance.py:1400} INFO - Marking task as UP_FOR_RETRY. dag_id=dag_with_postgres_operator, task_id=create_postgres_table, execution_date=20220218T000000, start_date=20220731T101638, end_date=20220731T101639
[2022-07-31 10:16:39,171] {standard_task_runner.py:97} ERROR - Failed to execute job 1378 for task create_postgres_table (could not translate host name "host.docker.local " to address: Name or service not known
; 2006)
[2022-07-31 10:16:39,212] {local_task_job.py:156} INFO - Task exited with return code 1
[2022-07-31 10:16:39,371] {local_task_job.py:273} INFO - 0 downstream tasks scheduled from follow-on schedule check
[2022-07-31 14:46:13,535] {taskinstance.py:1159} INFO - Dependencies all met for <TaskInstance: dag_with_postgres_operator.create_postgres_table scheduled__2022-02-18T00:00:00+00:00 [queued]>
[2022-07-31 14:46:13,565] {taskinstance.py:1159} INFO - Dependencies all met for <TaskInstance: dag_with_postgres_operator.create_postgres_table scheduled__2022-02-18T00:00:00+00:00 [queued]>
[2022-07-31 14:46:13,566] {taskinstance.py:1356} INFO - 
--------------------------------------------------------------------------------
[2022-07-31 14:46:13,566] {taskinstance.py:1357} INFO - Starting attempt 5 of 6
[2022-07-31 14:46:13,566] {taskinstance.py:1358} INFO - 
--------------------------------------------------------------------------------
[2022-07-31 14:46:13,596] {taskinstance.py:1377} INFO - Executing <Task(PostgresOperator): create_postgres_table> on 2022-02-18 00:00:00+00:00
[2022-07-31 14:46:13,601] {standard_task_runner.py:52} INFO - Started process 5966 to run task
[2022-07-31 14:46:13,604] {standard_task_runner.py:79} INFO - Running: ['***', 'tasks', 'run', 'dag_with_postgres_operator', 'create_postgres_table', 'scheduled__2022-02-18T00:00:00+00:00', '--job-id', '369', '--raw', '--subdir', 'DAGS_FOLDER/DAGWithPostgresOperator.py', '--cfg-path', '/tmp/tmpl1ltibiv', '--error-file', '/tmp/tmpk4f_9342']
[2022-07-31 14:46:13,604] {standard_task_runner.py:80} INFO - Job 369: Subtask create_postgres_table
[2022-07-31 14:46:13,696] {task_command.py:369} INFO - Running <TaskInstance: dag_with_postgres_operator.create_postgres_table scheduled__2022-02-18T00:00:00+00:00 [running]> on host 4688dd3b7141
[2022-07-31 14:46:13,808] {taskinstance.py:1571} INFO - Exporting the following env vars:
AIRFLOW_CTX_DAG_OWNER=yosr
AIRFLOW_CTX_DAG_ID=dag_with_postgres_operator
AIRFLOW_CTX_TASK_ID=create_postgres_table
AIRFLOW_CTX_EXECUTION_DATE=2022-02-18T00:00:00+00:00
AIRFLOW_CTX_TRY_NUMBER=5
AIRFLOW_CTX_DAG_RUN_ID=scheduled__2022-02-18T00:00:00+00:00
[2022-07-31 14:46:13,824] {base.py:68} INFO - Using connection ID 'postgres_localhost' for task execution.
[2022-07-31 14:46:23,833] {taskinstance.py:1889} ERROR - Task failed with exception
Traceback (most recent call last):
  File "/home/airflow/.local/lib/python3.7/site-packages/airflow/providers/postgres/operators/postgres.py", line 92, in execute
    self.hook.run(self.sql, self.autocommit, parameters=self.parameters)
  File "/home/airflow/.local/lib/python3.7/site-packages/airflow/hooks/dbapi.py", line 181, in run
    with closing(self.get_conn()) as conn:
  File "/home/airflow/.local/lib/python3.7/site-packages/airflow/providers/postgres/hooks/postgres.py", line 113, in get_conn
    self.conn = psycopg2.connect(**conn_args)
  File "/home/airflow/.local/lib/python3.7/site-packages/psycopg2/__init__.py", line 122, in connect
    conn = _connect(dsn, connection_factory=connection_factory, **kwasync)
psycopg2.OperationalError: could not translate host name "host.docker.local" to address: Temporary failure in name resolution

[2022-07-31 14:46:23,850] {taskinstance.py:1400} INFO - Marking task as UP_FOR_RETRY. dag_id=dag_with_postgres_operator, task_id=create_postgres_table, execution_date=20220218T000000, start_date=20220731T144613, end_date=20220731T144623
[2022-07-31 14:46:23,865] {standard_task_runner.py:97} ERROR - Failed to execute job 369 for task create_postgres_table (could not translate host name "host.docker.local" to address: Temporary failure in name resolution
; 5966)
[2022-07-31 14:46:23,898] {local_task_job.py:156} INFO - Task exited with return code 1
[2022-07-31 14:46:23,934] {local_task_job.py:273} INFO - 0 downstream tasks scheduled from follow-on schedule check
