[2022-07-30 19:04:20,386] {taskinstance.py:1159} INFO - Dependencies all met for <TaskInstance: dag_with_postgres_operator.create_postgres_table scheduled__2022-02-13T00:00:00+00:00 [queued]>
[2022-07-30 19:04:20,401] {taskinstance.py:1159} INFO - Dependencies all met for <TaskInstance: dag_with_postgres_operator.create_postgres_table scheduled__2022-02-13T00:00:00+00:00 [queued]>
[2022-07-30 19:04:20,401] {taskinstance.py:1356} INFO - 
--------------------------------------------------------------------------------
[2022-07-30 19:04:20,401] {taskinstance.py:1357} INFO - Starting attempt 3 of 6
[2022-07-30 19:04:20,401] {taskinstance.py:1358} INFO - 
--------------------------------------------------------------------------------
[2022-07-30 19:04:20,423] {taskinstance.py:1377} INFO - Executing <Task(PostgresOperator): create_postgres_table> on 2022-02-13 00:00:00+00:00
[2022-07-30 19:04:20,430] {standard_task_runner.py:52} INFO - Started process 5000 to run task
[2022-07-30 19:04:20,433] {standard_task_runner.py:79} INFO - Running: ['***', 'tasks', 'run', 'dag_with_postgres_operator', 'create_postgres_table', 'scheduled__2022-02-13T00:00:00+00:00', '--job-id', '333', '--raw', '--subdir', 'DAGS_FOLDER/DAGWithPostgresOperator.py', '--cfg-path', '/tmp/tmpi6mre31o', '--error-file', '/tmp/tmpep0tatrv']
[2022-07-30 19:04:20,434] {standard_task_runner.py:80} INFO - Job 333: Subtask create_postgres_table
[2022-07-30 19:04:20,520] {task_command.py:369} INFO - Running <TaskInstance: dag_with_postgres_operator.create_postgres_table scheduled__2022-02-13T00:00:00+00:00 [running]> on host 66bf18ec08cc
[2022-07-30 19:04:20,644] {taskinstance.py:1571} INFO - Exporting the following env vars:
AIRFLOW_CTX_DAG_OWNER=yosr
AIRFLOW_CTX_DAG_ID=dag_with_postgres_operator
AIRFLOW_CTX_TASK_ID=create_postgres_table
AIRFLOW_CTX_EXECUTION_DATE=2022-02-13T00:00:00+00:00
AIRFLOW_CTX_TRY_NUMBER=3
AIRFLOW_CTX_DAG_RUN_ID=scheduled__2022-02-13T00:00:00+00:00
[2022-07-30 19:04:20,661] {base.py:68} INFO - Using connection ID 'postgres_localhost' for task execution.
[2022-07-30 19:04:20,662] {taskinstance.py:1889} ERROR - Task failed with exception
Traceback (most recent call last):
  File "/home/airflow/.local/lib/python3.7/site-packages/airflow/providers/postgres/operators/postgres.py", line 92, in execute
    self.hook.run(self.sql, self.autocommit, parameters=self.parameters)
  File "/home/airflow/.local/lib/python3.7/site-packages/airflow/hooks/dbapi.py", line 181, in run
    with closing(self.get_conn()) as conn:
  File "/home/airflow/.local/lib/python3.7/site-packages/airflow/providers/postgres/hooks/postgres.py", line 113, in get_conn
    self.conn = psycopg2.connect(**conn_args)
  File "/home/airflow/.local/lib/python3.7/site-packages/psycopg2/__init__.py", line 122, in connect
    conn = _connect(dsn, connection_factory=connection_factory, **kwasync)
psycopg2.OperationalError: could not translate host name "host.docker.internal " to address: Name or service not known

[2022-07-30 19:04:20,675] {taskinstance.py:1400} INFO - Marking task as UP_FOR_RETRY. dag_id=dag_with_postgres_operator, task_id=create_postgres_table, execution_date=20220213T000000, start_date=20220730T190420, end_date=20220730T190420
[2022-07-30 19:04:20,707] {standard_task_runner.py:97} ERROR - Failed to execute job 333 for task create_postgres_table (could not translate host name "host.docker.internal " to address: Name or service not known
; 5000)
[2022-07-30 19:04:20,735] {local_task_job.py:156} INFO - Task exited with return code 1
[2022-07-30 19:04:20,791] {local_task_job.py:273} INFO - 0 downstream tasks scheduled from follow-on schedule check
[2022-07-31 10:06:34,958] {taskinstance.py:1159} INFO - Dependencies all met for <TaskInstance: dag_with_postgres_operator.create_postgres_table scheduled__2022-02-13T00:00:00+00:00 [queued]>
[2022-07-31 10:06:34,977] {taskinstance.py:1159} INFO - Dependencies all met for <TaskInstance: dag_with_postgres_operator.create_postgres_table scheduled__2022-02-13T00:00:00+00:00 [queued]>
[2022-07-31 10:06:34,978] {taskinstance.py:1356} INFO - 
--------------------------------------------------------------------------------
[2022-07-31 10:06:34,978] {taskinstance.py:1357} INFO - Starting attempt 3 of 6
[2022-07-31 10:06:34,978] {taskinstance.py:1358} INFO - 
--------------------------------------------------------------------------------
[2022-07-31 10:06:34,996] {taskinstance.py:1377} INFO - Executing <Task(PostgresOperator): create_postgres_table> on 2022-02-13 00:00:00+00:00
[2022-07-31 10:06:35,000] {standard_task_runner.py:52} INFO - Started process 1468 to run task
[2022-07-31 10:06:35,003] {standard_task_runner.py:79} INFO - Running: ['***', 'tasks', 'run', 'dag_with_postgres_operator', 'create_postgres_table', 'scheduled__2022-02-13T00:00:00+00:00', '--job-id', '1339', '--raw', '--subdir', 'DAGS_FOLDER/DAGWithPostgresOperator.py', '--cfg-path', '/tmp/tmplb_fv_2r', '--error-file', '/tmp/tmp5a6ddz56']
[2022-07-31 10:06:35,003] {standard_task_runner.py:80} INFO - Job 1339: Subtask create_postgres_table
[2022-07-31 10:06:35,070] {task_command.py:369} INFO - Running <TaskInstance: dag_with_postgres_operator.create_postgres_table scheduled__2022-02-13T00:00:00+00:00 [running]> on host 66bf18ec08cc
[2022-07-31 10:06:35,158] {taskinstance.py:1571} INFO - Exporting the following env vars:
AIRFLOW_CTX_DAG_OWNER=yosr
AIRFLOW_CTX_DAG_ID=dag_with_postgres_operator
AIRFLOW_CTX_TASK_ID=create_postgres_table
AIRFLOW_CTX_EXECUTION_DATE=2022-02-13T00:00:00+00:00
AIRFLOW_CTX_TRY_NUMBER=3
AIRFLOW_CTX_DAG_RUN_ID=scheduled__2022-02-13T00:00:00+00:00
[2022-07-31 10:06:35,173] {base.py:68} INFO - Using connection ID 'postgres_localhost' for task execution.
[2022-07-31 10:06:35,174] {taskinstance.py:1889} ERROR - Task failed with exception
Traceback (most recent call last):
  File "/home/airflow/.local/lib/python3.7/site-packages/airflow/providers/postgres/operators/postgres.py", line 92, in execute
    self.hook.run(self.sql, self.autocommit, parameters=self.parameters)
  File "/home/airflow/.local/lib/python3.7/site-packages/airflow/hooks/dbapi.py", line 181, in run
    with closing(self.get_conn()) as conn:
  File "/home/airflow/.local/lib/python3.7/site-packages/airflow/providers/postgres/hooks/postgres.py", line 113, in get_conn
    self.conn = psycopg2.connect(**conn_args)
  File "/home/airflow/.local/lib/python3.7/site-packages/psycopg2/__init__.py", line 122, in connect
    conn = _connect(dsn, connection_factory=connection_factory, **kwasync)
psycopg2.OperationalError: could not translate host name "host.docker.local " to address: Name or service not known

[2022-07-31 10:06:35,186] {taskinstance.py:1400} INFO - Marking task as UP_FOR_RETRY. dag_id=dag_with_postgres_operator, task_id=create_postgres_table, execution_date=20220213T000000, start_date=20220731T100634, end_date=20220731T100635
[2022-07-31 10:06:35,202] {standard_task_runner.py:97} ERROR - Failed to execute job 1339 for task create_postgres_table (could not translate host name "host.docker.local " to address: Name or service not known
; 1468)
[2022-07-31 10:06:35,221] {local_task_job.py:156} INFO - Task exited with return code 1
[2022-07-31 10:06:35,274] {local_task_job.py:273} INFO - 0 downstream tasks scheduled from follow-on schedule check
[2022-07-31 14:35:38,487] {taskinstance.py:1159} INFO - Dependencies all met for <TaskInstance: dag_with_postgres_operator.create_postgres_table scheduled__2022-02-13T00:00:00+00:00 [queued]>
[2022-07-31 14:35:38,502] {taskinstance.py:1159} INFO - Dependencies all met for <TaskInstance: dag_with_postgres_operator.create_postgres_table scheduled__2022-02-13T00:00:00+00:00 [queued]>
[2022-07-31 14:35:38,503] {taskinstance.py:1356} INFO - 
--------------------------------------------------------------------------------
[2022-07-31 14:35:38,503] {taskinstance.py:1357} INFO - Starting attempt 3 of 6
[2022-07-31 14:35:38,503] {taskinstance.py:1358} INFO - 
--------------------------------------------------------------------------------
[2022-07-31 14:35:38,526] {taskinstance.py:1377} INFO - Executing <Task(PostgresOperator): create_postgres_table> on 2022-02-13 00:00:00+00:00
[2022-07-31 14:35:38,530] {standard_task_runner.py:52} INFO - Started process 5389 to run task
[2022-07-31 14:35:38,534] {standard_task_runner.py:79} INFO - Running: ['***', 'tasks', 'run', 'dag_with_postgres_operator', 'create_postgres_table', 'scheduled__2022-02-13T00:00:00+00:00', '--job-id', '333', '--raw', '--subdir', 'DAGS_FOLDER/DAGWithPostgresOperator.py', '--cfg-path', '/tmp/tmp7lvb2h8f', '--error-file', '/tmp/tmp5vt3t3qr']
[2022-07-31 14:35:38,534] {standard_task_runner.py:80} INFO - Job 333: Subtask create_postgres_table
[2022-07-31 14:35:38,622] {task_command.py:369} INFO - Running <TaskInstance: dag_with_postgres_operator.create_postgres_table scheduled__2022-02-13T00:00:00+00:00 [running]> on host 4688dd3b7141
[2022-07-31 14:35:38,774] {taskinstance.py:1571} INFO - Exporting the following env vars:
AIRFLOW_CTX_DAG_OWNER=yosr
AIRFLOW_CTX_DAG_ID=dag_with_postgres_operator
AIRFLOW_CTX_TASK_ID=create_postgres_table
AIRFLOW_CTX_EXECUTION_DATE=2022-02-13T00:00:00+00:00
AIRFLOW_CTX_TRY_NUMBER=3
AIRFLOW_CTX_DAG_RUN_ID=scheduled__2022-02-13T00:00:00+00:00
[2022-07-31 14:35:38,797] {base.py:68} INFO - Using connection ID 'postgres_localhost' for task execution.
[2022-07-31 14:35:53,811] {taskinstance.py:1889} ERROR - Task failed with exception
Traceback (most recent call last):
  File "/home/airflow/.local/lib/python3.7/site-packages/airflow/providers/postgres/operators/postgres.py", line 92, in execute
    self.hook.run(self.sql, self.autocommit, parameters=self.parameters)
  File "/home/airflow/.local/lib/python3.7/site-packages/airflow/hooks/dbapi.py", line 181, in run
    with closing(self.get_conn()) as conn:
  File "/home/airflow/.local/lib/python3.7/site-packages/airflow/providers/postgres/hooks/postgres.py", line 113, in get_conn
    self.conn = psycopg2.connect(**conn_args)
  File "/home/airflow/.local/lib/python3.7/site-packages/psycopg2/__init__.py", line 122, in connect
    conn = _connect(dsn, connection_factory=connection_factory, **kwasync)
psycopg2.OperationalError: could not translate host name "host.docker.local" to address: Temporary failure in name resolution

[2022-07-31 14:35:53,827] {taskinstance.py:1400} INFO - Marking task as UP_FOR_RETRY. dag_id=dag_with_postgres_operator, task_id=create_postgres_table, execution_date=20220213T000000, start_date=20220731T143538, end_date=20220731T143553
[2022-07-31 14:35:53,844] {standard_task_runner.py:97} ERROR - Failed to execute job 333 for task create_postgres_table (could not translate host name "host.docker.local" to address: Temporary failure in name resolution
; 5389)
[2022-07-31 14:35:53,860] {local_task_job.py:156} INFO - Task exited with return code 1
[2022-07-31 14:35:54,099] {local_task_job.py:273} INFO - 0 downstream tasks scheduled from follow-on schedule check
