[2022-07-30 18:54:04,759] {taskinstance.py:1159} INFO - Dependencies all met for <TaskInstance: dag_with_postgres_operator.create_postgres_table scheduled__2022-01-24T00:00:00+00:00 [queued]>
[2022-07-30 18:54:04,779] {taskinstance.py:1159} INFO - Dependencies all met for <TaskInstance: dag_with_postgres_operator.create_postgres_table scheduled__2022-01-24T00:00:00+00:00 [queued]>
[2022-07-30 18:54:04,779] {taskinstance.py:1356} INFO - 
--------------------------------------------------------------------------------
[2022-07-30 18:54:04,779] {taskinstance.py:1357} INFO - Starting attempt 6 of 6
[2022-07-30 18:54:04,779] {taskinstance.py:1358} INFO - 
--------------------------------------------------------------------------------
[2022-07-30 18:54:04,804] {taskinstance.py:1377} INFO - Executing <Task(PostgresOperator): create_postgres_table> on 2022-01-24 00:00:00+00:00
[2022-07-30 18:54:04,810] {standard_task_runner.py:52} INFO - Started process 4420 to run task
[2022-07-30 18:54:04,815] {standard_task_runner.py:79} INFO - Running: ['***', 'tasks', 'run', 'dag_with_postgres_operator', 'create_postgres_table', 'scheduled__2022-01-24T00:00:00+00:00', '--job-id', '280', '--raw', '--subdir', 'DAGS_FOLDER/DAGWithPostgresOperator.py', '--cfg-path', '/tmp/tmprusvuwrr', '--error-file', '/tmp/tmphn7g9t3o']
[2022-07-30 18:54:04,815] {standard_task_runner.py:80} INFO - Job 280: Subtask create_postgres_table
[2022-07-30 18:54:04,901] {task_command.py:369} INFO - Running <TaskInstance: dag_with_postgres_operator.create_postgres_table scheduled__2022-01-24T00:00:00+00:00 [running]> on host 66bf18ec08cc
[2022-07-30 18:54:05,009] {taskinstance.py:1571} INFO - Exporting the following env vars:
AIRFLOW_CTX_DAG_OWNER=yosr
AIRFLOW_CTX_DAG_ID=dag_with_postgres_operator
AIRFLOW_CTX_TASK_ID=create_postgres_table
AIRFLOW_CTX_EXECUTION_DATE=2022-01-24T00:00:00+00:00
AIRFLOW_CTX_TRY_NUMBER=6
AIRFLOW_CTX_DAG_RUN_ID=scheduled__2022-01-24T00:00:00+00:00
[2022-07-30 18:54:05,024] {base.py:68} INFO - Using connection ID 'postgres_localhost' for task execution.
[2022-07-30 18:54:05,025] {taskinstance.py:1889} ERROR - Task failed with exception
Traceback (most recent call last):
  File "/home/airflow/.local/lib/python3.7/site-packages/airflow/providers/postgres/operators/postgres.py", line 92, in execute
    self.hook.run(self.sql, self.autocommit, parameters=self.parameters)
  File "/home/airflow/.local/lib/python3.7/site-packages/airflow/hooks/dbapi.py", line 181, in run
    with closing(self.get_conn()) as conn:
  File "/home/airflow/.local/lib/python3.7/site-packages/airflow/providers/postgres/hooks/postgres.py", line 113, in get_conn
    self.conn = psycopg2.connect(**conn_args)
  File "/home/airflow/.local/lib/python3.7/site-packages/psycopg2/__init__.py", line 122, in connect
    conn = _connect(dsn, connection_factory=connection_factory, **kwasync)
psycopg2.OperationalError: could not translate host name "host.docker.internal " to address: Name or service not known

[2022-07-30 18:54:05,040] {taskinstance.py:1400} INFO - Marking task as FAILED. dag_id=dag_with_postgres_operator, task_id=create_postgres_table, execution_date=20220124T000000, start_date=20220730T185404, end_date=20220730T185405
[2022-07-30 18:54:05,057] {standard_task_runner.py:97} ERROR - Failed to execute job 280 for task create_postgres_table (could not translate host name "host.docker.internal " to address: Name or service not known
; 4420)
[2022-07-30 18:54:05,073] {local_task_job.py:156} INFO - Task exited with return code 1
[2022-07-30 18:54:05,147] {local_task_job.py:273} INFO - 0 downstream tasks scheduled from follow-on schedule check
[2022-07-31 09:56:12,786] {taskinstance.py:1159} INFO - Dependencies all met for <TaskInstance: dag_with_postgres_operator.create_postgres_table scheduled__2022-01-24T00:00:00+00:00 [queued]>
[2022-07-31 09:56:12,819] {taskinstance.py:1159} INFO - Dependencies all met for <TaskInstance: dag_with_postgres_operator.create_postgres_table scheduled__2022-01-24T00:00:00+00:00 [queued]>
[2022-07-31 09:56:12,819] {taskinstance.py:1356} INFO - 
--------------------------------------------------------------------------------
[2022-07-31 09:56:12,819] {taskinstance.py:1357} INFO - Starting attempt 6 of 6
[2022-07-31 09:56:12,819] {taskinstance.py:1358} INFO - 
--------------------------------------------------------------------------------
[2022-07-31 09:56:12,863] {taskinstance.py:1377} INFO - Executing <Task(PostgresOperator): create_postgres_table> on 2022-01-24 00:00:00+00:00
[2022-07-31 09:56:12,889] {standard_task_runner.py:52} INFO - Started process 904 to run task
[2022-07-31 09:56:12,925] {standard_task_runner.py:79} INFO - Running: ['***', 'tasks', 'run', 'dag_with_postgres_operator', 'create_postgres_table', 'scheduled__2022-01-24T00:00:00+00:00', '--job-id', '1297', '--raw', '--subdir', 'DAGS_FOLDER/DAGWithPostgresOperator.py', '--cfg-path', '/tmp/tmpwak_bljk', '--error-file', '/tmp/tmp283_xpx4']
[2022-07-31 09:56:12,926] {standard_task_runner.py:80} INFO - Job 1297: Subtask create_postgres_table
[2022-07-31 09:56:13,268] {task_command.py:369} INFO - Running <TaskInstance: dag_with_postgres_operator.create_postgres_table scheduled__2022-01-24T00:00:00+00:00 [running]> on host 66bf18ec08cc
[2022-07-31 09:56:13,798] {taskinstance.py:1571} INFO - Exporting the following env vars:
AIRFLOW_CTX_DAG_OWNER=yosr
AIRFLOW_CTX_DAG_ID=dag_with_postgres_operator
AIRFLOW_CTX_TASK_ID=create_postgres_table
AIRFLOW_CTX_EXECUTION_DATE=2022-01-24T00:00:00+00:00
AIRFLOW_CTX_TRY_NUMBER=6
AIRFLOW_CTX_DAG_RUN_ID=scheduled__2022-01-24T00:00:00+00:00
[2022-07-31 09:56:13,831] {base.py:68} INFO - Using connection ID 'postgres_localhost' for task execution.
[2022-07-31 09:56:13,837] {taskinstance.py:1889} ERROR - Task failed with exception
Traceback (most recent call last):
  File "/home/airflow/.local/lib/python3.7/site-packages/airflow/providers/postgres/operators/postgres.py", line 92, in execute
    self.hook.run(self.sql, self.autocommit, parameters=self.parameters)
  File "/home/airflow/.local/lib/python3.7/site-packages/airflow/hooks/dbapi.py", line 181, in run
    with closing(self.get_conn()) as conn:
  File "/home/airflow/.local/lib/python3.7/site-packages/airflow/providers/postgres/hooks/postgres.py", line 113, in get_conn
    self.conn = psycopg2.connect(**conn_args)
  File "/home/airflow/.local/lib/python3.7/site-packages/psycopg2/__init__.py", line 122, in connect
    conn = _connect(dsn, connection_factory=connection_factory, **kwasync)
psycopg2.OperationalError: could not translate host name "host.docker.local " to address: Name or service not known

[2022-07-31 09:56:13,884] {taskinstance.py:1400} INFO - Marking task as FAILED. dag_id=dag_with_postgres_operator, task_id=create_postgres_table, execution_date=20220124T000000, start_date=20220731T095612, end_date=20220731T095613
[2022-07-31 09:56:13,927] {standard_task_runner.py:97} ERROR - Failed to execute job 1297 for task create_postgres_table (could not translate host name "host.docker.local " to address: Name or service not known
; 904)
[2022-07-31 09:56:13,984] {local_task_job.py:156} INFO - Task exited with return code 1
[2022-07-31 09:56:14,345] {local_task_job.py:273} INFO - 0 downstream tasks scheduled from follow-on schedule check
[2022-07-31 14:25:28,837] {taskinstance.py:1159} INFO - Dependencies all met for <TaskInstance: dag_with_postgres_operator.create_postgres_table scheduled__2022-01-24T00:00:00+00:00 [queued]>
[2022-07-31 14:25:28,873] {taskinstance.py:1159} INFO - Dependencies all met for <TaskInstance: dag_with_postgres_operator.create_postgres_table scheduled__2022-01-24T00:00:00+00:00 [queued]>
[2022-07-31 14:25:28,875] {taskinstance.py:1356} INFO - 
--------------------------------------------------------------------------------
[2022-07-31 14:25:28,876] {taskinstance.py:1357} INFO - Starting attempt 6 of 6
[2022-07-31 14:25:28,877] {taskinstance.py:1358} INFO - 
--------------------------------------------------------------------------------
[2022-07-31 14:25:28,920] {taskinstance.py:1377} INFO - Executing <Task(PostgresOperator): create_postgres_table> on 2022-01-24 00:00:00+00:00
[2022-07-31 14:25:28,951] {standard_task_runner.py:52} INFO - Started process 4810 to run task
[2022-07-31 14:25:28,963] {standard_task_runner.py:79} INFO - Running: ['***', 'tasks', 'run', 'dag_with_postgres_operator', 'create_postgres_table', 'scheduled__2022-01-24T00:00:00+00:00', '--job-id', '275', '--raw', '--subdir', 'DAGS_FOLDER/DAGWithPostgresOperator.py', '--cfg-path', '/tmp/tmpit1oon2l', '--error-file', '/tmp/tmpuierr0jv']
[2022-07-31 14:25:28,967] {standard_task_runner.py:80} INFO - Job 275: Subtask create_postgres_table
[2022-07-31 14:25:29,166] {task_command.py:369} INFO - Running <TaskInstance: dag_with_postgres_operator.create_postgres_table scheduled__2022-01-24T00:00:00+00:00 [running]> on host 4688dd3b7141
[2022-07-31 14:25:29,458] {taskinstance.py:1571} INFO - Exporting the following env vars:
AIRFLOW_CTX_DAG_OWNER=yosr
AIRFLOW_CTX_DAG_ID=dag_with_postgres_operator
AIRFLOW_CTX_TASK_ID=create_postgres_table
AIRFLOW_CTX_EXECUTION_DATE=2022-01-24T00:00:00+00:00
AIRFLOW_CTX_TRY_NUMBER=6
AIRFLOW_CTX_DAG_RUN_ID=scheduled__2022-01-24T00:00:00+00:00
[2022-07-31 14:25:29,861] {taskinstance.py:1889} ERROR - Task failed with exception
Traceback (most recent call last):
  File "/home/airflow/.local/lib/python3.7/site-packages/airflow/providers/postgres/operators/postgres.py", line 92, in execute
    self.hook.run(self.sql, self.autocommit, parameters=self.parameters)
  File "/home/airflow/.local/lib/python3.7/site-packages/airflow/hooks/dbapi.py", line 181, in run
    with closing(self.get_conn()) as conn:
  File "/home/airflow/.local/lib/python3.7/site-packages/airflow/providers/postgres/hooks/postgres.py", line 86, in get_conn
    conn = deepcopy(self.connection or self.get_connection(conn_id))
  File "/home/airflow/.local/lib/python3.7/site-packages/airflow/hooks/base.py", line 67, in get_connection
    conn = Connection.get_connection_from_secrets(conn_id)
  File "/home/airflow/.local/lib/python3.7/site-packages/airflow/models/connection.py", line 430, in get_connection_from_secrets
    raise AirflowNotFoundException(f"The conn_id `{conn_id}` isn't defined")
airflow.exceptions.AirflowNotFoundException: The conn_id `postgres_localhost` isn't defined
[2022-07-31 14:25:29,873] {taskinstance.py:1400} INFO - Marking task as FAILED. dag_id=dag_with_postgres_operator, task_id=create_postgres_table, execution_date=20220124T000000, start_date=20220731T142528, end_date=20220731T142529
[2022-07-31 14:25:29,923] {standard_task_runner.py:97} ERROR - Failed to execute job 275 for task create_postgres_table (The conn_id `postgres_localhost` isn't defined; 4810)
[2022-07-31 14:25:29,989] {local_task_job.py:156} INFO - Task exited with return code 1
[2022-07-31 14:25:30,140] {local_task_job.py:273} INFO - 0 downstream tasks scheduled from follow-on schedule check
