[2022-07-30 18:23:52,237] {taskinstance.py:1159} INFO - Dependencies all met for <TaskInstance: dag_with_postgres_operator.create_postgres_table scheduled__2022-01-09T00:00:00+00:00 [queued]>
[2022-07-30 18:23:52,257] {taskinstance.py:1159} INFO - Dependencies all met for <TaskInstance: dag_with_postgres_operator.create_postgres_table scheduled__2022-01-09T00:00:00+00:00 [queued]>
[2022-07-30 18:23:52,257] {taskinstance.py:1356} INFO - 
--------------------------------------------------------------------------------
[2022-07-30 18:23:52,257] {taskinstance.py:1357} INFO - Starting attempt 5 of 6
[2022-07-30 18:23:52,257] {taskinstance.py:1358} INFO - 
--------------------------------------------------------------------------------
[2022-07-30 18:23:52,277] {taskinstance.py:1377} INFO - Executing <Task(PostgresOperator): create_postgres_table> on 2022-01-09 00:00:00+00:00
[2022-07-30 18:23:52,284] {standard_task_runner.py:52} INFO - Started process 2790 to run task
[2022-07-30 18:23:52,289] {standard_task_runner.py:79} INFO - Running: ['***', 'tasks', 'run', 'dag_with_postgres_operator', 'create_postgres_table', 'scheduled__2022-01-09T00:00:00+00:00', '--job-id', '165', '--raw', '--subdir', 'DAGS_FOLDER/DAGWithPostgresOperator.py', '--cfg-path', '/tmp/tmpubn9armq', '--error-file', '/tmp/tmp7qepope7']
[2022-07-30 18:23:52,289] {standard_task_runner.py:80} INFO - Job 165: Subtask create_postgres_table
[2022-07-30 18:23:52,380] {task_command.py:369} INFO - Running <TaskInstance: dag_with_postgres_operator.create_postgres_table scheduled__2022-01-09T00:00:00+00:00 [running]> on host 66bf18ec08cc
[2022-07-30 18:23:52,503] {taskinstance.py:1571} INFO - Exporting the following env vars:
AIRFLOW_CTX_DAG_OWNER=yosr
AIRFLOW_CTX_DAG_ID=dag_with_postgres_operator
AIRFLOW_CTX_TASK_ID=create_postgres_table
AIRFLOW_CTX_EXECUTION_DATE=2022-01-09T00:00:00+00:00
AIRFLOW_CTX_TRY_NUMBER=5
AIRFLOW_CTX_DAG_RUN_ID=scheduled__2022-01-09T00:00:00+00:00
[2022-07-30 18:23:52,519] {base.py:68} INFO - Using connection ID 'postgres_localhost' for task execution.
[2022-07-30 18:23:52,520] {taskinstance.py:1889} ERROR - Task failed with exception
Traceback (most recent call last):
  File "/home/airflow/.local/lib/python3.7/site-packages/airflow/providers/postgres/operators/postgres.py", line 92, in execute
    self.hook.run(self.sql, self.autocommit, parameters=self.parameters)
  File "/home/airflow/.local/lib/python3.7/site-packages/airflow/hooks/dbapi.py", line 181, in run
    with closing(self.get_conn()) as conn:
  File "/home/airflow/.local/lib/python3.7/site-packages/airflow/providers/postgres/hooks/postgres.py", line 113, in get_conn
    self.conn = psycopg2.connect(**conn_args)
  File "/home/airflow/.local/lib/python3.7/site-packages/psycopg2/__init__.py", line 122, in connect
    conn = _connect(dsn, connection_factory=connection_factory, **kwasync)
psycopg2.OperationalError: could not translate host name "host.docker.internal " to address: Name or service not known

[2022-07-30 18:23:52,536] {taskinstance.py:1400} INFO - Marking task as UP_FOR_RETRY. dag_id=dag_with_postgres_operator, task_id=create_postgres_table, execution_date=20220109T000000, start_date=20220730T182352, end_date=20220730T182352
[2022-07-30 18:23:52,558] {standard_task_runner.py:97} ERROR - Failed to execute job 165 for task create_postgres_table (could not translate host name "host.docker.internal " to address: Name or service not known
; 2790)
[2022-07-30 18:23:52,590] {local_task_job.py:156} INFO - Task exited with return code 1
[2022-07-30 18:23:52,671] {local_task_job.py:273} INFO - 0 downstream tasks scheduled from follow-on schedule check
[2022-07-31 00:30:05,233] {taskinstance.py:1159} INFO - Dependencies all met for <TaskInstance: dag_with_postgres_operator.create_postgres_table scheduled__2022-01-09T00:00:00+00:00 [queued]>
[2022-07-31 00:30:05,271] {taskinstance.py:1159} INFO - Dependencies all met for <TaskInstance: dag_with_postgres_operator.create_postgres_table scheduled__2022-01-09T00:00:00+00:00 [queued]>
[2022-07-31 00:30:05,272] {taskinstance.py:1356} INFO - 
--------------------------------------------------------------------------------
[2022-07-31 00:30:05,272] {taskinstance.py:1357} INFO - Starting attempt 5 of 6
[2022-07-31 00:30:05,272] {taskinstance.py:1358} INFO - 
--------------------------------------------------------------------------------
[2022-07-31 00:30:05,296] {taskinstance.py:1377} INFO - Executing <Task(PostgresOperator): create_postgres_table> on 2022-01-09 00:00:00+00:00
[2022-07-31 00:30:05,304] {standard_task_runner.py:52} INFO - Started process 6711 to run task
[2022-07-31 00:30:05,310] {standard_task_runner.py:79} INFO - Running: ['***', 'tasks', 'run', 'dag_with_postgres_operator', 'create_postgres_table', 'scheduled__2022-01-09T00:00:00+00:00', '--job-id', '1176', '--raw', '--subdir', 'DAGS_FOLDER/DAGWithPostgresOperator.py', '--cfg-path', '/tmp/tmpli11znx6', '--error-file', '/tmp/tmp6yzelsk9']
[2022-07-31 00:30:05,311] {standard_task_runner.py:80} INFO - Job 1176: Subtask create_postgres_table
[2022-07-31 00:30:05,389] {task_command.py:369} INFO - Running <TaskInstance: dag_with_postgres_operator.create_postgres_table scheduled__2022-01-09T00:00:00+00:00 [running]> on host 66bf18ec08cc
[2022-07-31 00:30:05,507] {taskinstance.py:1571} INFO - Exporting the following env vars:
AIRFLOW_CTX_DAG_OWNER=yosr
AIRFLOW_CTX_DAG_ID=dag_with_postgres_operator
AIRFLOW_CTX_TASK_ID=create_postgres_table
AIRFLOW_CTX_EXECUTION_DATE=2022-01-09T00:00:00+00:00
AIRFLOW_CTX_TRY_NUMBER=5
AIRFLOW_CTX_DAG_RUN_ID=scheduled__2022-01-09T00:00:00+00:00
[2022-07-31 00:30:05,527] {base.py:68} INFO - Using connection ID 'postgres_localhost' for task execution.
[2022-07-31 00:30:05,528] {taskinstance.py:1889} ERROR - Task failed with exception
Traceback (most recent call last):
  File "/home/airflow/.local/lib/python3.7/site-packages/airflow/providers/postgres/operators/postgres.py", line 92, in execute
    self.hook.run(self.sql, self.autocommit, parameters=self.parameters)
  File "/home/airflow/.local/lib/python3.7/site-packages/airflow/hooks/dbapi.py", line 181, in run
    with closing(self.get_conn()) as conn:
  File "/home/airflow/.local/lib/python3.7/site-packages/airflow/providers/postgres/hooks/postgres.py", line 113, in get_conn
    self.conn = psycopg2.connect(**conn_args)
  File "/home/airflow/.local/lib/python3.7/site-packages/psycopg2/__init__.py", line 122, in connect
    conn = _connect(dsn, connection_factory=connection_factory, **kwasync)
psycopg2.OperationalError: could not translate host name "host.docker.local " to address: Name or service not known

[2022-07-31 00:30:05,541] {taskinstance.py:1400} INFO - Marking task as UP_FOR_RETRY. dag_id=dag_with_postgres_operator, task_id=create_postgres_table, execution_date=20220109T000000, start_date=20220731T003005, end_date=20220731T003005
[2022-07-31 00:30:05,557] {standard_task_runner.py:97} ERROR - Failed to execute job 1176 for task create_postgres_table (could not translate host name "host.docker.local " to address: Name or service not known
; 6711)
[2022-07-31 00:30:05,570] {local_task_job.py:156} INFO - Task exited with return code 1
[2022-07-31 00:30:05,636] {local_task_job.py:273} INFO - 0 downstream tasks scheduled from follow-on schedule check
[2022-07-31 11:24:20,734] {taskinstance.py:1159} INFO - Dependencies all met for <TaskInstance: dag_with_postgres_operator.create_postgres_table scheduled__2022-01-09T00:00:00+00:00 [queued]>
[2022-07-31 11:24:20,754] {taskinstance.py:1159} INFO - Dependencies all met for <TaskInstance: dag_with_postgres_operator.create_postgres_table scheduled__2022-01-09T00:00:00+00:00 [queued]>
[2022-07-31 11:24:20,754] {taskinstance.py:1356} INFO - 
--------------------------------------------------------------------------------
[2022-07-31 11:24:20,755] {taskinstance.py:1357} INFO - Starting attempt 5 of 6
[2022-07-31 11:24:20,755] {taskinstance.py:1358} INFO - 
--------------------------------------------------------------------------------
[2022-07-31 11:24:20,784] {taskinstance.py:1377} INFO - Executing <Task(PostgresOperator): create_postgres_table> on 2022-01-09 00:00:00+00:00
[2022-07-31 11:24:20,790] {standard_task_runner.py:52} INFO - Started process 5633 to run task
[2022-07-31 11:24:20,795] {standard_task_runner.py:79} INFO - Running: ['***', 'tasks', 'run', 'dag_with_postgres_operator', 'create_postgres_table', 'scheduled__2022-01-09T00:00:00+00:00', '--job-id', '1634', '--raw', '--subdir', 'DAGS_FOLDER/DAGWithPostgresOperator.py', '--cfg-path', '/tmp/tmpmzgwrgsy', '--error-file', '/tmp/tmps9pex4gu']
[2022-07-31 11:24:20,796] {standard_task_runner.py:80} INFO - Job 1634: Subtask create_postgres_table
[2022-07-31 11:24:20,882] {task_command.py:369} INFO - Running <TaskInstance: dag_with_postgres_operator.create_postgres_table scheduled__2022-01-09T00:00:00+00:00 [running]> on host 66bf18ec08cc
[2022-07-31 11:24:21,022] {taskinstance.py:1571} INFO - Exporting the following env vars:
AIRFLOW_CTX_DAG_OWNER=yosr
AIRFLOW_CTX_DAG_ID=dag_with_postgres_operator
AIRFLOW_CTX_TASK_ID=create_postgres_table
AIRFLOW_CTX_EXECUTION_DATE=2022-01-09T00:00:00+00:00
AIRFLOW_CTX_TRY_NUMBER=5
AIRFLOW_CTX_DAG_RUN_ID=scheduled__2022-01-09T00:00:00+00:00
[2022-07-31 11:24:21,041] {base.py:68} INFO - Using connection ID 'postgres_localhost' for task execution.
[2022-07-31 11:24:46,065] {taskinstance.py:1889} ERROR - Task failed with exception
Traceback (most recent call last):
  File "/home/airflow/.local/lib/python3.7/site-packages/airflow/providers/postgres/operators/postgres.py", line 92, in execute
    self.hook.run(self.sql, self.autocommit, parameters=self.parameters)
  File "/home/airflow/.local/lib/python3.7/site-packages/airflow/hooks/dbapi.py", line 181, in run
    with closing(self.get_conn()) as conn:
  File "/home/airflow/.local/lib/python3.7/site-packages/airflow/providers/postgres/hooks/postgres.py", line 113, in get_conn
    self.conn = psycopg2.connect(**conn_args)
  File "/home/airflow/.local/lib/python3.7/site-packages/psycopg2/__init__.py", line 122, in connect
    conn = _connect(dsn, connection_factory=connection_factory, **kwasync)
psycopg2.OperationalError: could not translate host name "host.docker.internal" to address: Temporary failure in name resolution

[2022-07-31 11:24:46,081] {taskinstance.py:1400} INFO - Marking task as UP_FOR_RETRY. dag_id=dag_with_postgres_operator, task_id=create_postgres_table, execution_date=20220109T000000, start_date=20220731T112420, end_date=20220731T112446
[2022-07-31 11:24:46,107] {standard_task_runner.py:97} ERROR - Failed to execute job 1634 for task create_postgres_table (could not translate host name "host.docker.internal" to address: Temporary failure in name resolution
; 5633)
[2022-07-31 11:24:46,120] {local_task_job.py:156} INFO - Task exited with return code 1
[2022-07-31 11:24:46,172] {local_task_job.py:273} INFO - 0 downstream tasks scheduled from follow-on schedule check
[2022-07-31 13:55:12,741] {taskinstance.py:1159} INFO - Dependencies all met for <TaskInstance: dag_with_postgres_operator.create_postgres_table scheduled__2022-01-09T00:00:00+00:00 [queued]>
[2022-07-31 13:55:12,766] {taskinstance.py:1159} INFO - Dependencies all met for <TaskInstance: dag_with_postgres_operator.create_postgres_table scheduled__2022-01-09T00:00:00+00:00 [queued]>
[2022-07-31 13:55:12,767] {taskinstance.py:1356} INFO - 
--------------------------------------------------------------------------------
[2022-07-31 13:55:12,768] {taskinstance.py:1357} INFO - Starting attempt 5 of 6
[2022-07-31 13:55:12,768] {taskinstance.py:1358} INFO - 
--------------------------------------------------------------------------------
[2022-07-31 13:55:12,796] {taskinstance.py:1377} INFO - Executing <Task(PostgresOperator): create_postgres_table> on 2022-01-09 00:00:00+00:00
[2022-07-31 13:55:12,802] {standard_task_runner.py:52} INFO - Started process 3200 to run task
[2022-07-31 13:55:12,806] {standard_task_runner.py:79} INFO - Running: ['***', 'tasks', 'run', 'dag_with_postgres_operator', 'create_postgres_table', 'scheduled__2022-01-09T00:00:00+00:00', '--job-id', '172', '--raw', '--subdir', 'DAGS_FOLDER/DAGWithPostgresOperator.py', '--cfg-path', '/tmp/tmpu_pmc6_4', '--error-file', '/tmp/tmpef3emf9z']
[2022-07-31 13:55:12,807] {standard_task_runner.py:80} INFO - Job 172: Subtask create_postgres_table
[2022-07-31 13:55:12,899] {task_command.py:369} INFO - Running <TaskInstance: dag_with_postgres_operator.create_postgres_table scheduled__2022-01-09T00:00:00+00:00 [running]> on host 4688dd3b7141
[2022-07-31 13:55:13,008] {taskinstance.py:1571} INFO - Exporting the following env vars:
AIRFLOW_CTX_DAG_OWNER=yosr
AIRFLOW_CTX_DAG_ID=dag_with_postgres_operator
AIRFLOW_CTX_TASK_ID=create_postgres_table
AIRFLOW_CTX_EXECUTION_DATE=2022-01-09T00:00:00+00:00
AIRFLOW_CTX_TRY_NUMBER=5
AIRFLOW_CTX_DAG_RUN_ID=scheduled__2022-01-09T00:00:00+00:00
[2022-07-31 13:55:13,072] {taskinstance.py:1889} ERROR - Task failed with exception
Traceback (most recent call last):
  File "/home/airflow/.local/lib/python3.7/site-packages/airflow/providers/postgres/operators/postgres.py", line 92, in execute
    self.hook.run(self.sql, self.autocommit, parameters=self.parameters)
  File "/home/airflow/.local/lib/python3.7/site-packages/airflow/hooks/dbapi.py", line 181, in run
    with closing(self.get_conn()) as conn:
  File "/home/airflow/.local/lib/python3.7/site-packages/airflow/providers/postgres/hooks/postgres.py", line 86, in get_conn
    conn = deepcopy(self.connection or self.get_connection(conn_id))
  File "/home/airflow/.local/lib/python3.7/site-packages/airflow/hooks/base.py", line 67, in get_connection
    conn = Connection.get_connection_from_secrets(conn_id)
  File "/home/airflow/.local/lib/python3.7/site-packages/airflow/models/connection.py", line 430, in get_connection_from_secrets
    raise AirflowNotFoundException(f"The conn_id `{conn_id}` isn't defined")
airflow.exceptions.AirflowNotFoundException: The conn_id `postgres_localhost` isn't defined
[2022-07-31 13:55:13,080] {taskinstance.py:1400} INFO - Marking task as UP_FOR_RETRY. dag_id=dag_with_postgres_operator, task_id=create_postgres_table, execution_date=20220109T000000, start_date=20220731T135512, end_date=20220731T135513
[2022-07-31 13:55:13,099] {standard_task_runner.py:97} ERROR - Failed to execute job 172 for task create_postgres_table (The conn_id `postgres_localhost` isn't defined; 3200)
[2022-07-31 13:55:13,148] {local_task_job.py:156} INFO - Task exited with return code 1
[2022-07-31 13:55:13,214] {local_task_job.py:273} INFO - 0 downstream tasks scheduled from follow-on schedule check
