[2022-07-30 18:28:53,616] {taskinstance.py:1159} INFO - Dependencies all met for <TaskInstance: dag_with_postgres_operator.create_postgres_table scheduled__2022-01-09T00:00:00+00:00 [queued]>
[2022-07-30 18:28:53,636] {taskinstance.py:1159} INFO - Dependencies all met for <TaskInstance: dag_with_postgres_operator.create_postgres_table scheduled__2022-01-09T00:00:00+00:00 [queued]>
[2022-07-30 18:28:53,637] {taskinstance.py:1356} INFO - 
--------------------------------------------------------------------------------
[2022-07-30 18:28:53,637] {taskinstance.py:1357} INFO - Starting attempt 6 of 6
[2022-07-30 18:28:53,637] {taskinstance.py:1358} INFO - 
--------------------------------------------------------------------------------
[2022-07-30 18:28:53,662] {taskinstance.py:1377} INFO - Executing <Task(PostgresOperator): create_postgres_table> on 2022-01-09 00:00:00+00:00
[2022-07-30 18:28:53,669] {standard_task_runner.py:52} INFO - Started process 3058 to run task
[2022-07-30 18:28:53,676] {standard_task_runner.py:79} INFO - Running: ['***', 'tasks', 'run', 'dag_with_postgres_operator', 'create_postgres_table', 'scheduled__2022-01-09T00:00:00+00:00', '--job-id', '184', '--raw', '--subdir', 'DAGS_FOLDER/DAGWithPostgresOperator.py', '--cfg-path', '/tmp/tmppxbxnv3w', '--error-file', '/tmp/tmph5e319hk']
[2022-07-30 18:28:53,676] {standard_task_runner.py:80} INFO - Job 184: Subtask create_postgres_table
[2022-07-30 18:28:53,773] {task_command.py:369} INFO - Running <TaskInstance: dag_with_postgres_operator.create_postgres_table scheduled__2022-01-09T00:00:00+00:00 [running]> on host 66bf18ec08cc
[2022-07-30 18:28:53,898] {taskinstance.py:1571} INFO - Exporting the following env vars:
AIRFLOW_CTX_DAG_OWNER=yosr
AIRFLOW_CTX_DAG_ID=dag_with_postgres_operator
AIRFLOW_CTX_TASK_ID=create_postgres_table
AIRFLOW_CTX_EXECUTION_DATE=2022-01-09T00:00:00+00:00
AIRFLOW_CTX_TRY_NUMBER=6
AIRFLOW_CTX_DAG_RUN_ID=scheduled__2022-01-09T00:00:00+00:00
[2022-07-30 18:28:53,923] {base.py:68} INFO - Using connection ID 'postgres_localhost' for task execution.
[2022-07-30 18:28:53,924] {taskinstance.py:1889} ERROR - Task failed with exception
Traceback (most recent call last):
  File "/home/airflow/.local/lib/python3.7/site-packages/airflow/providers/postgres/operators/postgres.py", line 92, in execute
    self.hook.run(self.sql, self.autocommit, parameters=self.parameters)
  File "/home/airflow/.local/lib/python3.7/site-packages/airflow/hooks/dbapi.py", line 181, in run
    with closing(self.get_conn()) as conn:
  File "/home/airflow/.local/lib/python3.7/site-packages/airflow/providers/postgres/hooks/postgres.py", line 113, in get_conn
    self.conn = psycopg2.connect(**conn_args)
  File "/home/airflow/.local/lib/python3.7/site-packages/psycopg2/__init__.py", line 122, in connect
    conn = _connect(dsn, connection_factory=connection_factory, **kwasync)
psycopg2.OperationalError: could not translate host name "host.docker.internal " to address: Name or service not known

[2022-07-30 18:28:53,944] {taskinstance.py:1400} INFO - Marking task as FAILED. dag_id=dag_with_postgres_operator, task_id=create_postgres_table, execution_date=20220109T000000, start_date=20220730T182853, end_date=20220730T182853
[2022-07-30 18:28:53,978] {standard_task_runner.py:97} ERROR - Failed to execute job 184 for task create_postgres_table (could not translate host name "host.docker.internal " to address: Name or service not known
; 3058)
[2022-07-30 18:28:54,019] {local_task_job.py:156} INFO - Task exited with return code 1
[2022-07-30 18:28:54,156] {local_task_job.py:273} INFO - 0 downstream tasks scheduled from follow-on schedule check
[2022-07-31 00:35:06,212] {taskinstance.py:1159} INFO - Dependencies all met for <TaskInstance: dag_with_postgres_operator.create_postgres_table scheduled__2022-01-09T00:00:00+00:00 [queued]>
[2022-07-31 00:35:06,239] {taskinstance.py:1159} INFO - Dependencies all met for <TaskInstance: dag_with_postgres_operator.create_postgres_table scheduled__2022-01-09T00:00:00+00:00 [queued]>
[2022-07-31 00:35:06,239] {taskinstance.py:1356} INFO - 
--------------------------------------------------------------------------------
[2022-07-31 00:35:06,240] {taskinstance.py:1357} INFO - Starting attempt 6 of 6
[2022-07-31 00:35:06,240] {taskinstance.py:1358} INFO - 
--------------------------------------------------------------------------------
[2022-07-31 00:35:06,261] {taskinstance.py:1377} INFO - Executing <Task(PostgresOperator): create_postgres_table> on 2022-01-09 00:00:00+00:00
[2022-07-31 00:35:06,269] {standard_task_runner.py:52} INFO - Started process 6975 to run task
[2022-07-31 00:35:06,277] {standard_task_runner.py:79} INFO - Running: ['***', 'tasks', 'run', 'dag_with_postgres_operator', 'create_postgres_table', 'scheduled__2022-01-09T00:00:00+00:00', '--job-id', '1188', '--raw', '--subdir', 'DAGS_FOLDER/DAGWithPostgresOperator.py', '--cfg-path', '/tmp/tmpja_8waow', '--error-file', '/tmp/tmp7sr37ql_']
[2022-07-31 00:35:06,277] {standard_task_runner.py:80} INFO - Job 1188: Subtask create_postgres_table
[2022-07-31 00:35:06,382] {task_command.py:369} INFO - Running <TaskInstance: dag_with_postgres_operator.create_postgres_table scheduled__2022-01-09T00:00:00+00:00 [running]> on host 66bf18ec08cc
[2022-07-31 00:35:06,491] {taskinstance.py:1571} INFO - Exporting the following env vars:
AIRFLOW_CTX_DAG_OWNER=yosr
AIRFLOW_CTX_DAG_ID=dag_with_postgres_operator
AIRFLOW_CTX_TASK_ID=create_postgres_table
AIRFLOW_CTX_EXECUTION_DATE=2022-01-09T00:00:00+00:00
AIRFLOW_CTX_TRY_NUMBER=6
AIRFLOW_CTX_DAG_RUN_ID=scheduled__2022-01-09T00:00:00+00:00
[2022-07-31 00:35:06,505] {base.py:68} INFO - Using connection ID 'postgres_localhost' for task execution.
[2022-07-31 00:35:06,507] {taskinstance.py:1889} ERROR - Task failed with exception
Traceback (most recent call last):
  File "/home/airflow/.local/lib/python3.7/site-packages/airflow/providers/postgres/operators/postgres.py", line 92, in execute
    self.hook.run(self.sql, self.autocommit, parameters=self.parameters)
  File "/home/airflow/.local/lib/python3.7/site-packages/airflow/hooks/dbapi.py", line 181, in run
    with closing(self.get_conn()) as conn:
  File "/home/airflow/.local/lib/python3.7/site-packages/airflow/providers/postgres/hooks/postgres.py", line 113, in get_conn
    self.conn = psycopg2.connect(**conn_args)
  File "/home/airflow/.local/lib/python3.7/site-packages/psycopg2/__init__.py", line 122, in connect
    conn = _connect(dsn, connection_factory=connection_factory, **kwasync)
psycopg2.OperationalError: could not translate host name "host.docker.local " to address: Name or service not known

[2022-07-31 00:35:06,523] {taskinstance.py:1400} INFO - Marking task as FAILED. dag_id=dag_with_postgres_operator, task_id=create_postgres_table, execution_date=20220109T000000, start_date=20220731T003506, end_date=20220731T003506
[2022-07-31 00:35:06,542] {standard_task_runner.py:97} ERROR - Failed to execute job 1188 for task create_postgres_table (could not translate host name "host.docker.local " to address: Name or service not known
; 6975)
[2022-07-31 00:35:06,576] {local_task_job.py:156} INFO - Task exited with return code 1
[2022-07-31 00:35:06,653] {local_task_job.py:273} INFO - 0 downstream tasks scheduled from follow-on schedule check
[2022-07-31 11:29:46,951] {taskinstance.py:1159} INFO - Dependencies all met for <TaskInstance: dag_with_postgres_operator.create_postgres_table scheduled__2022-01-09T00:00:00+00:00 [queued]>
[2022-07-31 11:29:46,969] {taskinstance.py:1159} INFO - Dependencies all met for <TaskInstance: dag_with_postgres_operator.create_postgres_table scheduled__2022-01-09T00:00:00+00:00 [queued]>
[2022-07-31 11:29:46,969] {taskinstance.py:1356} INFO - 
--------------------------------------------------------------------------------
[2022-07-31 11:29:46,969] {taskinstance.py:1357} INFO - Starting attempt 6 of 6
[2022-07-31 11:29:46,969] {taskinstance.py:1358} INFO - 
--------------------------------------------------------------------------------
[2022-07-31 11:29:47,002] {taskinstance.py:1377} INFO - Executing <Task(PostgresOperator): create_postgres_table> on 2022-01-09 00:00:00+00:00
[2022-07-31 11:29:47,008] {standard_task_runner.py:52} INFO - Started process 5922 to run task
[2022-07-31 11:29:47,015] {standard_task_runner.py:79} INFO - Running: ['***', 'tasks', 'run', 'dag_with_postgres_operator', 'create_postgres_table', 'scheduled__2022-01-09T00:00:00+00:00', '--job-id', '1650', '--raw', '--subdir', 'DAGS_FOLDER/DAGWithPostgresOperator.py', '--cfg-path', '/tmp/tmplsevtwwq', '--error-file', '/tmp/tmpb1gbeasv']
[2022-07-31 11:29:47,015] {standard_task_runner.py:80} INFO - Job 1650: Subtask create_postgres_table
[2022-07-31 11:29:47,094] {task_command.py:369} INFO - Running <TaskInstance: dag_with_postgres_operator.create_postgres_table scheduled__2022-01-09T00:00:00+00:00 [running]> on host 66bf18ec08cc
[2022-07-31 11:29:47,208] {taskinstance.py:1571} INFO - Exporting the following env vars:
AIRFLOW_CTX_DAG_OWNER=yosr
AIRFLOW_CTX_DAG_ID=dag_with_postgres_operator
AIRFLOW_CTX_TASK_ID=create_postgres_table
AIRFLOW_CTX_EXECUTION_DATE=2022-01-09T00:00:00+00:00
AIRFLOW_CTX_TRY_NUMBER=6
AIRFLOW_CTX_DAG_RUN_ID=scheduled__2022-01-09T00:00:00+00:00
[2022-07-31 11:29:47,225] {base.py:68} INFO - Using connection ID 'postgres_localhost' for task execution.
[2022-07-31 11:30:12,245] {taskinstance.py:1889} ERROR - Task failed with exception
Traceback (most recent call last):
  File "/home/airflow/.local/lib/python3.7/site-packages/airflow/providers/postgres/operators/postgres.py", line 92, in execute
    self.hook.run(self.sql, self.autocommit, parameters=self.parameters)
  File "/home/airflow/.local/lib/python3.7/site-packages/airflow/hooks/dbapi.py", line 181, in run
    with closing(self.get_conn()) as conn:
  File "/home/airflow/.local/lib/python3.7/site-packages/airflow/providers/postgres/hooks/postgres.py", line 113, in get_conn
    self.conn = psycopg2.connect(**conn_args)
  File "/home/airflow/.local/lib/python3.7/site-packages/psycopg2/__init__.py", line 122, in connect
    conn = _connect(dsn, connection_factory=connection_factory, **kwasync)
psycopg2.OperationalError: could not translate host name "host.docker.internal" to address: Temporary failure in name resolution

[2022-07-31 11:30:12,286] {taskinstance.py:1400} INFO - Marking task as FAILED. dag_id=dag_with_postgres_operator, task_id=create_postgres_table, execution_date=20220109T000000, start_date=20220731T112946, end_date=20220731T113012
[2022-07-31 11:30:12,406] {standard_task_runner.py:97} ERROR - Failed to execute job 1650 for task create_postgres_table (could not translate host name "host.docker.internal" to address: Temporary failure in name resolution
; 5922)
[2022-07-31 11:30:12,438] {local_task_job.py:156} INFO - Task exited with return code 1
[2022-07-31 11:30:12,501] {local_task_job.py:273} INFO - 0 downstream tasks scheduled from follow-on schedule check
[2022-07-31 14:00:14,405] {taskinstance.py:1159} INFO - Dependencies all met for <TaskInstance: dag_with_postgres_operator.create_postgres_table scheduled__2022-01-09T00:00:00+00:00 [queued]>
[2022-07-31 14:00:14,440] {taskinstance.py:1159} INFO - Dependencies all met for <TaskInstance: dag_with_postgres_operator.create_postgres_table scheduled__2022-01-09T00:00:00+00:00 [queued]>
[2022-07-31 14:00:14,441] {taskinstance.py:1356} INFO - 
--------------------------------------------------------------------------------
[2022-07-31 14:00:14,441] {taskinstance.py:1357} INFO - Starting attempt 6 of 6
[2022-07-31 14:00:14,442] {taskinstance.py:1358} INFO - 
--------------------------------------------------------------------------------
[2022-07-31 14:00:14,475] {taskinstance.py:1377} INFO - Executing <Task(PostgresOperator): create_postgres_table> on 2022-01-09 00:00:00+00:00
[2022-07-31 14:00:14,483] {standard_task_runner.py:52} INFO - Started process 3459 to run task
[2022-07-31 14:00:14,487] {standard_task_runner.py:79} INFO - Running: ['***', 'tasks', 'run', 'dag_with_postgres_operator', 'create_postgres_table', 'scheduled__2022-01-09T00:00:00+00:00', '--job-id', '186', '--raw', '--subdir', 'DAGS_FOLDER/DAGWithPostgresOperator.py', '--cfg-path', '/tmp/tmp1o5befv3', '--error-file', '/tmp/tmp4eyropb0']
[2022-07-31 14:00:14,488] {standard_task_runner.py:80} INFO - Job 186: Subtask create_postgres_table
[2022-07-31 14:00:14,677] {task_command.py:369} INFO - Running <TaskInstance: dag_with_postgres_operator.create_postgres_table scheduled__2022-01-09T00:00:00+00:00 [running]> on host 4688dd3b7141
[2022-07-31 14:00:14,844] {taskinstance.py:1571} INFO - Exporting the following env vars:
AIRFLOW_CTX_DAG_OWNER=yosr
AIRFLOW_CTX_DAG_ID=dag_with_postgres_operator
AIRFLOW_CTX_TASK_ID=create_postgres_table
AIRFLOW_CTX_EXECUTION_DATE=2022-01-09T00:00:00+00:00
AIRFLOW_CTX_TRY_NUMBER=6
AIRFLOW_CTX_DAG_RUN_ID=scheduled__2022-01-09T00:00:00+00:00
[2022-07-31 14:00:14,892] {taskinstance.py:1889} ERROR - Task failed with exception
Traceback (most recent call last):
  File "/home/airflow/.local/lib/python3.7/site-packages/airflow/providers/postgres/operators/postgres.py", line 92, in execute
    self.hook.run(self.sql, self.autocommit, parameters=self.parameters)
  File "/home/airflow/.local/lib/python3.7/site-packages/airflow/hooks/dbapi.py", line 181, in run
    with closing(self.get_conn()) as conn:
  File "/home/airflow/.local/lib/python3.7/site-packages/airflow/providers/postgres/hooks/postgres.py", line 86, in get_conn
    conn = deepcopy(self.connection or self.get_connection(conn_id))
  File "/home/airflow/.local/lib/python3.7/site-packages/airflow/hooks/base.py", line 67, in get_connection
    conn = Connection.get_connection_from_secrets(conn_id)
  File "/home/airflow/.local/lib/python3.7/site-packages/airflow/models/connection.py", line 430, in get_connection_from_secrets
    raise AirflowNotFoundException(f"The conn_id `{conn_id}` isn't defined")
airflow.exceptions.AirflowNotFoundException: The conn_id `postgres_localhost` isn't defined
[2022-07-31 14:00:14,896] {taskinstance.py:1400} INFO - Marking task as FAILED. dag_id=dag_with_postgres_operator, task_id=create_postgres_table, execution_date=20220109T000000, start_date=20220731T140014, end_date=20220731T140014
[2022-07-31 14:00:14,917] {standard_task_runner.py:97} ERROR - Failed to execute job 186 for task create_postgres_table (The conn_id `postgres_localhost` isn't defined; 3459)
[2022-07-31 14:00:14,964] {local_task_job.py:156} INFO - Task exited with return code 1
[2022-07-31 14:00:15,074] {local_task_job.py:273} INFO - 0 downstream tasks scheduled from follow-on schedule check
