[2022-07-30 18:13:49,822] {taskinstance.py:1159} INFO - Dependencies all met for <TaskInstance: dag_with_postgres_operator.create_postgres_table scheduled__2022-01-09T00:00:00+00:00 [queued]>
[2022-07-30 18:13:49,843] {taskinstance.py:1159} INFO - Dependencies all met for <TaskInstance: dag_with_postgres_operator.create_postgres_table scheduled__2022-01-09T00:00:00+00:00 [queued]>
[2022-07-30 18:13:49,843] {taskinstance.py:1356} INFO - 
--------------------------------------------------------------------------------
[2022-07-30 18:13:49,843] {taskinstance.py:1357} INFO - Starting attempt 3 of 6
[2022-07-30 18:13:49,843] {taskinstance.py:1358} INFO - 
--------------------------------------------------------------------------------
[2022-07-30 18:13:49,867] {taskinstance.py:1377} INFO - Executing <Task(PostgresOperator): create_postgres_table> on 2022-01-09 00:00:00+00:00
[2022-07-30 18:13:49,873] {standard_task_runner.py:52} INFO - Started process 2262 to run task
[2022-07-30 18:13:49,876] {standard_task_runner.py:79} INFO - Running: ['***', 'tasks', 'run', 'dag_with_postgres_operator', 'create_postgres_table', 'scheduled__2022-01-09T00:00:00+00:00', '--job-id', '137', '--raw', '--subdir', 'DAGS_FOLDER/DAGWithPostgresOperator.py', '--cfg-path', '/tmp/tmpr9kwxmn5', '--error-file', '/tmp/tmp1nyn8aad']
[2022-07-30 18:13:49,877] {standard_task_runner.py:80} INFO - Job 137: Subtask create_postgres_table
[2022-07-30 18:13:49,963] {task_command.py:369} INFO - Running <TaskInstance: dag_with_postgres_operator.create_postgres_table scheduled__2022-01-09T00:00:00+00:00 [running]> on host 66bf18ec08cc
[2022-07-30 18:13:50,062] {taskinstance.py:1571} INFO - Exporting the following env vars:
AIRFLOW_CTX_DAG_OWNER=yosr
AIRFLOW_CTX_DAG_ID=dag_with_postgres_operator
AIRFLOW_CTX_TASK_ID=create_postgres_table
AIRFLOW_CTX_EXECUTION_DATE=2022-01-09T00:00:00+00:00
AIRFLOW_CTX_TRY_NUMBER=3
AIRFLOW_CTX_DAG_RUN_ID=scheduled__2022-01-09T00:00:00+00:00
[2022-07-30 18:13:50,077] {base.py:68} INFO - Using connection ID 'postgres_localhost' for task execution.
[2022-07-30 18:13:50,078] {taskinstance.py:1889} ERROR - Task failed with exception
Traceback (most recent call last):
  File "/home/airflow/.local/lib/python3.7/site-packages/airflow/providers/postgres/operators/postgres.py", line 92, in execute
    self.hook.run(self.sql, self.autocommit, parameters=self.parameters)
  File "/home/airflow/.local/lib/python3.7/site-packages/airflow/hooks/dbapi.py", line 181, in run
    with closing(self.get_conn()) as conn:
  File "/home/airflow/.local/lib/python3.7/site-packages/airflow/providers/postgres/hooks/postgres.py", line 113, in get_conn
    self.conn = psycopg2.connect(**conn_args)
  File "/home/airflow/.local/lib/python3.7/site-packages/psycopg2/__init__.py", line 122, in connect
    conn = _connect(dsn, connection_factory=connection_factory, **kwasync)
psycopg2.OperationalError: could not translate host name "host.docker.internal " to address: Name or service not known

[2022-07-30 18:13:50,089] {taskinstance.py:1400} INFO - Marking task as UP_FOR_RETRY. dag_id=dag_with_postgres_operator, task_id=create_postgres_table, execution_date=20220109T000000, start_date=20220730T181349, end_date=20220730T181350
[2022-07-30 18:13:50,109] {standard_task_runner.py:97} ERROR - Failed to execute job 137 for task create_postgres_table (could not translate host name "host.docker.internal " to address: Name or service not known
; 2262)
[2022-07-30 18:13:50,138] {local_task_job.py:156} INFO - Task exited with return code 1
[2022-07-30 18:13:50,217] {local_task_job.py:273} INFO - 0 downstream tasks scheduled from follow-on schedule check
[2022-07-31 00:20:02,891] {taskinstance.py:1159} INFO - Dependencies all met for <TaskInstance: dag_with_postgres_operator.create_postgres_table scheduled__2022-01-09T00:00:00+00:00 [queued]>
[2022-07-31 00:20:02,907] {taskinstance.py:1159} INFO - Dependencies all met for <TaskInstance: dag_with_postgres_operator.create_postgres_table scheduled__2022-01-09T00:00:00+00:00 [queued]>
[2022-07-31 00:20:02,908] {taskinstance.py:1356} INFO - 
--------------------------------------------------------------------------------
[2022-07-31 00:20:02,908] {taskinstance.py:1357} INFO - Starting attempt 3 of 6
[2022-07-31 00:20:02,908] {taskinstance.py:1358} INFO - 
--------------------------------------------------------------------------------
[2022-07-31 00:20:02,928] {taskinstance.py:1377} INFO - Executing <Task(PostgresOperator): create_postgres_table> on 2022-01-09 00:00:00+00:00
[2022-07-31 00:20:02,932] {standard_task_runner.py:52} INFO - Started process 6185 to run task
[2022-07-31 00:20:02,936] {standard_task_runner.py:79} INFO - Running: ['***', 'tasks', 'run', 'dag_with_postgres_operator', 'create_postgres_table', 'scheduled__2022-01-09T00:00:00+00:00', '--job-id', '1143', '--raw', '--subdir', 'DAGS_FOLDER/DAGWithPostgresOperator.py', '--cfg-path', '/tmp/tmphhrf9ena', '--error-file', '/tmp/tmpni11atol']
[2022-07-31 00:20:02,936] {standard_task_runner.py:80} INFO - Job 1143: Subtask create_postgres_table
[2022-07-31 00:20:03,007] {task_command.py:369} INFO - Running <TaskInstance: dag_with_postgres_operator.create_postgres_table scheduled__2022-01-09T00:00:00+00:00 [running]> on host 66bf18ec08cc
[2022-07-31 00:20:03,095] {taskinstance.py:1571} INFO - Exporting the following env vars:
AIRFLOW_CTX_DAG_OWNER=yosr
AIRFLOW_CTX_DAG_ID=dag_with_postgres_operator
AIRFLOW_CTX_TASK_ID=create_postgres_table
AIRFLOW_CTX_EXECUTION_DATE=2022-01-09T00:00:00+00:00
AIRFLOW_CTX_TRY_NUMBER=3
AIRFLOW_CTX_DAG_RUN_ID=scheduled__2022-01-09T00:00:00+00:00
[2022-07-31 00:20:03,109] {base.py:68} INFO - Using connection ID 'postgres_localhost' for task execution.
[2022-07-31 00:20:03,111] {taskinstance.py:1889} ERROR - Task failed with exception
Traceback (most recent call last):
  File "/home/airflow/.local/lib/python3.7/site-packages/airflow/providers/postgres/operators/postgres.py", line 92, in execute
    self.hook.run(self.sql, self.autocommit, parameters=self.parameters)
  File "/home/airflow/.local/lib/python3.7/site-packages/airflow/hooks/dbapi.py", line 181, in run
    with closing(self.get_conn()) as conn:
  File "/home/airflow/.local/lib/python3.7/site-packages/airflow/providers/postgres/hooks/postgres.py", line 113, in get_conn
    self.conn = psycopg2.connect(**conn_args)
  File "/home/airflow/.local/lib/python3.7/site-packages/psycopg2/__init__.py", line 122, in connect
    conn = _connect(dsn, connection_factory=connection_factory, **kwasync)
psycopg2.OperationalError: could not translate host name "host.docker.local " to address: Name or service not known

[2022-07-31 00:20:03,123] {taskinstance.py:1400} INFO - Marking task as UP_FOR_RETRY. dag_id=dag_with_postgres_operator, task_id=create_postgres_table, execution_date=20220109T000000, start_date=20220731T002002, end_date=20220731T002003
[2022-07-31 00:20:03,138] {standard_task_runner.py:97} ERROR - Failed to execute job 1143 for task create_postgres_table (could not translate host name "host.docker.local " to address: Name or service not known
; 6185)
[2022-07-31 00:20:03,156] {local_task_job.py:156} INFO - Task exited with return code 1
[2022-07-31 00:20:03,216] {local_task_job.py:273} INFO - 0 downstream tasks scheduled from follow-on schedule check
[2022-07-31 11:13:28,644] {taskinstance.py:1159} INFO - Dependencies all met for <TaskInstance: dag_with_postgres_operator.create_postgres_table scheduled__2022-01-09T00:00:00+00:00 [queued]>
[2022-07-31 11:13:28,671] {taskinstance.py:1159} INFO - Dependencies all met for <TaskInstance: dag_with_postgres_operator.create_postgres_table scheduled__2022-01-09T00:00:00+00:00 [queued]>
[2022-07-31 11:13:28,671] {taskinstance.py:1356} INFO - 
--------------------------------------------------------------------------------
[2022-07-31 11:13:28,671] {taskinstance.py:1357} INFO - Starting attempt 3 of 6
[2022-07-31 11:13:28,672] {taskinstance.py:1358} INFO - 
--------------------------------------------------------------------------------
[2022-07-31 11:13:28,694] {taskinstance.py:1377} INFO - Executing <Task(PostgresOperator): create_postgres_table> on 2022-01-09 00:00:00+00:00
[2022-07-31 11:13:28,700] {standard_task_runner.py:52} INFO - Started process 5059 to run task
[2022-07-31 11:13:28,703] {standard_task_runner.py:79} INFO - Running: ['***', 'tasks', 'run', 'dag_with_postgres_operator', 'create_postgres_table', 'scheduled__2022-01-09T00:00:00+00:00', '--job-id', '1596', '--raw', '--subdir', 'DAGS_FOLDER/DAGWithPostgresOperator.py', '--cfg-path', '/tmp/tmpfyug_0n2', '--error-file', '/tmp/tmprpzyny7o']
[2022-07-31 11:13:28,704] {standard_task_runner.py:80} INFO - Job 1596: Subtask create_postgres_table
[2022-07-31 11:13:28,778] {task_command.py:369} INFO - Running <TaskInstance: dag_with_postgres_operator.create_postgres_table scheduled__2022-01-09T00:00:00+00:00 [running]> on host 66bf18ec08cc
[2022-07-31 11:13:28,890] {taskinstance.py:1571} INFO - Exporting the following env vars:
AIRFLOW_CTX_DAG_OWNER=yosr
AIRFLOW_CTX_DAG_ID=dag_with_postgres_operator
AIRFLOW_CTX_TASK_ID=create_postgres_table
AIRFLOW_CTX_EXECUTION_DATE=2022-01-09T00:00:00+00:00
AIRFLOW_CTX_TRY_NUMBER=3
AIRFLOW_CTX_DAG_RUN_ID=scheduled__2022-01-09T00:00:00+00:00
[2022-07-31 11:13:28,914] {base.py:68} INFO - Using connection ID 'postgres_localhost' for task execution.
[2022-07-31 11:13:53,937] {taskinstance.py:1889} ERROR - Task failed with exception
Traceback (most recent call last):
  File "/home/airflow/.local/lib/python3.7/site-packages/airflow/providers/postgres/operators/postgres.py", line 92, in execute
    self.hook.run(self.sql, self.autocommit, parameters=self.parameters)
  File "/home/airflow/.local/lib/python3.7/site-packages/airflow/hooks/dbapi.py", line 181, in run
    with closing(self.get_conn()) as conn:
  File "/home/airflow/.local/lib/python3.7/site-packages/airflow/providers/postgres/hooks/postgres.py", line 113, in get_conn
    self.conn = psycopg2.connect(**conn_args)
  File "/home/airflow/.local/lib/python3.7/site-packages/psycopg2/__init__.py", line 122, in connect
    conn = _connect(dsn, connection_factory=connection_factory, **kwasync)
psycopg2.OperationalError: could not translate host name "host.docker.internal" to address: Temporary failure in name resolution

[2022-07-31 11:13:53,953] {taskinstance.py:1400} INFO - Marking task as UP_FOR_RETRY. dag_id=dag_with_postgres_operator, task_id=create_postgres_table, execution_date=20220109T000000, start_date=20220731T111328, end_date=20220731T111353
[2022-07-31 11:13:54,149] {standard_task_runner.py:97} ERROR - Failed to execute job 1596 for task create_postgres_table (could not translate host name "host.docker.internal" to address: Temporary failure in name resolution
; 5059)
[2022-07-31 11:13:54,179] {local_task_job.py:156} INFO - Task exited with return code 1
[2022-07-31 11:13:54,221] {local_task_job.py:273} INFO - 0 downstream tasks scheduled from follow-on schedule check
[2022-07-31 13:45:10,156] {taskinstance.py:1159} INFO - Dependencies all met for <TaskInstance: dag_with_postgres_operator.create_postgres_table scheduled__2022-01-09T00:00:00+00:00 [queued]>
[2022-07-31 13:45:10,175] {taskinstance.py:1159} INFO - Dependencies all met for <TaskInstance: dag_with_postgres_operator.create_postgres_table scheduled__2022-01-09T00:00:00+00:00 [queued]>
[2022-07-31 13:45:10,176] {taskinstance.py:1356} INFO - 
--------------------------------------------------------------------------------
[2022-07-31 13:45:10,176] {taskinstance.py:1357} INFO - Starting attempt 3 of 6
[2022-07-31 13:45:10,176] {taskinstance.py:1358} INFO - 
--------------------------------------------------------------------------------
[2022-07-31 13:45:10,197] {taskinstance.py:1377} INFO - Executing <Task(PostgresOperator): create_postgres_table> on 2022-01-09 00:00:00+00:00
[2022-07-31 13:45:10,205] {standard_task_runner.py:52} INFO - Started process 2663 to run task
[2022-07-31 13:45:10,208] {standard_task_runner.py:79} INFO - Running: ['***', 'tasks', 'run', 'dag_with_postgres_operator', 'create_postgres_table', 'scheduled__2022-01-09T00:00:00+00:00', '--job-id', '137', '--raw', '--subdir', 'DAGS_FOLDER/DAGWithPostgresOperator.py', '--cfg-path', '/tmp/tmpsygvyab8', '--error-file', '/tmp/tmpbi29zpsd']
[2022-07-31 13:45:10,208] {standard_task_runner.py:80} INFO - Job 137: Subtask create_postgres_table
[2022-07-31 13:45:10,305] {task_command.py:369} INFO - Running <TaskInstance: dag_with_postgres_operator.create_postgres_table scheduled__2022-01-09T00:00:00+00:00 [running]> on host 4688dd3b7141
[2022-07-31 13:45:10,433] {taskinstance.py:1571} INFO - Exporting the following env vars:
AIRFLOW_CTX_DAG_OWNER=yosr
AIRFLOW_CTX_DAG_ID=dag_with_postgres_operator
AIRFLOW_CTX_TASK_ID=create_postgres_table
AIRFLOW_CTX_EXECUTION_DATE=2022-01-09T00:00:00+00:00
AIRFLOW_CTX_TRY_NUMBER=3
AIRFLOW_CTX_DAG_RUN_ID=scheduled__2022-01-09T00:00:00+00:00
[2022-07-31 13:45:10,590] {taskinstance.py:1889} ERROR - Task failed with exception
Traceback (most recent call last):
  File "/home/airflow/.local/lib/python3.7/site-packages/airflow/providers/postgres/operators/postgres.py", line 92, in execute
    self.hook.run(self.sql, self.autocommit, parameters=self.parameters)
  File "/home/airflow/.local/lib/python3.7/site-packages/airflow/hooks/dbapi.py", line 181, in run
    with closing(self.get_conn()) as conn:
  File "/home/airflow/.local/lib/python3.7/site-packages/airflow/providers/postgres/hooks/postgres.py", line 86, in get_conn
    conn = deepcopy(self.connection or self.get_connection(conn_id))
  File "/home/airflow/.local/lib/python3.7/site-packages/airflow/hooks/base.py", line 67, in get_connection
    conn = Connection.get_connection_from_secrets(conn_id)
  File "/home/airflow/.local/lib/python3.7/site-packages/airflow/models/connection.py", line 430, in get_connection_from_secrets
    raise AirflowNotFoundException(f"The conn_id `{conn_id}` isn't defined")
airflow.exceptions.AirflowNotFoundException: The conn_id `postgres_localhost` isn't defined
[2022-07-31 13:45:10,596] {taskinstance.py:1400} INFO - Marking task as UP_FOR_RETRY. dag_id=dag_with_postgres_operator, task_id=create_postgres_table, execution_date=20220109T000000, start_date=20220731T134510, end_date=20220731T134510
[2022-07-31 13:45:10,622] {standard_task_runner.py:97} ERROR - Failed to execute job 137 for task create_postgres_table (The conn_id `postgres_localhost` isn't defined; 2663)
[2022-07-31 13:45:10,674] {local_task_job.py:156} INFO - Task exited with return code 1
[2022-07-31 13:45:10,741] {local_task_job.py:273} INFO - 0 downstream tasks scheduled from follow-on schedule check
