[2022-07-30 18:13:48,953] {taskinstance.py:1159} INFO - Dependencies all met for <TaskInstance: dag_with_postgres_operator.create_postgres_table scheduled__2022-01-06T00:00:00+00:00 [queued]>
[2022-07-30 18:13:48,971] {taskinstance.py:1159} INFO - Dependencies all met for <TaskInstance: dag_with_postgres_operator.create_postgres_table scheduled__2022-01-06T00:00:00+00:00 [queued]>
[2022-07-30 18:13:48,972] {taskinstance.py:1356} INFO - 
--------------------------------------------------------------------------------
[2022-07-30 18:13:48,972] {taskinstance.py:1357} INFO - Starting attempt 3 of 6
[2022-07-30 18:13:48,972] {taskinstance.py:1358} INFO - 
--------------------------------------------------------------------------------
[2022-07-30 18:13:48,998] {taskinstance.py:1377} INFO - Executing <Task(PostgresOperator): create_postgres_table> on 2022-01-06 00:00:00+00:00
[2022-07-30 18:13:49,004] {standard_task_runner.py:52} INFO - Started process 2254 to run task
[2022-07-30 18:13:49,007] {standard_task_runner.py:79} INFO - Running: ['***', 'tasks', 'run', 'dag_with_postgres_operator', 'create_postgres_table', 'scheduled__2022-01-06T00:00:00+00:00', '--job-id', '132', '--raw', '--subdir', 'DAGS_FOLDER/DAGWithPostgresOperator.py', '--cfg-path', '/tmp/tmprjikq0uw', '--error-file', '/tmp/tmp6fr83n3r']
[2022-07-30 18:13:49,007] {standard_task_runner.py:80} INFO - Job 132: Subtask create_postgres_table
[2022-07-30 18:13:49,130] {task_command.py:369} INFO - Running <TaskInstance: dag_with_postgres_operator.create_postgres_table scheduled__2022-01-06T00:00:00+00:00 [running]> on host 66bf18ec08cc
[2022-07-30 18:13:49,265] {taskinstance.py:1571} INFO - Exporting the following env vars:
AIRFLOW_CTX_DAG_OWNER=yosr
AIRFLOW_CTX_DAG_ID=dag_with_postgres_operator
AIRFLOW_CTX_TASK_ID=create_postgres_table
AIRFLOW_CTX_EXECUTION_DATE=2022-01-06T00:00:00+00:00
AIRFLOW_CTX_TRY_NUMBER=3
AIRFLOW_CTX_DAG_RUN_ID=scheduled__2022-01-06T00:00:00+00:00
[2022-07-30 18:13:49,291] {base.py:68} INFO - Using connection ID 'postgres_localhost' for task execution.
[2022-07-30 18:13:49,292] {taskinstance.py:1889} ERROR - Task failed with exception
Traceback (most recent call last):
  File "/home/airflow/.local/lib/python3.7/site-packages/airflow/providers/postgres/operators/postgres.py", line 92, in execute
    self.hook.run(self.sql, self.autocommit, parameters=self.parameters)
  File "/home/airflow/.local/lib/python3.7/site-packages/airflow/hooks/dbapi.py", line 181, in run
    with closing(self.get_conn()) as conn:
  File "/home/airflow/.local/lib/python3.7/site-packages/airflow/providers/postgres/hooks/postgres.py", line 113, in get_conn
    self.conn = psycopg2.connect(**conn_args)
  File "/home/airflow/.local/lib/python3.7/site-packages/psycopg2/__init__.py", line 122, in connect
    conn = _connect(dsn, connection_factory=connection_factory, **kwasync)
psycopg2.OperationalError: could not translate host name "host.docker.internal " to address: Name or service not known

[2022-07-30 18:13:49,315] {taskinstance.py:1400} INFO - Marking task as UP_FOR_RETRY. dag_id=dag_with_postgres_operator, task_id=create_postgres_table, execution_date=20220106T000000, start_date=20220730T181348, end_date=20220730T181349
[2022-07-30 18:13:49,341] {standard_task_runner.py:97} ERROR - Failed to execute job 132 for task create_postgres_table (could not translate host name "host.docker.internal " to address: Name or service not known
; 2254)
[2022-07-30 18:13:49,354] {local_task_job.py:156} INFO - Task exited with return code 1
[2022-07-30 18:13:49,550] {local_task_job.py:273} INFO - 0 downstream tasks scheduled from follow-on schedule check
[2022-07-31 00:20:02,307] {taskinstance.py:1159} INFO - Dependencies all met for <TaskInstance: dag_with_postgres_operator.create_postgres_table scheduled__2022-01-06T00:00:00+00:00 [queued]>
[2022-07-31 00:20:02,332] {taskinstance.py:1159} INFO - Dependencies all met for <TaskInstance: dag_with_postgres_operator.create_postgres_table scheduled__2022-01-06T00:00:00+00:00 [queued]>
[2022-07-31 00:20:02,332] {taskinstance.py:1356} INFO - 
--------------------------------------------------------------------------------
[2022-07-31 00:20:02,332] {taskinstance.py:1357} INFO - Starting attempt 3 of 6
[2022-07-31 00:20:02,332] {taskinstance.py:1358} INFO - 
--------------------------------------------------------------------------------
[2022-07-31 00:20:02,351] {taskinstance.py:1377} INFO - Executing <Task(PostgresOperator): create_postgres_table> on 2022-01-06 00:00:00+00:00
[2022-07-31 00:20:02,356] {standard_task_runner.py:52} INFO - Started process 6179 to run task
[2022-07-31 00:20:02,360] {standard_task_runner.py:79} INFO - Running: ['***', 'tasks', 'run', 'dag_with_postgres_operator', 'create_postgres_table', 'scheduled__2022-01-06T00:00:00+00:00', '--job-id', '1139', '--raw', '--subdir', 'DAGS_FOLDER/DAGWithPostgresOperator.py', '--cfg-path', '/tmp/tmplszawcx_', '--error-file', '/tmp/tmpqhq2xo_c']
[2022-07-31 00:20:02,360] {standard_task_runner.py:80} INFO - Job 1139: Subtask create_postgres_table
[2022-07-31 00:20:02,438] {task_command.py:369} INFO - Running <TaskInstance: dag_with_postgres_operator.create_postgres_table scheduled__2022-01-06T00:00:00+00:00 [running]> on host 66bf18ec08cc
[2022-07-31 00:20:02,575] {taskinstance.py:1571} INFO - Exporting the following env vars:
AIRFLOW_CTX_DAG_OWNER=yosr
AIRFLOW_CTX_DAG_ID=dag_with_postgres_operator
AIRFLOW_CTX_TASK_ID=create_postgres_table
AIRFLOW_CTX_EXECUTION_DATE=2022-01-06T00:00:00+00:00
AIRFLOW_CTX_TRY_NUMBER=3
AIRFLOW_CTX_DAG_RUN_ID=scheduled__2022-01-06T00:00:00+00:00
[2022-07-31 00:20:02,593] {base.py:68} INFO - Using connection ID 'postgres_localhost' for task execution.
[2022-07-31 00:20:02,594] {taskinstance.py:1889} ERROR - Task failed with exception
Traceback (most recent call last):
  File "/home/airflow/.local/lib/python3.7/site-packages/airflow/providers/postgres/operators/postgres.py", line 92, in execute
    self.hook.run(self.sql, self.autocommit, parameters=self.parameters)
  File "/home/airflow/.local/lib/python3.7/site-packages/airflow/hooks/dbapi.py", line 181, in run
    with closing(self.get_conn()) as conn:
  File "/home/airflow/.local/lib/python3.7/site-packages/airflow/providers/postgres/hooks/postgres.py", line 113, in get_conn
    self.conn = psycopg2.connect(**conn_args)
  File "/home/airflow/.local/lib/python3.7/site-packages/psycopg2/__init__.py", line 122, in connect
    conn = _connect(dsn, connection_factory=connection_factory, **kwasync)
psycopg2.OperationalError: could not translate host name "host.docker.local " to address: Name or service not known

[2022-07-31 00:20:02,609] {taskinstance.py:1400} INFO - Marking task as UP_FOR_RETRY. dag_id=dag_with_postgres_operator, task_id=create_postgres_table, execution_date=20220106T000000, start_date=20220731T002002, end_date=20220731T002002
[2022-07-31 00:20:02,629] {standard_task_runner.py:97} ERROR - Failed to execute job 1139 for task create_postgres_table (could not translate host name "host.docker.local " to address: Name or service not known
; 6179)
[2022-07-31 00:20:02,668] {local_task_job.py:156} INFO - Task exited with return code 1
[2022-07-31 00:20:02,722] {local_task_job.py:273} INFO - 0 downstream tasks scheduled from follow-on schedule check
[2022-07-31 11:13:28,170] {taskinstance.py:1159} INFO - Dependencies all met for <TaskInstance: dag_with_postgres_operator.create_postgres_table scheduled__2022-01-06T00:00:00+00:00 [queued]>
[2022-07-31 11:13:28,197] {taskinstance.py:1159} INFO - Dependencies all met for <TaskInstance: dag_with_postgres_operator.create_postgres_table scheduled__2022-01-06T00:00:00+00:00 [queued]>
[2022-07-31 11:13:28,197] {taskinstance.py:1356} INFO - 
--------------------------------------------------------------------------------
[2022-07-31 11:13:28,197] {taskinstance.py:1357} INFO - Starting attempt 3 of 6
[2022-07-31 11:13:28,197] {taskinstance.py:1358} INFO - 
--------------------------------------------------------------------------------
[2022-07-31 11:13:28,219] {taskinstance.py:1377} INFO - Executing <Task(PostgresOperator): create_postgres_table> on 2022-01-06 00:00:00+00:00
[2022-07-31 11:13:28,224] {standard_task_runner.py:52} INFO - Started process 5052 to run task
[2022-07-31 11:13:28,227] {standard_task_runner.py:79} INFO - Running: ['***', 'tasks', 'run', 'dag_with_postgres_operator', 'create_postgres_table', 'scheduled__2022-01-06T00:00:00+00:00', '--job-id', '1592', '--raw', '--subdir', 'DAGS_FOLDER/DAGWithPostgresOperator.py', '--cfg-path', '/tmp/tmp2wfzmtd0', '--error-file', '/tmp/tmpnmolbyqk']
[2022-07-31 11:13:28,228] {standard_task_runner.py:80} INFO - Job 1592: Subtask create_postgres_table
[2022-07-31 11:13:28,313] {task_command.py:369} INFO - Running <TaskInstance: dag_with_postgres_operator.create_postgres_table scheduled__2022-01-06T00:00:00+00:00 [running]> on host 66bf18ec08cc
[2022-07-31 11:13:28,425] {taskinstance.py:1571} INFO - Exporting the following env vars:
AIRFLOW_CTX_DAG_OWNER=yosr
AIRFLOW_CTX_DAG_ID=dag_with_postgres_operator
AIRFLOW_CTX_TASK_ID=create_postgres_table
AIRFLOW_CTX_EXECUTION_DATE=2022-01-06T00:00:00+00:00
AIRFLOW_CTX_TRY_NUMBER=3
AIRFLOW_CTX_DAG_RUN_ID=scheduled__2022-01-06T00:00:00+00:00
[2022-07-31 11:13:28,443] {base.py:68} INFO - Using connection ID 'postgres_localhost' for task execution.
[2022-07-31 11:13:53,463] {taskinstance.py:1889} ERROR - Task failed with exception
Traceback (most recent call last):
  File "/home/airflow/.local/lib/python3.7/site-packages/airflow/providers/postgres/operators/postgres.py", line 92, in execute
    self.hook.run(self.sql, self.autocommit, parameters=self.parameters)
  File "/home/airflow/.local/lib/python3.7/site-packages/airflow/hooks/dbapi.py", line 181, in run
    with closing(self.get_conn()) as conn:
  File "/home/airflow/.local/lib/python3.7/site-packages/airflow/providers/postgres/hooks/postgres.py", line 113, in get_conn
    self.conn = psycopg2.connect(**conn_args)
  File "/home/airflow/.local/lib/python3.7/site-packages/psycopg2/__init__.py", line 122, in connect
    conn = _connect(dsn, connection_factory=connection_factory, **kwasync)
psycopg2.OperationalError: could not translate host name "host.docker.internal" to address: Temporary failure in name resolution

[2022-07-31 11:13:53,487] {taskinstance.py:1400} INFO - Marking task as UP_FOR_RETRY. dag_id=dag_with_postgres_operator, task_id=create_postgres_table, execution_date=20220106T000000, start_date=20220731T111328, end_date=20220731T111353
[2022-07-31 11:13:53,504] {standard_task_runner.py:97} ERROR - Failed to execute job 1592 for task create_postgres_table (could not translate host name "host.docker.internal" to address: Temporary failure in name resolution
; 5052)
[2022-07-31 11:13:53,511] {local_task_job.py:156} INFO - Task exited with return code 1
[2022-07-31 11:13:53,544] {local_task_job.py:273} INFO - 0 downstream tasks scheduled from follow-on schedule check
[2022-07-31 13:45:08,919] {taskinstance.py:1159} INFO - Dependencies all met for <TaskInstance: dag_with_postgres_operator.create_postgres_table scheduled__2022-01-06T00:00:00+00:00 [queued]>
[2022-07-31 13:45:08,940] {taskinstance.py:1159} INFO - Dependencies all met for <TaskInstance: dag_with_postgres_operator.create_postgres_table scheduled__2022-01-06T00:00:00+00:00 [queued]>
[2022-07-31 13:45:08,940] {taskinstance.py:1356} INFO - 
--------------------------------------------------------------------------------
[2022-07-31 13:45:08,940] {taskinstance.py:1357} INFO - Starting attempt 3 of 6
[2022-07-31 13:45:08,941] {taskinstance.py:1358} INFO - 
--------------------------------------------------------------------------------
[2022-07-31 13:45:08,968] {taskinstance.py:1377} INFO - Executing <Task(PostgresOperator): create_postgres_table> on 2022-01-06 00:00:00+00:00
[2022-07-31 13:45:08,975] {standard_task_runner.py:52} INFO - Started process 2656 to run task
[2022-07-31 13:45:08,981] {standard_task_runner.py:79} INFO - Running: ['***', 'tasks', 'run', 'dag_with_postgres_operator', 'create_postgres_table', 'scheduled__2022-01-06T00:00:00+00:00', '--job-id', '135', '--raw', '--subdir', 'DAGS_FOLDER/DAGWithPostgresOperator.py', '--cfg-path', '/tmp/tmpuw4cf8cz', '--error-file', '/tmp/tmp881hdnif']
[2022-07-31 13:45:08,982] {standard_task_runner.py:80} INFO - Job 135: Subtask create_postgres_table
[2022-07-31 13:45:09,119] {task_command.py:369} INFO - Running <TaskInstance: dag_with_postgres_operator.create_postgres_table scheduled__2022-01-06T00:00:00+00:00 [running]> on host 4688dd3b7141
[2022-07-31 13:45:09,249] {taskinstance.py:1571} INFO - Exporting the following env vars:
AIRFLOW_CTX_DAG_OWNER=yosr
AIRFLOW_CTX_DAG_ID=dag_with_postgres_operator
AIRFLOW_CTX_TASK_ID=create_postgres_table
AIRFLOW_CTX_EXECUTION_DATE=2022-01-06T00:00:00+00:00
AIRFLOW_CTX_TRY_NUMBER=3
AIRFLOW_CTX_DAG_RUN_ID=scheduled__2022-01-06T00:00:00+00:00
[2022-07-31 13:45:09,291] {taskinstance.py:1889} ERROR - Task failed with exception
Traceback (most recent call last):
  File "/home/airflow/.local/lib/python3.7/site-packages/airflow/providers/postgres/operators/postgres.py", line 92, in execute
    self.hook.run(self.sql, self.autocommit, parameters=self.parameters)
  File "/home/airflow/.local/lib/python3.7/site-packages/airflow/hooks/dbapi.py", line 181, in run
    with closing(self.get_conn()) as conn:
  File "/home/airflow/.local/lib/python3.7/site-packages/airflow/providers/postgres/hooks/postgres.py", line 86, in get_conn
    conn = deepcopy(self.connection or self.get_connection(conn_id))
  File "/home/airflow/.local/lib/python3.7/site-packages/airflow/hooks/base.py", line 67, in get_connection
    conn = Connection.get_connection_from_secrets(conn_id)
  File "/home/airflow/.local/lib/python3.7/site-packages/airflow/models/connection.py", line 430, in get_connection_from_secrets
    raise AirflowNotFoundException(f"The conn_id `{conn_id}` isn't defined")
airflow.exceptions.AirflowNotFoundException: The conn_id `postgres_localhost` isn't defined
[2022-07-31 13:45:09,295] {taskinstance.py:1400} INFO - Marking task as UP_FOR_RETRY. dag_id=dag_with_postgres_operator, task_id=create_postgres_table, execution_date=20220106T000000, start_date=20220731T134508, end_date=20220731T134509
[2022-07-31 13:45:09,314] {standard_task_runner.py:97} ERROR - Failed to execute job 135 for task create_postgres_table (The conn_id `postgres_localhost` isn't defined; 2656)
[2022-07-31 13:45:09,322] {local_task_job.py:156} INFO - Task exited with return code 1
[2022-07-31 13:45:09,378] {local_task_job.py:273} INFO - 0 downstream tasks scheduled from follow-on schedule check
