[2022-07-30 19:19:24,558] {taskinstance.py:1159} INFO - Dependencies all met for <TaskInstance: dag_with_postgres_operator.create_postgres_table scheduled__2022-02-17T00:00:00+00:00 [queued]>
[2022-07-30 19:19:24,574] {taskinstance.py:1159} INFO - Dependencies all met for <TaskInstance: dag_with_postgres_operator.create_postgres_table scheduled__2022-02-17T00:00:00+00:00 [queued]>
[2022-07-30 19:19:24,574] {taskinstance.py:1356} INFO - 
--------------------------------------------------------------------------------
[2022-07-30 19:19:24,574] {taskinstance.py:1357} INFO - Starting attempt 6 of 6
[2022-07-30 19:19:24,574] {taskinstance.py:1358} INFO - 
--------------------------------------------------------------------------------
[2022-07-30 19:19:24,599] {taskinstance.py:1377} INFO - Executing <Task(PostgresOperator): create_postgres_table> on 2022-02-17 00:00:00+00:00
[2022-07-30 19:19:24,605] {standard_task_runner.py:52} INFO - Started process 5798 to run task
[2022-07-30 19:19:24,608] {standard_task_runner.py:79} INFO - Running: ['***', 'tasks', 'run', 'dag_with_postgres_operator', 'create_postgres_table', 'scheduled__2022-02-17T00:00:00+00:00', '--job-id', '382', '--raw', '--subdir', 'DAGS_FOLDER/DAGWithPostgresOperator.py', '--cfg-path', '/tmp/tmpdo_dyv1b', '--error-file', '/tmp/tmpnntggarv']
[2022-07-30 19:19:24,608] {standard_task_runner.py:80} INFO - Job 382: Subtask create_postgres_table
[2022-07-30 19:19:24,686] {task_command.py:369} INFO - Running <TaskInstance: dag_with_postgres_operator.create_postgres_table scheduled__2022-02-17T00:00:00+00:00 [running]> on host 66bf18ec08cc
[2022-07-30 19:19:24,800] {taskinstance.py:1571} INFO - Exporting the following env vars:
AIRFLOW_CTX_DAG_OWNER=yosr
AIRFLOW_CTX_DAG_ID=dag_with_postgres_operator
AIRFLOW_CTX_TASK_ID=create_postgres_table
AIRFLOW_CTX_EXECUTION_DATE=2022-02-17T00:00:00+00:00
AIRFLOW_CTX_TRY_NUMBER=6
AIRFLOW_CTX_DAG_RUN_ID=scheduled__2022-02-17T00:00:00+00:00
[2022-07-30 19:19:24,817] {base.py:68} INFO - Using connection ID 'postgres_localhost' for task execution.
[2022-07-30 19:19:24,818] {taskinstance.py:1889} ERROR - Task failed with exception
Traceback (most recent call last):
  File "/home/airflow/.local/lib/python3.7/site-packages/airflow/providers/postgres/operators/postgres.py", line 92, in execute
    self.hook.run(self.sql, self.autocommit, parameters=self.parameters)
  File "/home/airflow/.local/lib/python3.7/site-packages/airflow/hooks/dbapi.py", line 181, in run
    with closing(self.get_conn()) as conn:
  File "/home/airflow/.local/lib/python3.7/site-packages/airflow/providers/postgres/hooks/postgres.py", line 113, in get_conn
    self.conn = psycopg2.connect(**conn_args)
  File "/home/airflow/.local/lib/python3.7/site-packages/psycopg2/__init__.py", line 122, in connect
    conn = _connect(dsn, connection_factory=connection_factory, **kwasync)
psycopg2.OperationalError: could not translate host name "host.docker.internal " to address: Name or service not known

[2022-07-30 19:19:24,835] {taskinstance.py:1400} INFO - Marking task as FAILED. dag_id=dag_with_postgres_operator, task_id=create_postgres_table, execution_date=20220217T000000, start_date=20220730T191924, end_date=20220730T191924
[2022-07-30 19:19:24,847] {standard_task_runner.py:97} ERROR - Failed to execute job 382 for task create_postgres_table (could not translate host name "host.docker.internal " to address: Name or service not known
; 5798)
[2022-07-30 19:19:24,870] {local_task_job.py:156} INFO - Task exited with return code 1
[2022-07-30 19:19:24,921] {local_task_job.py:273} INFO - 0 downstream tasks scheduled from follow-on schedule check
[2022-07-31 10:21:40,252] {taskinstance.py:1159} INFO - Dependencies all met for <TaskInstance: dag_with_postgres_operator.create_postgres_table scheduled__2022-02-17T00:00:00+00:00 [queued]>
[2022-07-31 10:21:40,323] {taskinstance.py:1159} INFO - Dependencies all met for <TaskInstance: dag_with_postgres_operator.create_postgres_table scheduled__2022-02-17T00:00:00+00:00 [queued]>
[2022-07-31 10:21:40,323] {taskinstance.py:1356} INFO - 
--------------------------------------------------------------------------------
[2022-07-31 10:21:40,324] {taskinstance.py:1357} INFO - Starting attempt 6 of 6
[2022-07-31 10:21:40,324] {taskinstance.py:1358} INFO - 
--------------------------------------------------------------------------------
[2022-07-31 10:21:40,365] {taskinstance.py:1377} INFO - Executing <Task(PostgresOperator): create_postgres_table> on 2022-02-17 00:00:00+00:00
[2022-07-31 10:21:40,371] {standard_task_runner.py:52} INFO - Started process 2272 to run task
[2022-07-31 10:21:40,377] {standard_task_runner.py:79} INFO - Running: ['***', 'tasks', 'run', 'dag_with_postgres_operator', 'create_postgres_table', 'scheduled__2022-02-17T00:00:00+00:00', '--job-id', '1393', '--raw', '--subdir', 'DAGS_FOLDER/DAGWithPostgresOperator.py', '--cfg-path', '/tmp/tmpqervq8d_', '--error-file', '/tmp/tmpcjt9866o']
[2022-07-31 10:21:40,377] {standard_task_runner.py:80} INFO - Job 1393: Subtask create_postgres_table
[2022-07-31 10:21:40,485] {task_command.py:369} INFO - Running <TaskInstance: dag_with_postgres_operator.create_postgres_table scheduled__2022-02-17T00:00:00+00:00 [running]> on host 66bf18ec08cc
[2022-07-31 10:21:40,606] {taskinstance.py:1571} INFO - Exporting the following env vars:
AIRFLOW_CTX_DAG_OWNER=yosr
AIRFLOW_CTX_DAG_ID=dag_with_postgres_operator
AIRFLOW_CTX_TASK_ID=create_postgres_table
AIRFLOW_CTX_EXECUTION_DATE=2022-02-17T00:00:00+00:00
AIRFLOW_CTX_TRY_NUMBER=6
AIRFLOW_CTX_DAG_RUN_ID=scheduled__2022-02-17T00:00:00+00:00
[2022-07-31 10:21:40,637] {base.py:68} INFO - Using connection ID 'postgres_localhost' for task execution.
[2022-07-31 10:21:40,638] {taskinstance.py:1889} ERROR - Task failed with exception
Traceback (most recent call last):
  File "/home/airflow/.local/lib/python3.7/site-packages/airflow/providers/postgres/operators/postgres.py", line 92, in execute
    self.hook.run(self.sql, self.autocommit, parameters=self.parameters)
  File "/home/airflow/.local/lib/python3.7/site-packages/airflow/hooks/dbapi.py", line 181, in run
    with closing(self.get_conn()) as conn:
  File "/home/airflow/.local/lib/python3.7/site-packages/airflow/providers/postgres/hooks/postgres.py", line 113, in get_conn
    self.conn = psycopg2.connect(**conn_args)
  File "/home/airflow/.local/lib/python3.7/site-packages/psycopg2/__init__.py", line 122, in connect
    conn = _connect(dsn, connection_factory=connection_factory, **kwasync)
psycopg2.OperationalError: could not translate host name "host.docker.local " to address: Name or service not known

[2022-07-31 10:21:40,655] {taskinstance.py:1400} INFO - Marking task as FAILED. dag_id=dag_with_postgres_operator, task_id=create_postgres_table, execution_date=20220217T000000, start_date=20220731T102140, end_date=20220731T102140
[2022-07-31 10:21:40,675] {standard_task_runner.py:97} ERROR - Failed to execute job 1393 for task create_postgres_table (could not translate host name "host.docker.local " to address: Name or service not known
; 2272)
[2022-07-31 10:21:40,685] {local_task_job.py:156} INFO - Task exited with return code 1
[2022-07-31 10:21:40,814] {local_task_job.py:273} INFO - 0 downstream tasks scheduled from follow-on schedule check
[2022-07-31 14:51:22,298] {taskinstance.py:1159} INFO - Dependencies all met for <TaskInstance: dag_with_postgres_operator.create_postgres_table scheduled__2022-02-17T00:00:00+00:00 [queued]>
[2022-07-31 14:51:22,325] {taskinstance.py:1159} INFO - Dependencies all met for <TaskInstance: dag_with_postgres_operator.create_postgres_table scheduled__2022-02-17T00:00:00+00:00 [queued]>
[2022-07-31 14:51:22,325] {taskinstance.py:1356} INFO - 
--------------------------------------------------------------------------------
[2022-07-31 14:51:22,325] {taskinstance.py:1357} INFO - Starting attempt 6 of 6
[2022-07-31 14:51:22,325] {taskinstance.py:1358} INFO - 
--------------------------------------------------------------------------------
[2022-07-31 14:51:22,353] {taskinstance.py:1377} INFO - Executing <Task(PostgresOperator): create_postgres_table> on 2022-02-17 00:00:00+00:00
[2022-07-31 14:51:22,361] {standard_task_runner.py:52} INFO - Started process 6213 to run task
[2022-07-31 14:51:22,365] {standard_task_runner.py:79} INFO - Running: ['***', 'tasks', 'run', 'dag_with_postgres_operator', 'create_postgres_table', 'scheduled__2022-02-17T00:00:00+00:00', '--job-id', '376', '--raw', '--subdir', 'DAGS_FOLDER/DAGWithPostgresOperator.py', '--cfg-path', '/tmp/tmpuatzq8j_', '--error-file', '/tmp/tmpm4a1e8ez']
[2022-07-31 14:51:22,366] {standard_task_runner.py:80} INFO - Job 376: Subtask create_postgres_table
[2022-07-31 14:51:22,475] {task_command.py:369} INFO - Running <TaskInstance: dag_with_postgres_operator.create_postgres_table scheduled__2022-02-17T00:00:00+00:00 [running]> on host 4688dd3b7141
[2022-07-31 14:51:22,547] {taskinstance.py:1889} ERROR - Task failed with exception
Traceback (most recent call last):
  File "/home/airflow/.local/lib/python3.7/site-packages/airflow/models/taskinstance.py", line 1451, in _run_raw_task
    self._execute_task_with_callbacks(context, test_mode)
  File "/home/airflow/.local/lib/python3.7/site-packages/airflow/models/taskinstance.py", line 1555, in _execute_task_with_callbacks
    task_orig = self.render_templates(context=context)
  File "/home/airflow/.local/lib/python3.7/site-packages/airflow/models/taskinstance.py", line 2202, in render_templates
    rendered_task = self.task.render_template_fields(context)
  File "/home/airflow/.local/lib/python3.7/site-packages/airflow/models/baseoperator.py", line 1179, in render_template_fields
    self._do_render_template_fields(self, self.template_fields, context, jinja_env, set())
  File "/home/airflow/.local/lib/python3.7/site-packages/airflow/utils/session.py", line 71, in wrapper
    return func(*args, session=session, **kwargs)
  File "/home/airflow/.local/lib/python3.7/site-packages/airflow/models/abstractoperator.py", line 348, in _do_render_template_fields
    seen_oids,
  File "/home/airflow/.local/lib/python3.7/site-packages/airflow/models/abstractoperator.py", line 385, in render_template
    template = jinja_env.get_template(value)
  File "/home/airflow/.local/lib/python3.7/site-packages/jinja2/environment.py", line 997, in get_template
    return self._load_template(name, globals)
  File "/home/airflow/.local/lib/python3.7/site-packages/jinja2/environment.py", line 958, in _load_template
    template = self.loader.load(self, name, self.make_globals(globals))
  File "/home/airflow/.local/lib/python3.7/site-packages/jinja2/loaders.py", line 125, in load
    source, filename, uptodate = self.get_source(environment, name)
  File "/home/airflow/.local/lib/python3.7/site-packages/jinja2/loaders.py", line 214, in get_source
    raise TemplateNotFound(template)
jinja2.exceptions.TemplateNotFound: /data/postgres/pet_schema.sql
[2022-07-31 14:51:22,592] {taskinstance.py:1400} INFO - Marking task as FAILED. dag_id=dag_with_postgres_operator, task_id=create_postgres_table, execution_date=20220217T000000, start_date=20220731T145122, end_date=20220731T145122
[2022-07-31 14:51:22,614] {standard_task_runner.py:97} ERROR - Failed to execute job 376 for task create_postgres_table (/data/postgres/pet_schema.sql; 6213)
[2022-07-31 14:51:22,633] {local_task_job.py:156} INFO - Task exited with return code 1
[2022-07-31 14:51:22,726] {local_task_job.py:273} INFO - 0 downstream tasks scheduled from follow-on schedule check
