[2022-07-30 19:49:54,428] {taskinstance.py:1159} INFO - Dependencies all met for <TaskInstance: dag_with_postgres_operator.create_postgres_table scheduled__2022-03-20T00:00:00+00:00 [queued]>
[2022-07-30 19:49:54,445] {taskinstance.py:1159} INFO - Dependencies all met for <TaskInstance: dag_with_postgres_operator.create_postgres_table scheduled__2022-03-20T00:00:00+00:00 [queued]>
[2022-07-30 19:49:54,445] {taskinstance.py:1356} INFO - 
--------------------------------------------------------------------------------
[2022-07-30 19:49:54,445] {taskinstance.py:1357} INFO - Starting attempt 2 of 6
[2022-07-30 19:49:54,445] {taskinstance.py:1358} INFO - 
--------------------------------------------------------------------------------
[2022-07-30 19:49:54,467] {taskinstance.py:1377} INFO - Executing <Task(PostgresOperator): create_postgres_table> on 2022-03-20 00:00:00+00:00
[2022-07-30 19:49:54,472] {standard_task_runner.py:52} INFO - Started process 7454 to run task
[2022-07-30 19:49:54,476] {standard_task_runner.py:79} INFO - Running: ['***', 'tasks', 'run', 'dag_with_postgres_operator', 'create_postgres_table', 'scheduled__2022-03-20T00:00:00+00:00', '--job-id', '512', '--raw', '--subdir', 'DAGS_FOLDER/DAGWithPostgresOperator.py', '--cfg-path', '/tmp/tmp450h6id8', '--error-file', '/tmp/tmpfkiys642']
[2022-07-30 19:49:54,476] {standard_task_runner.py:80} INFO - Job 512: Subtask create_postgres_table
[2022-07-30 19:49:54,553] {task_command.py:369} INFO - Running <TaskInstance: dag_with_postgres_operator.create_postgres_table scheduled__2022-03-20T00:00:00+00:00 [running]> on host 66bf18ec08cc
[2022-07-30 19:49:54,676] {taskinstance.py:1571} INFO - Exporting the following env vars:
AIRFLOW_CTX_DAG_OWNER=yosr
AIRFLOW_CTX_DAG_ID=dag_with_postgres_operator
AIRFLOW_CTX_TASK_ID=create_postgres_table
AIRFLOW_CTX_EXECUTION_DATE=2022-03-20T00:00:00+00:00
AIRFLOW_CTX_TRY_NUMBER=2
AIRFLOW_CTX_DAG_RUN_ID=scheduled__2022-03-20T00:00:00+00:00
[2022-07-30 19:49:54,694] {base.py:68} INFO - Using connection ID 'postgres_localhost' for task execution.
[2022-07-30 19:49:54,695] {taskinstance.py:1889} ERROR - Task failed with exception
Traceback (most recent call last):
  File "/home/airflow/.local/lib/python3.7/site-packages/airflow/providers/postgres/operators/postgres.py", line 92, in execute
    self.hook.run(self.sql, self.autocommit, parameters=self.parameters)
  File "/home/airflow/.local/lib/python3.7/site-packages/airflow/hooks/dbapi.py", line 181, in run
    with closing(self.get_conn()) as conn:
  File "/home/airflow/.local/lib/python3.7/site-packages/airflow/providers/postgres/hooks/postgres.py", line 113, in get_conn
    self.conn = psycopg2.connect(**conn_args)
  File "/home/airflow/.local/lib/python3.7/site-packages/psycopg2/__init__.py", line 122, in connect
    conn = _connect(dsn, connection_factory=connection_factory, **kwasync)
psycopg2.OperationalError: could not translate host name "host.docker.internal " to address: Name or service not known

[2022-07-30 19:49:54,713] {taskinstance.py:1400} INFO - Marking task as UP_FOR_RETRY. dag_id=dag_with_postgres_operator, task_id=create_postgres_table, execution_date=20220320T000000, start_date=20220730T194954, end_date=20220730T194954
[2022-07-30 19:49:54,733] {standard_task_runner.py:97} ERROR - Failed to execute job 512 for task create_postgres_table (could not translate host name "host.docker.internal " to address: Name or service not known
; 7454)
[2022-07-30 19:49:54,776] {local_task_job.py:156} INFO - Task exited with return code 1
[2022-07-30 19:49:54,857] {local_task_job.py:273} INFO - 0 downstream tasks scheduled from follow-on schedule check
