[2022-07-30 18:39:00,892] {taskinstance.py:1159} INFO - Dependencies all met for <TaskInstance: dag_with_postgres_operator.create_postgres_table scheduled__2022-01-22T00:00:00+00:00 [queued]>
[2022-07-30 18:39:00,910] {taskinstance.py:1159} INFO - Dependencies all met for <TaskInstance: dag_with_postgres_operator.create_postgres_table scheduled__2022-01-22T00:00:00+00:00 [queued]>
[2022-07-30 18:39:00,911] {taskinstance.py:1356} INFO - 
--------------------------------------------------------------------------------
[2022-07-30 18:39:00,911] {taskinstance.py:1357} INFO - Starting attempt 3 of 6
[2022-07-30 18:39:00,911] {taskinstance.py:1358} INFO - 
--------------------------------------------------------------------------------
[2022-07-30 18:39:00,937] {taskinstance.py:1377} INFO - Executing <Task(PostgresOperator): create_postgres_table> on 2022-01-22 00:00:00+00:00
[2022-07-30 18:39:00,942] {standard_task_runner.py:52} INFO - Started process 3612 to run task
[2022-07-30 18:39:00,947] {standard_task_runner.py:79} INFO - Running: ['***', 'tasks', 'run', 'dag_with_postgres_operator', 'create_postgres_table', 'scheduled__2022-01-22T00:00:00+00:00', '--job-id', '228', '--raw', '--subdir', 'DAGS_FOLDER/DAGWithPostgresOperator.py', '--cfg-path', '/tmp/tmpcqxloec4', '--error-file', '/tmp/tmpksbfauza']
[2022-07-30 18:39:00,948] {standard_task_runner.py:80} INFO - Job 228: Subtask create_postgres_table
[2022-07-30 18:39:01,026] {task_command.py:369} INFO - Running <TaskInstance: dag_with_postgres_operator.create_postgres_table scheduled__2022-01-22T00:00:00+00:00 [running]> on host 66bf18ec08cc
[2022-07-30 18:39:01,121] {taskinstance.py:1571} INFO - Exporting the following env vars:
AIRFLOW_CTX_DAG_OWNER=yosr
AIRFLOW_CTX_DAG_ID=dag_with_postgres_operator
AIRFLOW_CTX_TASK_ID=create_postgres_table
AIRFLOW_CTX_EXECUTION_DATE=2022-01-22T00:00:00+00:00
AIRFLOW_CTX_TRY_NUMBER=3
AIRFLOW_CTX_DAG_RUN_ID=scheduled__2022-01-22T00:00:00+00:00
[2022-07-30 18:39:01,135] {base.py:68} INFO - Using connection ID 'postgres_localhost' for task execution.
[2022-07-30 18:39:01,136] {taskinstance.py:1889} ERROR - Task failed with exception
Traceback (most recent call last):
  File "/home/airflow/.local/lib/python3.7/site-packages/airflow/providers/postgres/operators/postgres.py", line 92, in execute
    self.hook.run(self.sql, self.autocommit, parameters=self.parameters)
  File "/home/airflow/.local/lib/python3.7/site-packages/airflow/hooks/dbapi.py", line 181, in run
    with closing(self.get_conn()) as conn:
  File "/home/airflow/.local/lib/python3.7/site-packages/airflow/providers/postgres/hooks/postgres.py", line 113, in get_conn
    self.conn = psycopg2.connect(**conn_args)
  File "/home/airflow/.local/lib/python3.7/site-packages/psycopg2/__init__.py", line 122, in connect
    conn = _connect(dsn, connection_factory=connection_factory, **kwasync)
psycopg2.OperationalError: could not translate host name "host.docker.internal " to address: Name or service not known

[2022-07-30 18:39:01,147] {taskinstance.py:1400} INFO - Marking task as UP_FOR_RETRY. dag_id=dag_with_postgres_operator, task_id=create_postgres_table, execution_date=20220122T000000, start_date=20220730T183900, end_date=20220730T183901
[2022-07-30 18:39:01,162] {standard_task_runner.py:97} ERROR - Failed to execute job 228 for task create_postgres_table (could not translate host name "host.docker.internal " to address: Name or service not known
; 3612)
[2022-07-30 18:39:01,203] {local_task_job.py:156} INFO - Task exited with return code 1
[2022-07-30 18:39:01,286] {local_task_job.py:273} INFO - 0 downstream tasks scheduled from follow-on schedule check
[2022-07-31 09:41:03,631] {taskinstance.py:1159} INFO - Dependencies all met for <TaskInstance: dag_with_postgres_operator.create_postgres_table scheduled__2022-01-22T00:00:00+00:00 [queued]>
[2022-07-31 09:41:03,891] {taskinstance.py:1159} INFO - Dependencies all met for <TaskInstance: dag_with_postgres_operator.create_postgres_table scheduled__2022-01-22T00:00:00+00:00 [queued]>
[2022-07-31 09:41:03,892] {taskinstance.py:1356} INFO - 
--------------------------------------------------------------------------------
[2022-07-31 09:41:03,892] {taskinstance.py:1357} INFO - Starting attempt 3 of 6
[2022-07-31 09:41:03,892] {taskinstance.py:1358} INFO - 
--------------------------------------------------------------------------------
[2022-07-31 09:41:04,053] {taskinstance.py:1377} INFO - Executing <Task(PostgresOperator): create_postgres_table> on 2022-01-22 00:00:00+00:00
[2022-07-31 09:41:04,092] {standard_task_runner.py:52} INFO - Started process 95 to run task
[2022-07-31 09:41:04,239] {standard_task_runner.py:79} INFO - Running: ['***', 'tasks', 'run', 'dag_with_postgres_operator', 'create_postgres_table', 'scheduled__2022-01-22T00:00:00+00:00', '--job-id', '1241', '--raw', '--subdir', 'DAGS_FOLDER/DAGWithPostgresOperator.py', '--cfg-path', '/tmp/tmpnpahox_a', '--error-file', '/tmp/tmpk_b05_0q']
[2022-07-31 09:41:04,239] {standard_task_runner.py:80} INFO - Job 1241: Subtask create_postgres_table
[2022-07-31 09:41:05,068] {task_command.py:369} INFO - Running <TaskInstance: dag_with_postgres_operator.create_postgres_table scheduled__2022-01-22T00:00:00+00:00 [running]> on host 66bf18ec08cc
[2022-07-31 09:41:05,709] {taskinstance.py:1571} INFO - Exporting the following env vars:
AIRFLOW_CTX_DAG_OWNER=yosr
AIRFLOW_CTX_DAG_ID=dag_with_postgres_operator
AIRFLOW_CTX_TASK_ID=create_postgres_table
AIRFLOW_CTX_EXECUTION_DATE=2022-01-22T00:00:00+00:00
AIRFLOW_CTX_TRY_NUMBER=3
AIRFLOW_CTX_DAG_RUN_ID=scheduled__2022-01-22T00:00:00+00:00
[2022-07-31 09:41:05,776] {base.py:68} INFO - Using connection ID 'postgres_localhost' for task execution.
[2022-07-31 09:41:05,779] {taskinstance.py:1889} ERROR - Task failed with exception
Traceback (most recent call last):
  File "/home/airflow/.local/lib/python3.7/site-packages/airflow/providers/postgres/operators/postgres.py", line 92, in execute
    self.hook.run(self.sql, self.autocommit, parameters=self.parameters)
  File "/home/airflow/.local/lib/python3.7/site-packages/airflow/hooks/dbapi.py", line 181, in run
    with closing(self.get_conn()) as conn:
  File "/home/airflow/.local/lib/python3.7/site-packages/airflow/providers/postgres/hooks/postgres.py", line 113, in get_conn
    self.conn = psycopg2.connect(**conn_args)
  File "/home/airflow/.local/lib/python3.7/site-packages/psycopg2/__init__.py", line 122, in connect
    conn = _connect(dsn, connection_factory=connection_factory, **kwasync)
psycopg2.OperationalError: could not translate host name "host.docker.local " to address: Name or service not known

[2022-07-31 09:41:05,873] {taskinstance.py:1400} INFO - Marking task as UP_FOR_RETRY. dag_id=dag_with_postgres_operator, task_id=create_postgres_table, execution_date=20220122T000000, start_date=20220731T094103, end_date=20220731T094105
[2022-07-31 09:41:05,953] {standard_task_runner.py:97} ERROR - Failed to execute job 1241 for task create_postgres_table (could not translate host name "host.docker.local " to address: Name or service not known
; 95)
[2022-07-31 09:41:06,002] {local_task_job.py:156} INFO - Task exited with return code 1
[2022-07-31 09:41:06,111] {local_task_job.py:273} INFO - 0 downstream tasks scheduled from follow-on schedule check
[2022-07-31 14:10:25,004] {taskinstance.py:1159} INFO - Dependencies all met for <TaskInstance: dag_with_postgres_operator.create_postgres_table scheduled__2022-01-22T00:00:00+00:00 [queued]>
[2022-07-31 14:10:25,028] {taskinstance.py:1159} INFO - Dependencies all met for <TaskInstance: dag_with_postgres_operator.create_postgres_table scheduled__2022-01-22T00:00:00+00:00 [queued]>
[2022-07-31 14:10:25,028] {taskinstance.py:1356} INFO - 
--------------------------------------------------------------------------------
[2022-07-31 14:10:25,028] {taskinstance.py:1357} INFO - Starting attempt 3 of 6
[2022-07-31 14:10:25,028] {taskinstance.py:1358} INFO - 
--------------------------------------------------------------------------------
[2022-07-31 14:10:25,049] {taskinstance.py:1377} INFO - Executing <Task(PostgresOperator): create_postgres_table> on 2022-01-22 00:00:00+00:00
[2022-07-31 14:10:25,057] {standard_task_runner.py:52} INFO - Started process 4019 to run task
[2022-07-31 14:10:25,061] {standard_task_runner.py:79} INFO - Running: ['***', 'tasks', 'run', 'dag_with_postgres_operator', 'create_postgres_table', 'scheduled__2022-01-22T00:00:00+00:00', '--job-id', '228', '--raw', '--subdir', 'DAGS_FOLDER/DAGWithPostgresOperator.py', '--cfg-path', '/tmp/tmpf9znih98', '--error-file', '/tmp/tmpi6mcbaiq']
[2022-07-31 14:10:25,062] {standard_task_runner.py:80} INFO - Job 228: Subtask create_postgres_table
[2022-07-31 14:10:25,156] {task_command.py:369} INFO - Running <TaskInstance: dag_with_postgres_operator.create_postgres_table scheduled__2022-01-22T00:00:00+00:00 [running]> on host 4688dd3b7141
[2022-07-31 14:10:25,286] {taskinstance.py:1571} INFO - Exporting the following env vars:
AIRFLOW_CTX_DAG_OWNER=yosr
AIRFLOW_CTX_DAG_ID=dag_with_postgres_operator
AIRFLOW_CTX_TASK_ID=create_postgres_table
AIRFLOW_CTX_EXECUTION_DATE=2022-01-22T00:00:00+00:00
AIRFLOW_CTX_TRY_NUMBER=3
AIRFLOW_CTX_DAG_RUN_ID=scheduled__2022-01-22T00:00:00+00:00
[2022-07-31 14:10:25,339] {taskinstance.py:1889} ERROR - Task failed with exception
Traceback (most recent call last):
  File "/home/airflow/.local/lib/python3.7/site-packages/airflow/providers/postgres/operators/postgres.py", line 92, in execute
    self.hook.run(self.sql, self.autocommit, parameters=self.parameters)
  File "/home/airflow/.local/lib/python3.7/site-packages/airflow/hooks/dbapi.py", line 181, in run
    with closing(self.get_conn()) as conn:
  File "/home/airflow/.local/lib/python3.7/site-packages/airflow/providers/postgres/hooks/postgres.py", line 86, in get_conn
    conn = deepcopy(self.connection or self.get_connection(conn_id))
  File "/home/airflow/.local/lib/python3.7/site-packages/airflow/hooks/base.py", line 67, in get_connection
    conn = Connection.get_connection_from_secrets(conn_id)
  File "/home/airflow/.local/lib/python3.7/site-packages/airflow/models/connection.py", line 430, in get_connection_from_secrets
    raise AirflowNotFoundException(f"The conn_id `{conn_id}` isn't defined")
airflow.exceptions.AirflowNotFoundException: The conn_id `postgres_localhost` isn't defined
[2022-07-31 14:10:25,348] {taskinstance.py:1400} INFO - Marking task as UP_FOR_RETRY. dag_id=dag_with_postgres_operator, task_id=create_postgres_table, execution_date=20220122T000000, start_date=20220731T141025, end_date=20220731T141025
[2022-07-31 14:10:25,367] {standard_task_runner.py:97} ERROR - Failed to execute job 228 for task create_postgres_table (The conn_id `postgres_localhost` isn't defined; 4019)
[2022-07-31 14:10:25,408] {local_task_job.py:156} INFO - Task exited with return code 1
[2022-07-31 14:10:25,469] {local_task_job.py:273} INFO - 0 downstream tasks scheduled from follow-on schedule check
