[2022-07-29 10:55:29,167] {taskinstance.py:1159} INFO - Dependencies all met for <TaskInstance: Second_one.first_task scheduled__2022-02-01T00:00:00+00:00 [queued]>
[2022-07-29 10:55:29,185] {taskinstance.py:1159} INFO - Dependencies all met for <TaskInstance: Second_one.first_task scheduled__2022-02-01T00:00:00+00:00 [queued]>
[2022-07-29 10:55:29,185] {taskinstance.py:1356} INFO - 
--------------------------------------------------------------------------------
[2022-07-29 10:55:29,185] {taskinstance.py:1357} INFO - Starting attempt 1 of 6
[2022-07-29 10:55:29,185] {taskinstance.py:1358} INFO - 
--------------------------------------------------------------------------------
[2022-07-29 10:55:29,211] {taskinstance.py:1377} INFO - Executing <Task(BashOperator): first_task> on 2022-02-01 00:00:00+00:00
[2022-07-29 10:55:29,216] {standard_task_runner.py:52} INFO - Started process 3151 to run task
[2022-07-29 10:55:29,220] {standard_task_runner.py:79} INFO - Running: ['***', 'tasks', 'run', 'Second_one', 'first_task', 'scheduled__2022-02-01T00:00:00+00:00', '--job-id', '256', '--raw', '--subdir', 'DAGS_FOLDER/Second_One.py', '--cfg-path', '/tmp/tmpng0bnr95', '--error-file', '/tmp/tmp9vjzavqo']
[2022-07-29 10:55:29,221] {standard_task_runner.py:80} INFO - Job 256: Subtask first_task
[2022-07-29 10:55:29,319] {task_command.py:369} INFO - Running <TaskInstance: Second_one.first_task scheduled__2022-02-01T00:00:00+00:00 [running]> on host 9f0f006fc89d
[2022-07-29 10:55:29,420] {taskinstance.py:1571} INFO - Exporting the following env vars:
AIRFLOW_CTX_DAG_OWNER=yosr
AIRFLOW_CTX_DAG_ID=Second_one
AIRFLOW_CTX_TASK_ID=first_task
AIRFLOW_CTX_EXECUTION_DATE=2022-02-01T00:00:00+00:00
AIRFLOW_CTX_TRY_NUMBER=1
AIRFLOW_CTX_DAG_RUN_ID=scheduled__2022-02-01T00:00:00+00:00
[2022-07-29 10:55:29,421] {subprocess.py:62} INFO - Tmp dir root location: 
 /tmp
[2022-07-29 10:55:29,422] {subprocess.py:74} INFO - Running command: ['bash', '-c', "echo hello world, I'm the first task"]
[2022-07-29 10:55:29,438] {subprocess.py:85} INFO - Output:
[2022-07-29 10:55:29,439] {subprocess.py:92} INFO - bash: -c: line 1: unexpected EOF while looking for matching `''
[2022-07-29 10:55:29,439] {subprocess.py:92} INFO - bash: -c: line 2: syntax error: unexpected end of file
[2022-07-29 10:55:29,439] {subprocess.py:96} INFO - Command exited with return code 2
[2022-07-29 10:55:29,460] {taskinstance.py:1889} ERROR - Task failed with exception
Traceback (most recent call last):
  File "/home/airflow/.local/lib/python3.7/site-packages/airflow/operators/bash.py", line 195, in execute
    f'Bash command failed. The command returned a non-zero exit code {result.exit_code}.'
airflow.exceptions.AirflowException: Bash command failed. The command returned a non-zero exit code 2.
[2022-07-29 10:55:29,466] {taskinstance.py:1400} INFO - Marking task as UP_FOR_RETRY. dag_id=Second_one, task_id=first_task, execution_date=20220201T000000, start_date=20220729T105529, end_date=20220729T105529
[2022-07-29 10:55:29,482] {standard_task_runner.py:97} ERROR - Failed to execute job 256 for task first_task (Bash command failed. The command returned a non-zero exit code 2.; 3151)
[2022-07-29 10:55:29,522] {local_task_job.py:156} INFO - Task exited with return code 1
[2022-07-29 10:55:29,572] {local_task_job.py:273} INFO - 0 downstream tasks scheduled from follow-on schedule check
