[2022-07-30 18:03:46,682] {taskinstance.py:1159} INFO - Dependencies all met for <TaskInstance: dag_with_postgres_operator.create_postgres_table scheduled__2022-01-07T00:00:00+00:00 [queued]>
[2022-07-30 18:03:46,700] {taskinstance.py:1159} INFO - Dependencies all met for <TaskInstance: dag_with_postgres_operator.create_postgres_table scheduled__2022-01-07T00:00:00+00:00 [queued]>
[2022-07-30 18:03:46,700] {taskinstance.py:1356} INFO - 
--------------------------------------------------------------------------------
[2022-07-30 18:03:46,700] {taskinstance.py:1357} INFO - Starting attempt 1 of 6
[2022-07-30 18:03:46,700] {taskinstance.py:1358} INFO - 
--------------------------------------------------------------------------------
[2022-07-30 18:03:46,727] {taskinstance.py:1377} INFO - Executing <Task(PostgresOperator): create_postgres_table> on 2022-01-07 00:00:00+00:00
[2022-07-30 18:03:46,733] {standard_task_runner.py:52} INFO - Started process 1730 to run task
[2022-07-30 18:03:46,737] {standard_task_runner.py:79} INFO - Running: ['***', 'tasks', 'run', 'dag_with_postgres_operator', 'create_postgres_table', 'scheduled__2022-01-07T00:00:00+00:00', '--job-id', '102', '--raw', '--subdir', 'DAGS_FOLDER/DAGWithPostgresOperator.py', '--cfg-path', '/tmp/tmp7rciao8f', '--error-file', '/tmp/tmpecf89rjw']
[2022-07-30 18:03:46,738] {standard_task_runner.py:80} INFO - Job 102: Subtask create_postgres_table
[2022-07-30 18:03:46,817] {task_command.py:369} INFO - Running <TaskInstance: dag_with_postgres_operator.create_postgres_table scheduled__2022-01-07T00:00:00+00:00 [running]> on host 66bf18ec08cc
[2022-07-30 18:03:46,925] {taskinstance.py:1571} INFO - Exporting the following env vars:
AIRFLOW_CTX_DAG_OWNER=yosr
AIRFLOW_CTX_DAG_ID=dag_with_postgres_operator
AIRFLOW_CTX_TASK_ID=create_postgres_table
AIRFLOW_CTX_EXECUTION_DATE=2022-01-07T00:00:00+00:00
AIRFLOW_CTX_TRY_NUMBER=1
AIRFLOW_CTX_DAG_RUN_ID=scheduled__2022-01-07T00:00:00+00:00
[2022-07-30 18:03:46,940] {base.py:68} INFO - Using connection ID 'postgres_localhost' for task execution.
[2022-07-30 18:03:46,941] {taskinstance.py:1889} ERROR - Task failed with exception
Traceback (most recent call last):
  File "/home/airflow/.local/lib/python3.7/site-packages/airflow/providers/postgres/operators/postgres.py", line 92, in execute
    self.hook.run(self.sql, self.autocommit, parameters=self.parameters)
  File "/home/airflow/.local/lib/python3.7/site-packages/airflow/hooks/dbapi.py", line 181, in run
    with closing(self.get_conn()) as conn:
  File "/home/airflow/.local/lib/python3.7/site-packages/airflow/providers/postgres/hooks/postgres.py", line 113, in get_conn
    self.conn = psycopg2.connect(**conn_args)
  File "/home/airflow/.local/lib/python3.7/site-packages/psycopg2/__init__.py", line 122, in connect
    conn = _connect(dsn, connection_factory=connection_factory, **kwasync)
psycopg2.OperationalError: could not translate host name "host.docker.internal " to address: Name or service not known

[2022-07-30 18:03:46,955] {taskinstance.py:1400} INFO - Marking task as UP_FOR_RETRY. dag_id=dag_with_postgres_operator, task_id=create_postgres_table, execution_date=20220107T000000, start_date=20220730T180346, end_date=20220730T180346
[2022-07-30 18:03:46,976] {standard_task_runner.py:97} ERROR - Failed to execute job 102 for task create_postgres_table (could not translate host name "host.docker.internal " to address: Name or service not known
; 1730)
[2022-07-30 18:03:46,997] {local_task_job.py:156} INFO - Task exited with return code 1
[2022-07-30 18:03:47,060] {local_task_job.py:273} INFO - 0 downstream tasks scheduled from follow-on schedule check
[2022-07-31 00:10:00,726] {taskinstance.py:1159} INFO - Dependencies all met for <TaskInstance: dag_with_postgres_operator.create_postgres_table scheduled__2022-01-07T00:00:00+00:00 [queued]>
[2022-07-31 00:10:00,747] {taskinstance.py:1159} INFO - Dependencies all met for <TaskInstance: dag_with_postgres_operator.create_postgres_table scheduled__2022-01-07T00:00:00+00:00 [queued]>
[2022-07-31 00:10:00,748] {taskinstance.py:1356} INFO - 
--------------------------------------------------------------------------------
[2022-07-31 00:10:00,748] {taskinstance.py:1357} INFO - Starting attempt 1 of 6
[2022-07-31 00:10:00,748] {taskinstance.py:1358} INFO - 
--------------------------------------------------------------------------------
[2022-07-31 00:10:00,774] {taskinstance.py:1377} INFO - Executing <Task(PostgresOperator): create_postgres_table> on 2022-01-07 00:00:00+00:00
[2022-07-31 00:10:00,780] {standard_task_runner.py:52} INFO - Started process 5656 to run task
[2022-07-31 00:10:00,785] {standard_task_runner.py:79} INFO - Running: ['***', 'tasks', 'run', 'dag_with_postgres_operator', 'create_postgres_table', 'scheduled__2022-01-07T00:00:00+00:00', '--job-id', '1110', '--raw', '--subdir', 'DAGS_FOLDER/DAGWithPostgresOperator.py', '--cfg-path', '/tmp/tmpb3nnie87', '--error-file', '/tmp/tmp6w2pivlf']
[2022-07-31 00:10:00,785] {standard_task_runner.py:80} INFO - Job 1110: Subtask create_postgres_table
[2022-07-31 00:10:00,865] {task_command.py:369} INFO - Running <TaskInstance: dag_with_postgres_operator.create_postgres_table scheduled__2022-01-07T00:00:00+00:00 [running]> on host 66bf18ec08cc
[2022-07-31 00:10:00,989] {taskinstance.py:1571} INFO - Exporting the following env vars:
AIRFLOW_CTX_DAG_OWNER=yosr
AIRFLOW_CTX_DAG_ID=dag_with_postgres_operator
AIRFLOW_CTX_TASK_ID=create_postgres_table
AIRFLOW_CTX_EXECUTION_DATE=2022-01-07T00:00:00+00:00
AIRFLOW_CTX_TRY_NUMBER=1
AIRFLOW_CTX_DAG_RUN_ID=scheduled__2022-01-07T00:00:00+00:00
[2022-07-31 00:10:01,001] {base.py:68} INFO - Using connection ID 'postgres_localhost' for task execution.
[2022-07-31 00:10:01,002] {taskinstance.py:1889} ERROR - Task failed with exception
Traceback (most recent call last):
  File "/home/airflow/.local/lib/python3.7/site-packages/airflow/providers/postgres/operators/postgres.py", line 92, in execute
    self.hook.run(self.sql, self.autocommit, parameters=self.parameters)
  File "/home/airflow/.local/lib/python3.7/site-packages/airflow/hooks/dbapi.py", line 181, in run
    with closing(self.get_conn()) as conn:
  File "/home/airflow/.local/lib/python3.7/site-packages/airflow/providers/postgres/hooks/postgres.py", line 113, in get_conn
    self.conn = psycopg2.connect(**conn_args)
  File "/home/airflow/.local/lib/python3.7/site-packages/psycopg2/__init__.py", line 122, in connect
    conn = _connect(dsn, connection_factory=connection_factory, **kwasync)
psycopg2.OperationalError: could not translate host name "host.docker.local " to address: Name or service not known

[2022-07-31 00:10:01,017] {taskinstance.py:1400} INFO - Marking task as UP_FOR_RETRY. dag_id=dag_with_postgres_operator, task_id=create_postgres_table, execution_date=20220107T000000, start_date=20220731T001000, end_date=20220731T001001
[2022-07-31 00:10:01,034] {standard_task_runner.py:97} ERROR - Failed to execute job 1110 for task create_postgres_table (could not translate host name "host.docker.local " to address: Name or service not known
; 5656)
[2022-07-31 00:10:01,042] {local_task_job.py:156} INFO - Task exited with return code 1
[2022-07-31 00:10:01,101] {local_task_job.py:273} INFO - 0 downstream tasks scheduled from follow-on schedule check
[2022-07-31 11:03:26,159] {taskinstance.py:1159} INFO - Dependencies all met for <TaskInstance: dag_with_postgres_operator.create_postgres_table scheduled__2022-01-07T00:00:00+00:00 [queued]>
[2022-07-31 11:03:26,185] {taskinstance.py:1159} INFO - Dependencies all met for <TaskInstance: dag_with_postgres_operator.create_postgres_table scheduled__2022-01-07T00:00:00+00:00 [queued]>
[2022-07-31 11:03:26,185] {taskinstance.py:1356} INFO - 
--------------------------------------------------------------------------------
[2022-07-31 11:03:26,185] {taskinstance.py:1357} INFO - Starting attempt 1 of 6
[2022-07-31 11:03:26,185] {taskinstance.py:1358} INFO - 
--------------------------------------------------------------------------------
[2022-07-31 11:03:26,207] {taskinstance.py:1377} INFO - Executing <Task(PostgresOperator): create_postgres_table> on 2022-01-07 00:00:00+00:00
[2022-07-31 11:03:26,212] {standard_task_runner.py:52} INFO - Started process 4522 to run task
[2022-07-31 11:03:26,215] {standard_task_runner.py:79} INFO - Running: ['***', 'tasks', 'run', 'dag_with_postgres_operator', 'create_postgres_table', 'scheduled__2022-01-07T00:00:00+00:00', '--job-id', '1560', '--raw', '--subdir', 'DAGS_FOLDER/DAGWithPostgresOperator.py', '--cfg-path', '/tmp/tmpr2xp_gsl', '--error-file', '/tmp/tmpmfql2ptl']
[2022-07-31 11:03:26,216] {standard_task_runner.py:80} INFO - Job 1560: Subtask create_postgres_table
[2022-07-31 11:03:26,299] {task_command.py:369} INFO - Running <TaskInstance: dag_with_postgres_operator.create_postgres_table scheduled__2022-01-07T00:00:00+00:00 [running]> on host 66bf18ec08cc
[2022-07-31 11:03:26,411] {taskinstance.py:1571} INFO - Exporting the following env vars:
AIRFLOW_CTX_DAG_OWNER=yosr
AIRFLOW_CTX_DAG_ID=dag_with_postgres_operator
AIRFLOW_CTX_TASK_ID=create_postgres_table
AIRFLOW_CTX_EXECUTION_DATE=2022-01-07T00:00:00+00:00
AIRFLOW_CTX_TRY_NUMBER=1
AIRFLOW_CTX_DAG_RUN_ID=scheduled__2022-01-07T00:00:00+00:00
[2022-07-31 11:03:26,428] {base.py:68} INFO - Using connection ID 'postgres_localhost' for task execution.
[2022-07-31 11:03:26,429] {taskinstance.py:1889} ERROR - Task failed with exception
Traceback (most recent call last):
  File "/home/airflow/.local/lib/python3.7/site-packages/airflow/providers/postgres/operators/postgres.py", line 92, in execute
    self.hook.run(self.sql, self.autocommit, parameters=self.parameters)
  File "/home/airflow/.local/lib/python3.7/site-packages/airflow/hooks/dbapi.py", line 181, in run
    with closing(self.get_conn()) as conn:
  File "/home/airflow/.local/lib/python3.7/site-packages/airflow/providers/postgres/hooks/postgres.py", line 113, in get_conn
    self.conn = psycopg2.connect(**conn_args)
  File "/home/airflow/.local/lib/python3.7/site-packages/psycopg2/__init__.py", line 122, in connect
    conn = _connect(dsn, connection_factory=connection_factory, **kwasync)
psycopg2.OperationalError: could not translate host name "host.docker.internal " to address: Name or service not known

[2022-07-31 11:03:26,446] {taskinstance.py:1400} INFO - Marking task as UP_FOR_RETRY. dag_id=dag_with_postgres_operator, task_id=create_postgres_table, execution_date=20220107T000000, start_date=20220731T110326, end_date=20220731T110326
[2022-07-31 11:03:26,474] {standard_task_runner.py:97} ERROR - Failed to execute job 1560 for task create_postgres_table (could not translate host name "host.docker.internal " to address: Name or service not known
; 4522)
[2022-07-31 11:03:26,515] {local_task_job.py:156} INFO - Task exited with return code 1
[2022-07-31 11:03:26,573] {local_task_job.py:273} INFO - 0 downstream tasks scheduled from follow-on schedule check
[2022-07-31 13:35:06,982] {taskinstance.py:1159} INFO - Dependencies all met for <TaskInstance: dag_with_postgres_operator.create_postgres_table scheduled__2022-01-07T00:00:00+00:00 [queued]>
[2022-07-31 13:35:07,000] {taskinstance.py:1159} INFO - Dependencies all met for <TaskInstance: dag_with_postgres_operator.create_postgres_table scheduled__2022-01-07T00:00:00+00:00 [queued]>
[2022-07-31 13:35:07,000] {taskinstance.py:1356} INFO - 
--------------------------------------------------------------------------------
[2022-07-31 13:35:07,001] {taskinstance.py:1357} INFO - Starting attempt 1 of 6
[2022-07-31 13:35:07,001] {taskinstance.py:1358} INFO - 
--------------------------------------------------------------------------------
[2022-07-31 13:35:07,023] {taskinstance.py:1377} INFO - Executing <Task(PostgresOperator): create_postgres_table> on 2022-01-07 00:00:00+00:00
[2022-07-31 13:35:07,028] {standard_task_runner.py:52} INFO - Started process 2123 to run task
[2022-07-31 13:35:07,031] {standard_task_runner.py:79} INFO - Running: ['***', 'tasks', 'run', 'dag_with_postgres_operator', 'create_postgres_table', 'scheduled__2022-01-07T00:00:00+00:00', '--job-id', '102', '--raw', '--subdir', 'DAGS_FOLDER/DAGWithPostgresOperator.py', '--cfg-path', '/tmp/tmp2rqe_d35', '--error-file', '/tmp/tmpqvv3lnbx']
[2022-07-31 13:35:07,031] {standard_task_runner.py:80} INFO - Job 102: Subtask create_postgres_table
[2022-07-31 13:35:07,108] {task_command.py:369} INFO - Running <TaskInstance: dag_with_postgres_operator.create_postgres_table scheduled__2022-01-07T00:00:00+00:00 [running]> on host 4688dd3b7141
[2022-07-31 13:35:07,209] {taskinstance.py:1571} INFO - Exporting the following env vars:
AIRFLOW_CTX_DAG_OWNER=yosr
AIRFLOW_CTX_DAG_ID=dag_with_postgres_operator
AIRFLOW_CTX_TASK_ID=create_postgres_table
AIRFLOW_CTX_EXECUTION_DATE=2022-01-07T00:00:00+00:00
AIRFLOW_CTX_TRY_NUMBER=1
AIRFLOW_CTX_DAG_RUN_ID=scheduled__2022-01-07T00:00:00+00:00
[2022-07-31 13:35:07,248] {taskinstance.py:1889} ERROR - Task failed with exception
Traceback (most recent call last):
  File "/home/airflow/.local/lib/python3.7/site-packages/airflow/providers/postgres/operators/postgres.py", line 92, in execute
    self.hook.run(self.sql, self.autocommit, parameters=self.parameters)
  File "/home/airflow/.local/lib/python3.7/site-packages/airflow/hooks/dbapi.py", line 181, in run
    with closing(self.get_conn()) as conn:
  File "/home/airflow/.local/lib/python3.7/site-packages/airflow/providers/postgres/hooks/postgres.py", line 86, in get_conn
    conn = deepcopy(self.connection or self.get_connection(conn_id))
  File "/home/airflow/.local/lib/python3.7/site-packages/airflow/hooks/base.py", line 67, in get_connection
    conn = Connection.get_connection_from_secrets(conn_id)
  File "/home/airflow/.local/lib/python3.7/site-packages/airflow/models/connection.py", line 430, in get_connection_from_secrets
    raise AirflowNotFoundException(f"The conn_id `{conn_id}` isn't defined")
airflow.exceptions.AirflowNotFoundException: The conn_id `postgres_localhost` isn't defined
[2022-07-31 13:35:07,255] {taskinstance.py:1400} INFO - Marking task as UP_FOR_RETRY. dag_id=dag_with_postgres_operator, task_id=create_postgres_table, execution_date=20220107T000000, start_date=20220731T133506, end_date=20220731T133507
[2022-07-31 13:35:07,281] {standard_task_runner.py:97} ERROR - Failed to execute job 102 for task create_postgres_table (The conn_id `postgres_localhost` isn't defined; 2123)
[2022-07-31 13:35:07,331] {local_task_job.py:156} INFO - Task exited with return code 1
[2022-07-31 13:35:07,381] {local_task_job.py:273} INFO - 0 downstream tasks scheduled from follow-on schedule check
